Workbook

Sheet Old Material Testing
A1: Sample 1:
A2: Width: | B2: 0.5 | C2: in
A3: Height: | B3: 0.25 | C3: in
A4: Length: | B4: 6.91 | C4: in
A5: "Yield" | B5: 1190 | C5: g | D5: =(B5/1000)*2.2 -> 2.618 | E5: lbf | F5: Started making cracking sounds
A6: Ultimate | B6: 1260 | C6: g | D6: =(B6/1000)*2.2 -> 2.772 | E6: lbf | F6: I think this number is a slight underestimate.
A8: Half-length: | B8: =B4/2 -> 3.455 | C8: in
A9: Internal moment at "Yield" | B9: =$B$8*(D5/2) -> 4.522595 | C9: in-lbs
A10: Internal moment at "Ult" | B10: =$B$8*(D6/2) -> 4.78863 | C10: in-lbs
A12: I: | B12: =B2*(B3^3)/12 -> 0.00065104167 | C12: in^4
A13: Yield Tensile: | B13: =B9*($B$3/2)/$B$12 -> 868.33824 | C13: psi
A14: Ult Tensile: | B14: =B10*($B$3/2)/$B$12 -> 919.41696 | C14: psi
A15: Density est:
A16: Approx mass of sample: | B16: 7 | C16: g
A17: Length: | B17: 35 | C17: in
A18: Vol of sample: | B18: =B2*B3*B17 -> 4.375 | C18: in^3
A19: density of sample: | B19: =B16/B18 -> 1.6 | C19: g/in^3 | D19: =B19/16.3871 -> 0.097637776 | E19: g/cm^3 | F19: =D19*1000 -> 97.637776 | G19: kg/m^3
A26: Sample 2:
A27: Width: | B27: 0.5 | C27: in
A28: Height: | B28: 0.25 | C28: in
A29: Length: | B29: 6.875 | C29: in
A30: "Yield" | C30: g | D30: =(B30/1000)*2.2 -> 0 | E30: lbf | F30: Started making cracking sounds | M30: 2060
A31: Ultimate | B31: 2060 | C31: g | D31: =(B31/1000)*2.2 -> 4.532 | E31: lbf | F31: I think this number is a slight underestimate.
A33: Half-length: | B33: =B29/2 -> 3.4375 | C33: in
A34: Internal moment at "Yield" | B34: =$B$8*(D30/2) -> 0 | C34: in-lbs
A35: Internal moment at "Ult" | B35: =$B$8*(D31/2) -> 7.82903 | C35: in-lbs
A37: I: | B37: =B27*(B28^3)/12 -> 0.00065104167 | C37: in^4
A38: Yield Tensile: | B38: =B34*($B$3/2)/$B$12 -> 0 | C38: psi
A39: Ult Tensile: | B39: =B35*($B$3/2)/$B$12 -> 1503.1738 | C39: psi
A40: Density est:
A41: Approx mass of sample: | B41: 9 | C41: g
A42: Length: | B42: 35 | C42: in
A43: Vol of sample: | B43: =B27*B28*B42 -> 4.375 | C43: in^3
A44: density of sample: | B44: =B41/B43 -> 2.0571429 | C44: g/in^3 | D44: =B44/16.3871 -> 0.12553428 | E44: g/cm^3 | F44: =D44*1000 -> 125.53428 | G44: kg/m^3
A50: Sample 3:
A51: Width: | B51: 0.5 | C51: in
A52: Height: | B52: 0.25 | C52: in
A53: Length: | B53: 6.95 | C53: in
A54: "Yield" | C54: g | D54: =(B54/1000)*2.2 -> 0 | E54: lbf | F54: Started making cracking sounds | M54: 2400
A55: Ultimate | B55: 2400 | C55: g | D55: =(B55/1000)*2.2 -> 5.28 | E55: lbf | F55: I think this number is a slight underestimate.
...

Sheet Initial Sizing
A1: Full-Scale Edge 540
A2: Wingspan: | B2: 293 | C2: in
A3: Root Chord | B3: 62 | C3: in
A4: Tip Chord | B4: 29 | C4: in
A5: Wing Area | B5: 98 | C5: ft^2 | D5: =B5*144 -> 14112 | E5: in^2
A6: Aircraft Length: | B6: 247 | C6: in
A7: Aircraft Height: | B7: =(7*12)+9 -> 93 | C7: in
A8: H-Tail Span: | B8: =(8*12)+1 -> 97 | C8: in
A9: H-Tail Area: | B9: 22 | C9: ft^2 | D9: =B9*144 -> 3168 | E9: in^2
A10: V-tail Area: | B10: =D10/144 -> 14.069444 | C10: ft^2 | D10: =(14*144)+10 -> 2026 | E10: in^2
A11: V-Tail Height: | B11: =D11/12 -> 5.1666667 | C11: ft | D11: =(5*12)+2 -> 62 | E11: in^2
I12: Area: | J12: 658
A13: Calculated Wing Area | B13: =B2*(AVERAGE(B3,B4)) -> 13331.5 | C13: in^2
A14: Calculated AR: | B14: =B2/(AVERAGE(B3:B4)) -> 6.4395604 | C14: dim.
C15: 65 | J15: 0.3 | K15: 13.75 | L15: 6.5
A16: Edge 540 60:
C17: Span: (in) | D17: Chord | E17: Area: (in^2) | F17: Area (ft^2) | G17: Aspect Ratio: | H17: Est Mass: | I17: Weight: (lbs) | J17: Target Structure lbs/ft^2 | K17: Mass Fraction: | L17: Root Chord: | M17: Tip Chord:
A18: Wing | C18: 64 | D18: =AVERAGE(L18:M18) -> 10.625 | E18: =C18*D18 -> 680 | F18: =E18/144 -> 4.7222222 | G18: =C18/D18 -> 6.0235294 | H18: =I18/2.2046 -> 0.47123691 | I18: =F18*J18 -> 1.0388889 | J18: 0.22 | K18: =H18/H38 -> 0.15587164 | L18: =B42 -> 14.25 | M18: =B56 -> 7
C19: Length | H19: Target Mass: | I19: Target Weight:
A20: Fuselage | C20: 54.7 | H20: 0.8 | I20: =H20*2.2046 -> 1.76368 | K20: =H20/$H$38 -> 0.26461704 | N20: Includes Motor, Prop, Rudder
C21: Span: (in) | D21: Mean Chord (in) | E21: Area: (in^2) | F21: Area (ft^2) | G21: Aspect Ratio: | H21: Est Mass: | I21: Weight: (lbs) | J21: Target Structure lbs/ft^2
A22: H-Tail | C22: 21.5 | D22: =E22/C22 -> 7.2618605 | E22: 156.13 | F22: =E22/144 -> 1.0842361 | G22: =C22/D22 -> 2.9606738 | H22: 0.09 | K22: =H22/$H$38 -> 0.029769417
C23: Height: (in) | D23: Mean Chord (in) | E23: Area: (in^2) | F23: Area (ft^2) | G23: Aspect Ratio: | H23: Est Mass: | I23: Weight: (lbs) | J23: Target Structure lbs/ft^2
A24: V-Tail | C24: 13.75 | E24: 99.85 | H24: 0.09 | K24: =H24/$H$38 -> 0.029769417
C25: Prop: | H25: Est Mass:
A26: Super Tiger 61 | C26: 12 x 6 | H26: 0.85 | K26: =H26/$H$38 -> 0.2811556
A28: Flight Battery | H28: 0.115 | K28: =H28/$H$38 -> 0.038038699
A30: Landing Gear | H30: 0.213 | K30: =H30/$H$38 -> 0.070454287
A32: Fuel tank | H32: 0.047 | K32: =H32/$H$38 -> 0.015546251
A34: Servos | H34: 0.25 | K34: =H34/$H$38 -> 0.082692825
A36: Cowling | H36: 0.097 | K36: =H36/$H$38 -> 0.032084816
G38: Total Mass: | H38: =SUM(H18,H20,H22,H24,H26,H28,H30,H32,H34,H36) -> 3.0232369 | I38: kg | J38: =H38*2.2046 -> 6.6650281 | K38: lbs
G39: Wing Loading: | H39: =(J38*16)/F18 -> 22.582683 | I39: oz/ft^2
A40: Relevant Parameters
A41: Panel_Span | B41: 28.6 | C41: in
A42: Root_Chord | B42: 14.25 | C42: in
A43: Main_Spar_Root_Chord_Rel_Position | B43: 0.2 | C43: ul
A44: Main_Spar_Root_Height | B44: 1.5 | C44: in
A45: Main_Spar_Root_flange_Height | B45: 0.2 | C45: in
A46: Main_Spar_Root_flange_Width | B46: 0.3 | C46: in
...

Sheet Material Properties
A1: Balsa:
A2: Part 1:
A3: L: | B3: 36 | C3: in
A4: W: | B4: 1 | C4: in
A5: H: | B5: 0.25 | C5: in
A6: volume: | B6: =B3*B4*B5 -> 9 | C6: in^3 | D6: =B6/(39.37^3) -> 0.00014748446 | E6: m^3
A7: Mass: | B7: 17.5 | C7: g | D7: =B7/1000 -> 0.0175 | E7: kg | F7: =D7*2.2 -> 0.0385 | G7: lbs | H7: =F7/B6 -> 0.0042777778
A8: Density: | B8: =D7/D6 -> 118.65657 | C8: kg/m^3 | G8: =B8/16.0185 -> 7.4074706 | I8: =G8/(12^3) -> 0.0042867307 | J8: lb/in^3
A11: Part 2:
A12: L: | B12: 36 | C12: in
A13: W: | B13: 3 | C13: in
A14: H: | B14: =3/32 -> 0.09375 | C14: in
A15: volume: | B15: =B12*B13*B14 -> 10.125 | C15: in^3 | D15: =B15/(39.37^3) -> 0.00016592002 | E15: m^3
A16: Mass: | B16: 30 | C16: g | D16: =B16/1000 -> 0.03 | E16: kg
A17: Density: | B17: =D16/D15 -> 180.81001 | C17: kg/m^3 | G17: =B17/16.0185 -> 11.287574 | I17: =G17/(12^3) -> 0.006532161 | J17: lb/in^12
A19: Part 3:
A20: L: | B20: 36 | C20: in
A21: W: | B21: 1 | C21: in
A22: H: | B22: 0.25 | C22: in
A23: volume: | B23: =B20*B21*B22 -> 9 | C23: in^3 | D23: =B23/(39.37^3) -> 0.00014748446
A24: Mass: | B24: 15 | C24: g | D24: =B24/1000 -> 0.015
A25: Density: | B25: =D24/D23 -> 101.70563 | C25: kg/m^3
A27: Part 4:
A28: L: | B28: 36 | C28: in
A29: W: | B29: 1 | C29: in
A30: H: | B30: 0.25 | C30: in
A31: volume: | B31: =B28*B29*B30 -> 9 | C31: in^3 | D31: =B31/(39.37^3) -> 0.00014748446
A32: Mass: | B32: 16 | C32: g | D32: =B32/1000 -> 0.016
A33: Density: | B33: =D32/D31 -> 108.48601 | C33: kg/m^3
A35: Part 2:
A36: L: | B36: 36 | C36: in
A37: W: | B37: 3 | C37: in
A38: H: | B38: =3/16 -> 0.1875 | C38: in
A39: volume: | B39: =B36*B37*B38 -> 20.25 | C39: in^3 | D39: =B39/(39.37^3) -> 0.00033184004 | E39: m^3
A40: Mass: | B40: 54 | C40: g | D40: =B40/1000 -> 0.054 | E40: kg | F40: =D40*2.2 -> 0.1188 | G40: lbs | H40: =F40/B39 -> 0.0058666667
A41: Density: | B41: =D40/D39 -> 162.72901 | C41: kg/m^3 | G41: =B41/16.0185 -> 10.158817 | I41: =G41/(12^3) -> 0.0058789449 | J41: lb/in^3
A43: Part 2:
A44: L: | B44: 36 | C44: in
A45: W: | B45: 3 | C45: in
A46: H: | B46: 0.13 | C46: in
...

Sheet Mass Breakdown
N1: Ply Density: | O1: 0.022046
N3: Balsa Density: | O3: 0.006523
A5: Fuselage: | B5: Area: | C5: Thickness: | D5: volume (in^3) | E5: density lb/in^3 | F5: mass (lbm) | G5: Lightening fraction: | H5: Number: | I5: Final Mass (lbm) | J5: X CG | K5: Y CG | L5: Z CG | M5: Ixx | N5: Iyy | O5: Izz | P5: Ixz | Q5: in-lbs CG x | R5: in-lbs CG y | S5: in-lbs CG z
A6: Firewall | B6: 34.27 | C6: 0.125 | D6: =B6*C6 -> 4.28375 | E6: =$O$1 -> 0.022046 | F6: =D6*E6 -> 0.094439553 | G6: 1 | H6: 1 | I6: =G6*F6*H6 -> 0.094439553 | J6: -5.94 | K6: 0 | Q6: =$I6*J6 -> -0.56097094 | R6: =$I6*K6 -> 0 | S6: =$I6*L6 -> 0
A7: Bulkhead 1 | B7: 42.11 | C7: 0.125 | D7: =B7*C7 -> 5.26375 | E7: =$O$1 -> 0.022046 | F7: =D7*E7 -> 0.11604463 | G7: 0.6666 | H7: 1 | I7: =G7*F7*H7 -> 0.077355352 | J7: 1.06 | K7: 0 | Q7: =$I7*J7 -> 0.081996673 | R7: =$I7*K7 -> 0 | S7: =$I7*L7 -> 0
A8: Bulkhead 2 | B8: 21.75 | C8: 0.125 | D8: =B8*C8 -> 2.71875 | E8: =$O$1 -> 0.022046 | F8: =D8*E8 -> 0.059937562 | G8: 1 | H8: 1 | I8: =G8*F8*H8 -> 0.059937562 | J8: 12.06 | K8: 0 | Q8: =$I8*J8 -> 0.722847 | R8: =$I8*K8 -> 0 | S8: =$I8*L8 -> 0
A9: Bulkhead 2.5 | B9: 14.02 | C9: 0.125 | D9: =B9*C9 -> 1.7525 | E9: =$O$1 -> 0.022046 | F9: =D9*E9 -> 0.038635615 | G9: 1 | H9: 1 | I9: =G9*F9*H9 -> 0.038635615 | J9: 22.06 | K9: 0 | L9: -0.37 | M9: 0.24 | N9: 0.18 | O9: 0.06 | P9: 0 | Q9: =$I9*J9 -> 0.85230167 | R9: =$I9*K9 -> 0 | S9: =$I9*L9 -> -0.014295178
A10: Bulkhead 3 | B10: 8.96 | C10: 0.125 | D10: 0.61 | E10: =$O$1 -> 0.022046 | F10: =D10*E10 -> 0.01344806 | G10: 0.666 | H10: 1 | I10: =G10*F10*H10 -> 0.008956408 | J10: 31.56 | K10: 0 | L10: -0.93 | M10: 0.02 | N10: 0.02 | O10: 0 | P10: 0 | Q10: =$I10*J10 -> 0.28266424 | R10: =$I10*K10 -> 0 | S10: =$I10*L10 -> -0.0083294594
A11: Aft side beam: | D11: 3.7 | E11: =$O$1 -> 0.022046 | F11: =D11*E11 -> 0.0815702 | G11: 1 | H11: 2 | I11: =G11*F11*H11 -> 0.1631404 | J11: 23.99 | K11: 1.7 | L11: -1.71 | M11: 0.31 | N11: 8.23 | O11: 8.06 | P11: 0.31 | Q11: =$I11*J11 -> 3.9137382 | R11: =$I11*K11 -> 0.27733868 | S11: =$I11*L11 -> -0.27897008 | T11: Symmetric Part
A12: Wing Mount: | B12: 32.56 | C12: 0.125 | D12: =B12*C12 -> 4.07 | E12: =$O$1 -> 0.022046 | F12: =D12*E12 -> 0.08972722 | G12: 1 | H12: 2 | I12: =G12*F12*H12 -> 0.17945444 | J12: 2.99 | K12: 2.44 | L12: -1.64 | M12: 0.58 | N12: 5.35 | O12: 4.77 | P12: -0.1 | Q12: =$I12*J12 -> 0.53656878 | R12: =$I12*K12 -> 0.43786883 | S12: =$I12*L12 -> -0.29430528 | T12: Symmetric Part
A13: TurtleDeck Sheeting | B13: 198.72 | C13: 0.0625 | D13: =B13*C13 -> 12.42 | E13: =O3 -> 0.006523 | F13: =D13*E13 -> 0.08101566 | G13: 1 | H13: 1 | I13: =G13*F13*H13 -> 0.08101566 | Q13: =$I13*J13 -> 0 | R13: =$I13*K13 -> 0 | S13: =$I13*L13 -> 0
A14: Top TurtleDeck Support | B14: =0.375^2 -> 0.140625 | C14: 24 | D14: =B14*C14 -> 3.375 | E14: =O3 -> 0.006523 | F14: =D14*E14 -> 0.022015125 | G14: 1 | H14: 1 | I14: =G14*F14*H14 -> 0.022015125 | Q14: =$I14*J14 -> 0 | R14: =$I14*K14 -> 0 | S14: =$I14*L14 -> 0
A15: Keel Sheet | B15: 127.23 | C15: 0.0625 | D15: =B15*C15 -> 7.951875 | E15: =O3 -> 0.006523 | F15: =D15*E15 -> 0.051870081 | G15: 1 | H15: 1 | I15: =G15*F15*H15 -> 0.051870081 | Q15: =$I15*J15 -> 0 | R15: =$I15*K15 -> 0 | S15: =$I15*L15 -> 0
A16: Access Panel/canopy | D16: =B16*C16 -> 0 | F16: =D16*E16 -> 0 | G16: 1 | H16: 1 | I16: =G16*F16*H16 -> 0 | Q16: =$I16*J16 -> 0 | R16: =$I16*K16 -> 0 | S16: =$I16*L16 -> 0
A17: Energy Compartment sheet | B17: 56.9 | C17: 0.0625 | D17: =B17*C17 -> 3.55625 | E17: =O3 -> 0.006523 | F17: =D17*E17 -> 0.023197419 | G17: 1 | H17: 1 | I17: =G17*F17*H17 -> 0.023197419 | J17: -2.4 | K17: 0 | L17: 1.45 | M17: 1 | N17: 1.07 | O17: 1.87 | P17: 0.02 | Q17: =$I17*J17 -> -0.055673805 | R17: =$I17*K17 -> 0 | S17: =$I17*L17 -> 0.033636257
D18: =B18*C18 -> 0 | F18: =D18*E18 -> 0 | I18: =G18*F18*H18 -> 0 | Q18: =$I18*J18 -> 0 | R18: =$I18*K18 -> 0 | S18: =$I18*L18 -> 0
D19: =B19*C19 -> 0 | F19: =D19*E19 -> 0 | I19: =G19*F19*H19 -> 0 | Q19: =$I19*J19 -> 0 | R19: =$I19*K19 -> 0 | S19: =$I19*L19 -> 0
D20: =B20*C20 -> 0 | F20: =D20*E20 -> 0 | I20: =G20*F20*H20 -> 0 | Q20: =$I20*J20 -> 0 | R20: =$I20*K20 -> 0 | S20: =$I20*L20 -> 0
D21: =B21*C21 -> 0 | F21: =D21*E21 -> 0 | I21: =G21*F21*H21 -> 0 | Q21: =$I21*J21 -> 0 | R21: =$I21*K21 -> 0 | S21: =$I21*L21 -> 0
D22: =B22*C22 -> 0 | F22: =D22*E22 -> 0 | I22: =G22*F22*H22 -> 0 | Q22: =$I22*J22 -> 0 | R22: =$I22*K22 -> 0 | S22: =$I22*L22 -> 0
D23: =B23*C23 -> 0 | F23: =D23*E23 -> 0 | I23: =G23*F23*H23 -> 0 | Q23: =$I23*J23 -> 0 | R23: =$I23*K23 -> 0 | S23: =$I23*L23 -> 0
D24: =B24*C24 -> 0 | F24: =D24*E24 -> 0 | I24: =G24*F24*H24 -> 0 | Q24: =$I24*J24 -> 0 | R24: =$I24*K24 -> 0 | S24: =$I24*L24 -> 0
D25: =B25*C25 -> 0 | F25: =D25*E25 -> 0 | I25: =G25*F25*H25 -> 0 | Q25: =$I25*J25 -> 0 | R25: =$I25*K25 -> 0 | S25: =$I25*L25 -> 0
G26: Fuselage Total: | I26: =SUM(I6:I25) -> 0.80001761 | J26: lbm
G27: Glue Correction: | I27: 1.2 | J27: dim.
G28: Fuselage Final: | I28: =I26*I27 -> 0.96002114
A33: Inventor Wing: | B33: Area: | C33: Thickness: | D33: volume (in^3) | E33: density lb/in^3 | F33: mass: | G33: Lightening fraction: | H33: Number: | I33: Final Mass (lb) | J33: X CG | K33: Y CG | L33: Z CG | M33: Ixx | N33: Iyy | O33: Izz | P33: Ixz | Q33: in-lbs CG x | R33: in-lbs CG y | S33: in-lbs CG z
A34: Total: | I34: 0.595
A35: Ailerons | F35: 0.176 | G35: 0.666 | H35: 2 | I35: =F35*G35*H35 -> 0.234432
G37: Inventor Wing Total: | I37: =SUM(I34:I36) -> 0.829432 | J37: lbm
G38: Glue Correction: | I38: 1.2 | J38: dim.
G39: Inventor Wing Final: | I39: =I37*I38 -> 0.9953184 | J39: lbm
A41: Actual Wing: | B41: Area: | C41: Thickness: (in) | D41: volume (in^3) | E41: density lb/in^3 | F41: mass: (kg) | G41: Lightening fraction: | H41: Number: | I41: Final Mass (lb)
A42: Current Half Structure Mass: | F42: 0.159 | G42: 1 | H42: 2 | I42: =G42*F42*H42*2.2046 -> 0.7010628 | K42: Includes aileron servo mounting hardware
A43: Aileron Structure | B43: 0.00875 | C43: 29.5 | D43: =B43*C43 -> 0.258125 | E43: =O3 -> 0.006523 | F43: 0.029 | G43: 1 | H43: 2 | I43: =G43*F43*H43*2.2046 -> 0.1278668 | K43: before covering
A44: Carbon Fiber Spar Mass: | F44: 0.065 | G44: 1 | H44: 1 | I44: =G44*F44*H44*2.2046 -> 0.143299
A45: UltraCote | B45: 10 | E45: 0.005 | F45: =B45*E45 -> 0.05 | G45: 1 | H45: 1 | I45: =G45*F45*H45*2.2046 -> 0.11023 | K45: Area is in Ft^2, Density is in grams/ft^2
F46: =I47/2.2046 -> 0.491
H47: Total Wing Weight: | I47: =SUM(I42:I45) -> 1.0824586 | J47: lb
H48: Growth Factor: | I48: 1 | J48: dim
...

Sheet Progressive Analysis
A1: Full-Scale Edge 540, for reference
A2: Wingspan: | B2: 293 | C2: in
A3: Root Chord | B3: 62 | C3: in
A4: Tip Chord | B4: 29 | C4: in
A5: Wing Area | B5: 98 | C5: ft^2 | D5: =B5*144 -> 14112 | E5: in^2
A6: Aircraft Length: | B6: 247 | C6: in
A7: Aircraft Height: | B7: =(7*12)+9 -> 93 | C7: in
A8: H-Tail Span: | B8: =(8*12)+1 -> 97 | C8: in
A9: H-Tail Area: | B9: 22 | C9: ft^2 | D9: =B9*144 -> 3168 | E9: in^2
A10: V-tail Area: | B10: =D10/144 -> 14.069444 | C10: ft^2 | D10: =(14*144)+10 -> 2026 | E10: in^2
A11: V-Tail Height: | B11: =D11/12 -> 5.1666667 | C11: ft | D11: =(5*12)+2 -> 62 | E11: in^2
I12: Area: | J12: 658
A13: Calculated Wing Area | B13: =B2*(AVERAGE(B3,B4)) -> 13331.5 | C13: in^2
A14: Calculated AR: | B14: =B2/(AVERAGE(B3:B4)) -> 6.4395604 | C14: dim.
C15: 65 | J15: 0.3 | K15: 13.75 | L15: 6.5
A16: Edge 540 60:
C17: Span: (in) | D17: Mean Chord | E17: Area: (in^2) | F17: Area (ft^2) | G17: Aspect Ratio: | H17: Est Mass: | I17: Est Weight: (lbs) | J17: Area Density lbs/ft^2 | K17: Mass Fraction: | L17: Root Chord: | M17: Tip Chord: | O17: Cost
A18: Wing | C18: 64 | D18: =AVERAGE(L18:M18) -> 10.625 | E18: =C18*D18 -> 680 | F18: =E18/144 -> 4.7222222 | G18: =C18/D18 -> 6.0235294 | H18: =I18/2.2046 -> 0.491 | I18: ='Mass Breakdown'!I49 -> 1.0824586 | J18: =I18/F18 -> 0.22922653 | K18: =H18/H38 -> 0.19297315 | L18: =B44 -> 14.25 | M18: =B58 -> 7
C19: Length | H19: Est Mass: | I19: Est Weight:
A20: Fuselage | C20: 54.7 | H20: =I20/2.2046 -> 0.43546273 | I20: ='Mass Breakdown'!I28 -> 0.96002114 | K20: =H20/$H$38 -> 0.17114586
C21: Span: (in) | D21: Mean Chord (in) | E21: Area: (in^2) | F21: Area (ft^2) | G21: Aspect Ratio: | H21: Est Mass: | I21: Weight: (lbs) | J21: Area Density lbs/ft^2
A22: H-Tail | C22: 21.5 | D22: =E22/C22 -> 7.2618605 | E22: 156.13 | F22: =E22/144 -> 1.0842361 | G22: =C22/D22 -> 2.9606738 | H22: =I22/2.2046 -> 0.12622283 | I22: ='Mass Breakdown'!I75 -> 0.27827086 | J22: =I22/F22 -> 0.25665153 | K22: =H22/$H$38 -> 0.049608183
C23: Height: (in) | D23: Mean Chord (in) | E23: Area: (in^2) | F23: Area (ft^2) | G23: Aspect Ratio: | H23: Est Mass: | I23: Weight: (lbs) | J23: Area Density lbs/ft^2
A24: V-Tail | C24: 13.75 | D24: =AVERAGE(L24,M24) -> 7.25 | E24: =D24*C24 -> 99.6875 | F24: =E24/144 -> 0.69227431 | H24: =I24/2.2046 -> 0.079469294 | I24: ='Mass Breakdown'!K100 -> 0.175198 | J24: =I24/F24 -> 0.25307599 | K24: =H24/$H$38 -> 0.031233075 | L24: 11 | M24: 3.5
C25: Prop: | H25: Est Mass:
A26: Tiger Motor AT3520 550kv | C26: APC 14*7 | H26: ='Mass Breakdown'!H118 -> 0.218 | I26: =H26*2.2046 -> 0.4806028 | K26: =H26/$H$38 -> 0.085678506 | O26: 79.99
A28: Flight Battery | H28: ='Mass Breakdown'!H119 -> 0.693 | I28: =H28*2.2046 -> 1.5277878 | K28: =H28/$H$38 -> 0.27236333 | N28: Graphene 6S 4000 mah | O28: 89.14
A30: Landing Gear | H30: =I30/2.2046 -> 0.18424057 | I30: ='Mass Breakdown'!I114 -> 0.40617676 | K30: =H30/$H$38 -> 0.072410352
A32: Castle Talon 60A 6S ESC | H32: ='Mass Breakdown'!H120 -> 0.06 | I32: =H32*2.2046 -> 0.132276 | K32: =H32/H38 -> 0.02358124 | O32: 69.95
A34: Servos | H34: =SUM('Mass Breakdown'!H121:H124) -> 0.16 | I34: =H34*2.2046 -> 0.352736 | K34: =H34/$H$38 -> 0.062883307 | N34: Assuming 4 Savox SV-1260MG, which weigh 40g each | O34: =80*4 -> 320
A36: Cowling | H36: ='Mass Breakdown'!H125 -> 0.097 | I36: =H36*2.2046 -> 0.2138462 | K36: =H36/$H$38 -> 0.038123005
G38: Total Mass: | H38: =SUM(H18,H20,H22,H24,H26,H28,H30,H34,H36,H32) -> 2.5443954 | I38: kg | J38: =H38*2.2046 -> 5.6093742 | K38: lbs | N38: Total Cost: | O38: =SUM(O18:O35) -> 559.08
G39: Wing Loading: | H39: =(J38*16)/F18 -> 19.00588 | I39: oz/ft^2
G40: AT3520 Max Thrust: | H40: 4.116 | I40: kg
B41: Max Up | C41: =(((H40*9.81)-9.81*H38)/H38) -> 6.059373 | D41: m/s^2 | G41: T/W | H41: =H40/H38 -> 1.6176731 | I41: dim.
A42: Relevant Parameters
A43: Panel_Span | B43: 29.5 | C43: in
A44: Root_Chord | B44: 14.25 | C44: in
A45: Main_Spar_Root_Chord_Rel_Position | B45: 0.2 | C45: ul
A46: Main_Spar_Root_Height | B46: 1.5 | C46: in
...

Sheet Drag Polar
B2: Cd0 wing | C2: 0.012
B3: Cd0 misc | C3: 0.06
B4: K | C4: 0.063
B5: Cl | C5: 0.825
B7: Cd | C7: =C2+C3+(C4*(C5^2)) -> 0.11487937
E10: Cl | F10: Cd | G10: L/D
E11: 0.05 | F11: =$C$2+$C$3+($C$4*(E11^2)) -> 0.0721575 | G11: =E11/F11 -> 0.69292866
E12: 0.1 | F12: =$C$2+$C$3+($C$4*(E12^2)) -> 0.07263 | G12: =E12/F12 -> 1.3768415
E13: 0.15 | F13: =$C$2+$C$3+($C$4*(E13^2)) -> 0.0734175 | G13: =E13/F13 -> 2.0431096
E14: 0.2 | F14: =$C$2+$C$3+($C$4*(E14^2)) -> 0.07452 | G14: =E14/F14 -> 2.6838433
E15: 0.25 | F15: =$C$2+$C$3+($C$4*(E15^2)) -> 0.0759375 | G15: =E15/F15 -> 3.2921811
E16: 0.3 | F16: =$C$2+$C$3+($C$4*(E16^2)) -> 0.07767 | G16: =E16/F16 -> 3.8624952
E17: 0.35 | F17: =$C$2+$C$3+($C$4*(E17^2)) -> 0.0797175 | G17: =E17/F17 -> 4.390504
E18: 0.4 | F18: =$C$2+$C$3+($C$4*(E18^2)) -> 0.08208 | G18: =E18/F18 -> 4.8732943
E19: 0.45 | F19: =$C$2+$C$3+($C$4*(E19^2)) -> 0.0847575 | G19: =E19/F19 -> 5.3092647
E20: 0.5 | F20: =$C$2+$C$3+($C$4*(E20^2)) -> 0.08775 | G20: =E20/F20 -> 5.6980057
E21: 0.55 | F21: =$C$2+$C$3+($C$4*(E21^2)) -> 0.0910575 | G21: =E21/F21 -> 6.0401395
E22: 0.6 | F22: =$C$2+$C$3+($C$4*(E22^2)) -> 0.09468 | G22: =E22/F22 -> 6.3371356
... E40: 1.5 | F40: =$C$2+$C$3+($C$4*(E40^2)) -> 0.21375 | G40: =E40/F40 -> 7.0175439
B53: Cd0 wing | C53: 0.012
B54: Cd0 misc | C54: 0.06
B55: K | C55: 0.0585
B56: Cl | C56: 0.86
B58: Cd | C58: =C53+C54+(C55*(C56^2)) -> 0.1152666
E61: Cl | F61: Cd | G61: L/D
E62: 0.05 | F62: =$C$53+$C$54+($C$55*(E62^2)) -> 0.07214625 | G62: =E62/F62 -> 0.69303671
E63: 0.1 | F63: =$C$53+$C$54+($C$55*(E63^2)) -> 0.072585 | G63: =E63/F63 -> 1.3776951
E64: 0.15 | F64: =$C$53+$C$54+($C$55*(E64^2)) -> 0.07331625 | G64: =E64/F64 -> 2.0459312
E65: 0.2 | F65: =$C$53+$C$54+($C$55*(E65^2)) -> 0.07434 | G65: =E65/F65 -> 2.6903417
E66: 0.25 | F66: =$C$53+$C$54+($C$55*(E66^2)) -> 0.07565625 | G66: =E66/F66 -> 3.3044197
E67: 0.3 | F67: =$C$53+$C$54+($C$55*(E67^2)) -> 0.077265 | G67: =E67/F67 -> 3.8827412
E68: 0.35 | F68: =$C$53+$C$54+($C$55*(E68^2)) -> 0.07916625 | G68: =E68/F68 -> 4.4210759
E69: 0.4 | F69: =$C$53+$C$54+($C$55*(E69^2)) -> 0.08136 | G69: =E69/F69 -> 4.9164208
E70: 0.45 | F70: =$C$53+$C$54+($C$55*(E70^2)) -> 0.08384625 | G70: =E70/F70 -> 5.3669663
E71: 0.5 | F71: =$C$53+$C$54+($C$55*(E71^2)) -> 0.086625 | G71: =E71/F71 -> 5.7720058
E72: 0.55 | F72: =$C$53+$C$54+($C$55*(E72^2)) -> 0.08969625 | G72: =E72/F72 -> 6.131806
E73: 0.6 | F73: =$C$53+$C$54+($C$55*(E73^2)) -> 0.09306 | G73: =E73/F73 -> 6.4474533
... E91: 1.5 | F91: =$C$53+$C$54+($C$55*(E91^2)) -> 0.203625 | G91: =E91/F91 -> 7.3664825

Sheet Estimated Inertias
B1: Mass: | C1: Ixx | D1: Iyy | E1: Izz | F1: Ixy
A2: Airframe | B2: 5.03
A3: Systems
A4: Overall | B4: 5.16 | C4: 380.5 | D4: 1035.57 | E4: 1355.75 | F4: 23.67 | I4: Missing LH aileron servo, MLG, Tail gear,
C5: =C4/12 -> 31.708333 | D5: =D4/12 -> 86.2975 | E5: =E4/12 -> 112.97917 | F5: =F4/12 -> 1.9725
G9: x | H9: y | I9: z
A10: According to master Assy | B10: 5.53 | C10: 358.88 | D10: 782.02 | E10: 1084.15 | F10: -11.98 | G10: 3.24 | H10: 0 | I10: -0.17
C11: =C10/144 -> 2.4922222 | D11: =D10/144 -> 5.4306944 | E11: =E10/144 -> 7.5288194 | F11: =F10/144 -> -0.083194444

Sheet Cost Breakdown
B1: Price per: | C1: Number | D1: Total Cost
D2: =C2*B2 -> 0
A3: Wing
A5: Fuselage | D5: =C5*B5 -> 0
D6: =C6*B6 -> 0
A7: H-Tail | D7: =C7*B7 -> 0
D8: =C8*B8 -> 0
A9: V-Tail | D9: =C9*B9 -> 0
D10: =C10*B10 -> 0
A11: T-Motor AT3520 500 kv | B11: 79.99 | C11: 1 | D11: =C11*B11 -> 79.99
D12: =C12*B12 -> 0
A13: Graphene 6S 4000 mah | B13: 89.14 | C13: 2 | D13: =C13*B13 -> 178.28
D14: =C14*B14 -> 0
A15: Landing Gear | D15: =C15*B15 -> 0
D16: =C16*B16 -> 0
A17: Castle 60A ESC | B17: 69.95 | C17: 1 | D17: =C17*B17 -> 69.95
D18: =C18*B18 -> 0
A19: Assuming 4 Savox SV-1260MG, which weigh 40g each | B19: 79.99 | C19: 4 | D19: =C19*B19 -> 319.96
A20: 1.25" Aluminum Servo Arms 25T | B20: 5.99 | C20: 4 | D20: =C20*B20 -> 23.96
A21: Control Horns
A22: Ball Joints
A23: 4-40 Threaded Rod
A26: Total Cost: | D26: =SUM(D1:D20) -> 672.14

Sheet New Stress Hand-Calcs
A1: Safety Factors:
A2: Ult Safety Factor: | B2: 2.25
A3: Yield Safety Factor: | B3: 1.75
A4: Carbon Spar at Wing Root:
B5: FEM: | C5: Hand-Calcs:
A6: Outer Diameter: | B6: ='Progressive Analysis'!B60/2 -> 0.5 | C6: =B6 -> 0.5 | D6: in
A7: Inner Diameter: | B7: =0.905512/2 -> 0.452756 | C7: =0.905512/2 -> 0.452756 | D7: in
A8: I: | B8: =PI()*(1/4)*((B6^4)-(B7^4)) -> 0.016084893 | C8: =PI()*(1/4)*((C6^4)-(C7^4)) -> 0.016084893 | D8: in^4
A9: Stress in CF Spar | B9: 0 | C9: =(#REF!*('New Stress Hand-Calcs'!C6/2)/'New Stress Hand-Calcs'!C8)/1000 -> #REF! | D9: ksi
A10: MS: | B10: ='Material Properties'!$B$90/(B9*$B$2)-1 -> #DIV/0! | C10: ='Material Properties'!$B$90/(C9*$B$2)-1 -> #REF! | D10: dim.
A13: Wood Spar at Wing Root:
A14: Est Moment (for reference): | B14: =F15 -> 343.68 | C14: in-lbs | D14: 32.2 | E14: ft-lbs | F14: =D14*12 -> 386.4
A15: Big Rectangle Height: | B15: 1.875 | C15: in | D15: 28.64 | F15: =D15*12 -> 343.68
A16: Big Rectangle outer width: | B16: 0.5 | C16: in
A17: Small Rectangle inner Height: | B17: =B15-('Progressive Analysis'!B47*2) -> 1.375 | C17: in
A18: Small Rectangle inner width: | B18: =B16-0.125 -> 0.375 | C18: in
A19: Big Rectangle I: | B19: =(1/12)*(B16*(B15^3)) -> 0.2746582 | C19: in^4
A20: Small Rectange I: | B20: =(1/12)*(B18*(B17^3)) -> 0.081237793 | C20: in^4
A21: Total I: | B21: =B19-B20 -> 0.19342041 | C21: in^4
A23: Max Tensile Stress: | B23: =(B14*(B15/2))/B21 -> 1665.8015 | C23: psi

Sheet Wing Stress
