Workbook

Sheet Combustion Analysis
A1: Propellant Properties:
B2: LOX | D2: Pure Ethanol | G2: Liquid Water | K2: Net Fuel
A3: Density | B3: 1141 | D3: 789.3 | E3: kg/m^3 | G3: 998 | H3: kg/m^3 | K3: =(0.7*D3)+(0.3*G3) -> 851.91 | L3: kg/m^3
A4: Heat of Combustion: | B4: N/A | D4: 1336 | E4: kJ/mol
A5: Cp: | I5: *NOTE THAT THESE NUMBERS ARE ALL APPROXIMATE
A6: Molar Mass: (Assuming O2) | B6: 0.032 | C6: kg/mol | D6: 0.04607 | E6: kg/mol | G6: 0.0180153 | H6: kg/mol
A7: Boiling Point | B7: 90.19 | C7: K | D7: 351.39 | E7: K | G7: 373.2 | H7: K
A10: Exhaust Gas Properties:
B11: CO2 | D11: H2O | G11: Ethanol
A12: Molecular Mass: | B12: =0.04401 -> 0.04401 | D12: 0.01802 | E12: kg/mol
A13: Cp: | B13: 1.326 | D13: 2.609 | E13: kJ/(kg*K) | F13: at 1500 K
A14: Cp: | B14: =B13*B12 -> 0.05835726 | D14: =D13*D12 -> 0.04701418 | E14: kJ/mol*K | G14: 0.074 | H14: kJ/mol*K
A15: Specific Volume:
A16: Theoretical:
A17: mol of CO2 per mol of ethanol | B17: 2 | D17: From the Balanced Stochiometric Chemical Equation
A18: mol of water per mol of ethanol | B18: 3 | D18: From the Balanced Stochiometric Chemical Equation
A20: Amount of Ethanol Per kg of Fuel | B20: =B67 -> 0.7 | C20: kg | D20: =B20/D6 -> 15.19427 | E20: mol
A21: Amount of Water Per kg of Fuel | B21: =1-B67 -> 0.3 | C21: kg | D21: =B21/G6 -> 16.652512 | E21: mol
A23: Propellants at current Mixture Ratio:
A24: Total Amount of O2 | B24: =B63 -> 1.26 | C24: kg | D24: =B24/B6 -> 39.375 | E24: mol | I24: Net Chemical Equation, Including Extras:
A25: Total Amount of fuel | B25: 1 | C25: kg | I25: XH2O + YC2H5OH + ZO2 + (C2H5OH + O2) → (2CO2 + 3H2O) + XH20 + YC2H5OH + ZO2
A26: Total Mass: | B26: =SUM(B24,B25) -> 2.26 | C26: kg | F26: This is used as a check for my calculations. Should be Equal to B36
A28: Contents:
A29: Total Amount of ethanol: | B29: =D29*D6 -> 0.7 | C29: kg | D29: =D20 -> 15.19427 | E29: mol
A30: Combustion Ethanol: | B30: =D30*D6 -> 0.60466875 | C30: kg | D30: =D24/3 -> 13.125 | E30: mol | F30: Ensure this stays updated. Probably only true if Engine runs Fuel Rich
A31: Amount of Extra water (X) | B31: =B21 -> 0.3 | C31: kg | D31: =D21 -> 16.652512 | E31: mol | P31: =D30/P32 -> 0.18428351
A32: Amount of Extra Ethanol (Y) | B32: =D32*D6 -> 0.09533125 | C32: kg | D32: =D29-D30 -> 2.0692696 | E32: mol | F32: Ensure this stays updated. Only Positive if engine runs fuel Rich | P32: =D29+D31+D33 -> 71.221782
A33: Combustion Oxygen: | B33: =D33*B6 -> 1.26 | C33: kg | D33: =D24 -> 39.375 | E33: mol
A34: Amount of Extra O2 (Z) | B34: =D34*B6 -> 0 | C34: kg | D34: =D24-D33 -> 0 | E34: mol | F34: Ensure this stays updated. Only 0 if engine runs fuel rich.
A35: Total Mass: | B35: =SUM(B29,B31,B33,B34) -> 2.26 | C35: kg | F35: This is used as a check for my calculations. Should be Equal to B26
A36: Combusting Mass: | B36: =SUM(B30,B33) -> 1.8646687 | C36: kg | F36: This is used as a check for my calculations. Should be Equal to B41
A38: Products for a kg of fuel
A39: Amount of combustion-product CO2: | B39: =D39*B12 -> 1.1552625 | D39: =B17*D30 -> 26.25 | E39: mol
A40: Amount of Combustion-product H2O: | B40: =D40*D12 -> 0.7095375 | D40: =(B18*D30) -> 39.375 | E40: mol
A41: Combusting Mass: | B41: =SUM(B39:B40) -> 1.8648 | C41: kg | F41: This is used as a check for my calculations. Should be Equal to B36
A43: Total Exhaust Gases:
A44: CO2: | B44: =D44*B12 -> 1.1552625 | C44: kg | D44: =D39 -> 26.25 | E44: mol
A45: Total Water: | B45: =D45*D12 -> 1.0096158 | C45: kg | D45: =D40+D31 -> 56.027512 | E45: mol
A46: Extra Ethanol: (Y) | B46: =D46*D6 -> 0.09533125 | C46: kg | D46: =D32 -> 2.0692696 | E46: mol
A47: Extra O2 (Z) | B47: =D47*B6 -> 0 | C47: kg | D47: =D34 -> 0 | E47: mol
...

Sheet Engine Requirements
A1: Chamber Details
A2: Chamber Pressure: | B2: 332 | C2: psi | D2: =B2*6894.76 -> 2289060.3 | E2: Pa | F2: =D2/1000 -> 2289.0603 | G2: kPa
A3: Target Thrust: | B3: 250 | C3: lbf | D3: =B3/2.2 -> 113.63636 | E3: kg | F3: =D3*9.8 -> 1113.6364 | G3: N
A4: Chamber Thrust: | B4: =(B2-B44)*B42 -> 170.55087 | C4: lbf | D4: =B4/2.2 -> 77.523124 | E4: kg | F4: =B4*4.44822 -> 758.64781 | G4: N
A5: Estimated Actual Thrust: | B5: =B4*B45 -> 0 | C5: lbf | D5: =B5/2.2 -> 0 | E5: kg | F5: =B5*0.00444822 -> 0 | G5: N
A6: Theoretical Max Isp: | B6: ='Combustion Analysis'!B80 -> 208.99863 | C6: s
A7: Exhaust gas Velocity: | B7: =B6*9.8 -> 2048.1866 | C7: m/s
A8: Mass flow rate: | B8: =F3/B7 -> 0.54371822 | C8: kg/s
A9: Engine O.D. | B9: 4 | C9: in
A10: Cylindrical Chamber Length | B10: 0.787 | C10: in
A11: Chamber I.D. | B11: 3.5 | C11: in
A12: Distance from Chamber to Throat | B12: 4 | C12: in | D12: =B12*0.0254 -> 0.1016 | E12: m
A14: Possible design I.D. | B14: 1.53 | C14: in
A15: Rough Design-Chamb Vol: | B15: =(PI()*(B14/2)^2)*B12 -> 7.3541542 | C15: in^3 | D15: =B15/6123.7 -> 0.0012009331 | E15: m^3
A16: Design Stay Time: | B16: =D15/('Solution of Isentropic Expansio'!D47*'Engine Requirements'!B24) -> 0.0052811033 | C16: s
A18: Chamber Volume incl. Conv nozzle | D18: =F18/1000000 -> 0.000376281 | E18: m^3 | F18: 376.281 | G18: cm^3 | H18: Update please
A20: Injector Stuff
A21: Target Mixture Ratio: | B21: 1.26 | C21: kg O2/kg fuel
A22: Oxidizer Mass Flow Rate: | B22: =B21*B8/(B21+1) -> 0.30313494 | C22: kg/s
A23: Fuel Mass Flow Rate: | B23: =B8/(B21+1) -> 0.24058328 | C23: kg/s
A24: Total Mass Flow Rate: | B24: =SUM(B22,B23) -> 0.54371822 | C24: kg/s
A25: Oxidizer Volum. Flow Rate: | B25: =B22/'Combustion Analysis'!B3 -> 0.00026567479 | C25: m^3/s | D25: =B25*1000000 -> 265.67479 | E25: cm^3/s | F25: =B25*61023.7 -> 16.212459
A26: Fuel Volum. Flow Rate: | B26: =B23/'Combustion Analysis'!K3 -> 0.00028240458 | C26: m^3/s | D26: =B26*1000000 -> 282.40458 | E26: cm^3/s | F26: =B26*61023.7 -> 17.233372
A27: Total Volumetric Flow Rate: | B27: =B25+B26 -> 0.00054807937 | C27: m^3/s | D27: =B27*1000000 -> 548.07937 | E27: cm^3/s | F27: =B27*61023.7 -> 33.445831 | G27: in^3/s | H27: =B27*3600 -> 1.9730857 | I27: m^3/h | J27: =B27*264.172 -> 0.14478722 | K27: GPM
A28: Ox holes per injector | B28: 17
A29: Oxidizer Injector hole diameter | B29: =2*SQRT((B25/(B28*B32*PI()))) -> 0.00081441384 | C29: m | D29: =B29*100 -> 0.081441384 | E29: cm | F29: =D29*0.393701 -> 0.032063554 | G29: in
A30: Fuel holes per injector | B30: 18
A31: Fuel Injector hole diameter | B31: =2*SQRT((B26/(B30*B34*PI()))) -> 0.0008160073 | C31: m | D31: =B31*100 -> 0.08160073 | E31: cm | F31: =D31*0.393701 -> 0.032126289 | G31: in
A32: Ox injector velocity | B32: 30 | C32: m/s | H32: Double check this number with Fluid Mechanics
A33: Ox injector Re | C33: mvl/v
A34: Fuel injector velocity | B34: 30 | C34: m/s | H34: Double check this number with Fluid Mechanics
A35: Delta-P as percent of Chamb Press | B35: 0.14
A36: Ox injector Target delta-P | B36: =B35*B2 -> 46.48 | C36: psi
A37: Fuel injector Target delta-P | B37: =B35*B2 -> 46.48 | C37: psi
A38: Target Flow Supply Pressure | B38: =B2+B36 -> 378.48
A40: Nozzle Specs
A41: Throat Diameter | B41: ='Solution of Isentropic Expansio'!I26 -> 0.82663628 | C41: in | D41: =B41*0.0254 -> 0.020996562 | E41: m
A42: Throat Area At | B42: =PI()*(B41/2)^2 -> 0.5366842 | C42: in^2
A43: Thrust Coefficient | B43: 0.98 | H43: Pulled from RPA. I don't know how accurate it is
A44: Ambient Air Pressure | B44: =F44*0.145038 -> 14.213724 | C44: Psi | D44: =F44*1000 -> 98000 | E44: Pa | F44: 98 | G44: kPa
...

Sheet Test and practical stuff
A1: Max Test duration | B1: 8 | C1: s
A2: Prop safety Margin | B2: 1.25 | C2: dim
A3: Oxidizer Mass req'd: | B3: =B1*'Engine Requirements'!B22 -> 2.4250795 | C3: kg
A4: Fuel Mass req'd: | B4: =B1*'Engine Requirements'!B23 -> 1.9246663 | C4: kg
B6: Stress Pressure | C6: 1000 | D6: PSI | E6: =C6*6894.76 -> 6894760 | F6: Pa
C7: 2.5 | D7: dim. | E7: ='Engine Requirements'!D2*'Test and practical stuff'!C7 -> 5722650.8 | F7: Pa
A8: Line OD | B8: Wall Thickness | C8: Line ID | D8: Area (in^2) | E8: Area (m^2) | F8: Feed Flow Velocity (m/s) | G8: Ox Flow Velocity | H8: Fuel Flow Velocity | I8: Wall Stress (MPa) | K8: Price
A9: 0.25 | B9: 0.035 | C9: =A9-(2*B9) -> 0.18 | D9: =PI()*(C9/2)^2 -> 0.0254469 | E9: =D9/1550 -> 1.6417355e-05 | F9: ='Engine Requirements'!$B$27/'Test and practical stuff'!E9 -> 33.384145 | G9: ='Engine Requirements'!$B$25/'Test and practical stuff'!E9 -> 16.182557 | H9: ='Engine Requirements'!$B$26/'Test and practical stuff'!E9 -> 17.201588 | I9: =((C9*'Test and practical stuff'!$E$7)/(2*'Test and practical stuff'!B9))/1000000 -> 14.715388
A10: 0.25 | B10: 0.049 | C10: =A10-(2*B10) -> 0.152 | D10: =PI()*(C10/2)^2 -> 0.018145839 | E10: =D10/1550 -> 1.1706993e-05 | F10: ='Engine Requirements'!$B$27/'Test and practical stuff'!E10 -> 46.816408 | G10: ='Engine Requirements'!$B$25/'Test and practical stuff'!E10 -> 22.693683 | H10: ='Engine Requirements'!$B$26/'Test and practical stuff'!E10 -> 24.122725 | I10: =((C10*'Test and practical stuff'!$E$7)/(2*'Test and practical stuff'!B10))/1000000 -> 8.8759482
A11: 0.25 | B11: 0.065 | C11: =A11-(2*B11) -> 0.12 | D11: =PI()*(C11/2)^2 -> 0.011309734 | E11: =D11/1550 -> 7.2966023e-06 | F11: ='Engine Requirements'!$B$27/'Test and practical stuff'!E11 -> 75.114326 | G11: ='Engine Requirements'!$B$25/'Test and practical stuff'!E11 -> 36.410754 | H11: ='Engine Requirements'!$B$26/'Test and practical stuff'!E11 -> 38.703573 | I11: =((C11*'Test and practical stuff'!$E$7)/(2*'Test and practical stuff'!B11))/1000000 -> 5.2824469
A12: 0.3125 | B12: 0.049 | C12: =A12-(2*B12) -> 0.2145 | D12: =PI()*(C12/2)^2 -> 0.036136366 | E12: =D12/1550 -> 2.3313784e-05 | F12: ='Engine Requirements'!$B$27/'Test and practical stuff'!E12 -> 23.508812 | G12: ='Engine Requirements'!$B$25/'Test and practical stuff'!E12 -> 11.39561 | H12: ='Engine Requirements'!$B$26/'Test and practical stuff'!E12 -> 12.113202 | I12: =((C12*'Test and practical stuff'!$E$7)/(2*'Test and practical stuff'!B12))/1000000 -> 12.525598
A13: 0.3125 | B13: 0.065 | C13: =A13-(2*B13) -> 0.1825 | D13: =PI()*(C13/2)^2 -> 0.026158668 | E13: =D13/1550 -> 1.687656e-05 | F13: ='Engine Requirements'!$B$27/'Test and practical stuff'!E13 -> 32.475776 | G13: ='Engine Requirements'!$B$25/'Test and practical stuff'!E13 -> 15.742236 | H13: ='Engine Requirements'!$B$26/'Test and practical stuff'!E13 -> 16.733539 | I13: =((C13*'Test and practical stuff'!$E$7)/(2*'Test and practical stuff'!B13))/1000000 -> 8.0337213
A14: 0.375 | B14: 0.035 | C14: =A14-(2*B14) -> 0.305 | D14: =PI()*(C14/2)^2 -> 0.073061664 | E14: =D14/1550 -> 4.7136558e-05 | F14: ='Engine Requirements'!$B$27/'Test and practical stuff'!E14 -> 11.62748 | G14: ='Engine Requirements'!$B$25/'Test and practical stuff'!E14 -> 5.636279 | H14: ='Engine Requirements'!$B$26/'Test and practical stuff'!E14 -> 5.9912007 | I14: =((C14*'Test and practical stuff'!$E$7)/(2*'Test and practical stuff'!B14))/1000000 -> 24.934407
A15: 0.375 | B15: 0.049 | C15: =A15-(2*B15) -> 0.277 | D15: =PI()*(C15/2)^2 -> 0.060262816 | E15: =D15/1550 -> 3.8879236e-05 | F15: ='Engine Requirements'!$B$27/'Test and practical stuff'!E15 -> 14.096969 | G15: ='Engine Requirements'!$B$25/'Test and practical stuff'!E15 -> 6.8333336 | H15: ='Engine Requirements'!$B$26/'Test and practical stuff'!E15 -> 7.2636349 | I15: =((C15*'Test and practical stuff'!$E$7)/(2*'Test and practical stuff'!B15))/1000000 -> 16.175248
A16: 0.375 | B16: 0.058 | C16: =A16-(2*B16) -> 0.259 | D16: =PI()*(C16/2)^2 -> 0.052685294 | E16: =D16/1550 -> 3.3990512e-05 | F16: ='Engine Requirements'!$B$27/'Test and practical stuff'!E16 -> 16.124481 | G16: ='Engine Requirements'!$B$25/'Test and practical stuff'!E16 -> 7.8161455 | H16: ='Engine Requirements'!$B$26/'Test and practical stuff'!E16 -> 8.3083354 | I16: =((C16*'Test and practical stuff'!$E$7)/(2*'Test and practical stuff'!B16))/1000000 -> 12.777298
A17: 0.375 | B17: 0.065 | C17: =A17-(2*B17) -> 0.245 | D17: =PI()*(C17/2)^2 -> 0.047143525 | E17: =D17/1550 -> 3.0415177e-05 | F17: ='Engine Requirements'!$B$27/'Test and practical stuff'!E17 -> 18.01993 | G17: ='Engine Requirements'!$B$25/'Test and practical stuff'!E17 -> 8.7349414 | H17: ='Engine Requirements'!$B$26/'Test and practical stuff'!E17 -> 9.2849887 | I17: =((C17*'Test and practical stuff'!$E$7)/(2*'Test and practical stuff'!B17))/1000000 -> 10.784996
A18: 0.4375 | B18: 0.035 | C18: =A18-(2*B18) -> 0.3675 | D18: =PI()*(C18/2)^2 -> 0.10607293 | E18: =D18/1550 -> 6.8434149e-05 | F18: ='Engine Requirements'!$B$27/'Test and practical stuff'!E18 -> 8.0088578 | G18: ='Engine Requirements'!$B$25/'Test and practical stuff'!E18 -> 3.8821962 | H18: ='Engine Requirements'!$B$26/'Test and practical stuff'!E18 -> 4.1266616 | I18: =((C18*'Test and practical stuff'!$E$7)/(2*'Test and practical stuff'!B18))/1000000 -> 30.043917
A19: 0.4375 | B19: 0.065 | C19: =A19-(2*B19) -> 0.3075 | D19: =PI()*(C19/2)^2 -> 0.074264305 | E19: =D19/1550 -> 4.7912455e-05 | F19: ='Engine Requirements'!$B$27/'Test and practical stuff'!E19 -> 11.439184 | G19: ='Engine Requirements'!$B$25/'Test and practical stuff'!E19 -> 5.5450048 | H19: ='Engine Requirements'!$B$26/'Test and practical stuff'!E19 -> 5.8941788 | I19: =((C19*'Test and practical stuff'!$E$7)/(2*'Test and practical stuff'!B19))/1000000 -> 13.53627
A20: 0.5 | B20: 0.028 | C20: =A20-(2*B20) -> 0.444 | D20: =PI()*(C20/2)^2 -> 0.15483025 | E20: =D20/1550 -> 9.9890485e-05 | F20: ='Engine Requirements'!$B$27/'Test and practical stuff'!E20 -> 5.4868025 | G20: ='Engine Requirements'!$B$25/'Test and practical stuff'!E20 -> 2.6596606 | H20: ='Engine Requirements'!$B$26/'Test and practical stuff'!E20 -> 2.8271419 | I20: =((C20*'Test and practical stuff'!$E$7)/(2*'Test and practical stuff'!B20))/1000000 -> 45.372446
... A26: 0.5 | B26: 0.12 | C26: =A26-(2*B26) -> 0.26 | D26: =PI()*(C26/2)^2 -> 0.053092916 | E26: =D26/1550 -> 3.4253494e-05 | F26: ='Engine Requirements'!$B$27/'Test and practical stuff'!E26 -> 16.000685 | G26: ='Engine Requirements'!$B$25/'Test and practical stuff'!E26 -> 7.7561369 | H26: ='Engine Requirements'!$B$26/'Test and practical stuff'!E26 -> 8.244548 | I26: =((C26*'Test and practical stuff'!$E$7)/(2*'Test and practical stuff'!B26))/1000000 -> 6.1995384
A28: 0.625
A30: Oxidizer Tank Stuff:
A31: Oxidizer Volume Req'd | B31: =B1*'Engine Requirements'!B25 -> 0.0021253983 | C31: m^3 | D31: =B31*1000 -> 2.1253983 | E31: liters
A32: Oxidizer Tank Inner Diameter | B32: =D32*0.0254 -> 0.0889 | C32: m | D32: 3.5 | E32: Inches
A33: Oxidizer Tank Depth Required | B33: =B31/(PI()*(B32/2)^2) -> 0.34241039 | C33: m | D33: =B33*39.3701 -> 13.480731 | E33: Inches
A36: Fuel Tank Stuff:
A37: Fuel Volume Req'd: | B37: ='Engine Requirements'!B26*'Test and practical stuff'!B1 -> 0.0022592366 | C37: m^3 | D37: =B37*1000 -> 2.2592366 | E37: liters
A38: Fuel Tank Inner Diameter | B38: =D38*0.0254 -> 0.0889 | C38: m | D38: 3.5 | E38: Inches
A39: Fuel Tank Depth Required | B39: =B37/(PI()*(B38/2)^2) -> 0.36397228 | C39: m | D39: =B39*39.3701 -> 14.329625 | E39: Inches
A41: Feed System Stuff
A42: Gas Volum Req'd by Engine: | B42: =B31+B37 -> 0.0043846349 | C42: m^3 | D42: =B42*1000 -> 4.3846349 | E42: liters | F42: =B42*35.3147 -> 0.15484207 | G42: ft^3 | I42: At System Pressure, not including Pneumatics

Sheet Strength Analysis
A1: Material Properties: | B1: Yield Stress | F1: Ultimate
A2: Aluminum 6061-T6 Room Temp | B2: 35 | C2: Ksi | D2: =B2*6.89476 -> 241.3166 | E2: MPa | F2: 42 | G2: Ksi | H2: =F2*6.89476 -> 289.57992 | I2: Mpa
A5: Generalized Prop Tank Analysis ---NOTE THAT I ASSUMED THIN WALLS, WHICH IS NOT A GREAT ASSUMPTION IN THIS CASE.
A6: Max Service Pressure: | B6: 1000 | C6: PSI | D6: =B6*6894.76 -> 6894760 | E6: Pa
A7: Proof Pressure: | B7: =B6*1.5 -> 1500 | C7: PSI | D7: =B7*6894.76 -> 10342140 | E7: Pa
A8: Burst Pressure:` | B8: =B6*2.5 -> 2500 | C8: PSI | D8: =B8*6894.76 -> 17236900 | E8: Pa
A10: Aluminum 6061-O, assuming T6 is lost in the welding process
A11: "Typical" Yield Strenth: | B11: 55 | C11: MPa | D11: =B11*0.14504 -> 7.9772 | E11: ksi | F11: Source: | G11: Matweb
A12: Ultimate Tensile Strength | B12: 124 | C12: Mpa | D12: =B12*0.14504 -> 17.98496 | E12: ksi
A13: Tank inner diameter: | B13: ='Test and practical stuff'!B32 -> 0.0889 | C13: m
A14: Wall thickness: | B14: =D14*0.0254 -> 0.00635 | C14: m | D14: 0.25 | E14: in
A15: Service Pressure Hoop Stress: | B15: =(B13*D6)/(2*B14) -> 48263320 | C15: Pa | D15: =B15/1000000 -> 48.26332 | E15: Mpa
A16: Service Pressure Factor of Safety: | B16: =B11/D15 -> 1.1395818 | C16: dim.
A17: Service Pressure Margin of Safety: | B17: =B16-1 -> 0.13958178 | C17: dim.
A18: Proof Pressure Hoop Stress: | B18: =(B13*D7)/(2*B14) -> 72394980 | C18: Pa | D18: =B18/1000000 -> 72.39498 | E18: Mpa
A19: Proof Pressure Factor of Safety: | B19: =B11/D18 -> 0.75972119 | C19: dim.
A20: Proof Pressure Margin of Safety: | B20: =B19-1 -> -0.24027881 | C20: dim.
A21: Burst Pressure Hoop Stress: | B21: =(B13*D8)/(2*B14) -> 120658300 | C21: Pa | D21: =B21/1000000 -> 120.6583 | E21: Mpa
A22: Burst Pressure Factor of Safety: | B22: =B12/D21 -> 1.0276956 | C22: dim.
A23: Burst Pressure Margin of Safety: | B23: =B22-1 -> 0.027695567 | C23: dim.
A25: Longitudinal Stress
A26: Service Longitudinal Stress: | B26: =(D6*B13)/(4*B14) -> 24131660 | C26: Pa | D26: =B26/1000000 -> 24.13166 | E26: Mpa
A27: Service Factor of Safety: | B27: =B11/D26 -> 2.2791636 | C27: dim.
A28: Service Margin of Safety: | B28: =B27-1 -> 1.2791636 | C28: dim.
A29: Proof Longitudinal Stress: | B29: =(D7*B13)/(4*B14) -> 36197490 | C29: Pa | D29: =B29/1000000 -> 36.19749 | E29: MPa
A30: Proof Factor of Safety: | B30: =B11/D29 -> 1.5194424 | C30: dim.
A31: Proof Margin of Safety: | B31: =B30-1 -> 0.51944237 | C31: dim.
A32: Burst Longitudinal Stress: | B32: =(D8*B13)/(4*B14) -> 60329150 | C32: Pa | D32: =B32/1000000 -> 60.32915 | E32: Mpa
A33: Burst Factor of Safety: | B33: =B12/D32 -> 2.0553911 | C33: dim.
A34: Burst Margin of Safety: | B34: =B33-1 -> 1.0553911 | C34: dim.
A36: Steel 304
A37: "Typical" Yield Strenth: | B37: =D37*6.8948 -> 179.2648 | C37: MPa | D37: 26 | E37: ksi | F37: Source: | G37: MMPDS
A38: Ultimate Tensile Strength | B38: =D38*6.8948 -> 503.3204 | C38: Mpa | D38: 73 | E38: ksi | F38: Source: | G38: MMPDS
A39: Tank inner diameter: | B39: ='Test and practical stuff'!B32 -> 0.0889 | C39: m
A40: Wall thickness: | B40: =D40*0.0254 -> 0.00635 | C40: m | D40: 0.25 | E40: in
A41: Service Pressure Hoop Stress: | B41: =(B39*D6)/(2*B40) -> 48263320 | C41: Pa | D41: =B41/1000000 -> 48.26332 | E41: Mpa
A42: Service Pressure Factor of Safety: | B42: =B37/D41 -> 3.7143073 | C42: dim.
A43: Service Pressure Margin of Safety: | B43: =B42-1 -> 2.7143073 | C43: dim.
A44: Proof Pressure Hoop Stress: | B44: =(B39*D7)/(2*B40) -> 72394980 | C44: Pa | D44: =B44/1000000 -> 72.39498 | E44: Mpa
A45: Proof Pressure Factor of Safety: | B45: =B37/D44 -> 2.4762048 | C45: dim.
...

Sheet Solution of Isentropic Expansio
A1: Pressure (kPa) | B1: Pressure (Pa) | C1: Temperature (K) | D1: Specific Volume: | E1: V2 (m/s) | F1: Area: (m^2) | G1: Area: (in^2) | H1: Diameter: (m) | I1: Diameter: (in) | K1: Mach: (m/s)
A2: 98 | B2: =A2*1000 -> 98000 | C2: ='Engine Requirements'!$G$62*(B2/'Engine Requirements'!$K$62)^(('Combustion Analysis'!$B$58-1)/'Combustion Analysis'!$B$58) -> 1418.9639 | D2: ='Engine Requirements'!$J$62*('Engine Requirements'!$K$62/B2)^(1/'Combustion Analysis'!$B$58) -> 4.4928891 | E2: =SQRT(((2*'Combustion Analysis'!$B$58)/('Combustion Analysis'!$B$58-1))*'Combustion Analysis'!$B$69*'Engine Requirements'!$G$62*(1-('Solution of Isentropic Expansio'!B2/'Engine Requirements'!$K$62)^(('Combustion Analysis'!$B$58-1)/'Combustion Analysis'!$B$58))) -> 2050.2766 | F2: =('Engine Requirements'!$B$24*'Solution of Isentropic Expansio'!D2)/'Solution of Isentropic Expansio'!E2 -> 0.001191481 | G2: =F2*1550 -> 1.8467956 | H2: =(2*SQRT(F2/PI())) -> 0.038949208 | I2: =H2*39.3701 -> 1.5334342 | K2: =SQRT('Combustion Analysis'!$B$58*'Combustion Analysis'!$B$69*'Solution of Isentropic Expansio'!C2) -> 765.00479
A3: 100 | B3: =A3*1000 -> 100000 | C3: ='Engine Requirements'!$G$62*(B3/'Engine Requirements'!$K$62)^(('Combustion Analysis'!$B$58-1)/'Combustion Analysis'!$B$58) -> 1426.0809 | D3: ='Engine Requirements'!$J$62*('Engine Requirements'!$K$62/B3)^(1/'Combustion Analysis'!$B$58) -> 4.4251153 | E3: =SQRT(((2*'Combustion Analysis'!$B$58)/('Combustion Analysis'!$B$58-1))*'Combustion Analysis'!$B$69*'Engine Requirements'!$G$62*(1-('Solution of Isentropic Expansio'!B3/'Engine Requirements'!$K$62)^(('Combustion Analysis'!$B$58-1)/'Combustion Analysis'!$B$58))) -> 2045.9225 | F3: =('Engine Requirements'!$B$24*'Solution of Isentropic Expansio'!D3)/'Solution of Isentropic Expansio'!E3 -> 0.0011760053 | G3: =F3*1550 -> 1.8228083 | H3: =(2*SQRT(F3/PI())) -> 0.038695433 | I3: =H3*39.3701 -> 1.5234431 | K3: =SQRT('Combustion Analysis'!$B$58*'Combustion Analysis'!$B$69*'Solution of Isentropic Expansio'!C3) -> 766.92087
A4: 150 | B4: =A4*1000 -> 150000 | C4: ='Engine Requirements'!$G$62*(B4/'Engine Requirements'!$K$62)^(('Combustion Analysis'!$B$58-1)/'Combustion Analysis'!$B$58) -> 1576.7109 | D4: ='Engine Requirements'!$J$62*('Engine Requirements'!$K$62/B4)^(1/'Combustion Analysis'!$B$58) -> 3.2616792 | E4: =SQRT(((2*'Combustion Analysis'!$B$58)/('Combustion Analysis'!$B$58-1))*'Combustion Analysis'!$B$69*'Engine Requirements'!$G$62*(1-('Solution of Isentropic Expansio'!B4/'Engine Requirements'!$K$62)^(('Combustion Analysis'!$B$58-1)/'Combustion Analysis'!$B$58))) -> 1951.4913 | F4: =('Engine Requirements'!$B$24*'Solution of Isentropic Expansio'!D4)/'Solution of Isentropic Expansio'!E4 -> 0.00090875854 | G4: =F4*1550 -> 1.4085757 | H4: =(2*SQRT(F4/PI())) -> 0.034015692 | I4: =H4*39.3701 -> 1.3392012 | K4: =SQRT('Combustion Analysis'!$B$58*'Combustion Analysis'!$B$69*'Solution of Isentropic Expansio'!C4) -> 806.40742
A5: 200 | B5: =A5*1000 -> 200000 | C5: ='Engine Requirements'!$G$62*(B5/'Engine Requirements'!$K$62)^(('Combustion Analysis'!$B$58-1)/'Combustion Analysis'!$B$58) -> 1693.1381 | D5: ='Engine Requirements'!$J$62*('Engine Requirements'!$K$62/B5)^(1/'Combustion Analysis'!$B$58) -> 2.6268956 | E5: =SQRT(((2*'Combustion Analysis'!$B$58)/('Combustion Analysis'!$B$58-1))*'Combustion Analysis'!$B$69*'Engine Requirements'!$G$62*(1-('Solution of Isentropic Expansio'!B5/'Engine Requirements'!$K$62)^(('Combustion Analysis'!$B$58-1)/'Combustion Analysis'!$B$58))) -> 1875.2468 | F5: =('Engine Requirements'!$B$24*'Solution of Isentropic Expansio'!D5)/'Solution of Isentropic Expansio'!E5 -> 0.00076165495 | G5: =F5*1550 -> 1.1805652 | H5: =(2*SQRT(F5/PI())) -> 0.031141118 | I5: =H5*39.3701 -> 1.2260289 | K5: =SQRT('Combustion Analysis'!$B$58*'Combustion Analysis'!$B$69*'Solution of Isentropic Expansio'!C5) -> 835.65049
A6: 250 | B6: =A6*1000 -> 250000 | C6: ='Engine Requirements'!$G$62*(B6/'Engine Requirements'!$K$62)^(('Combustion Analysis'!$B$58-1)/'Combustion Analysis'!$B$58) -> 1789.3345 | D6: ='Engine Requirements'!$J$62*('Engine Requirements'!$K$62/B6)^(1/'Combustion Analysis'!$B$58) -> 2.2209152 | E6: =SQRT(((2*'Combustion Analysis'!$B$58)/('Combustion Analysis'!$B$58-1))*'Combustion Analysis'!$B$69*'Engine Requirements'!$G$62*(1-('Solution of Isentropic Expansio'!B6/'Engine Requirements'!$K$62)^(('Combustion Analysis'!$B$58-1)/'Combustion Analysis'!$B$58))) -> 1809.8291 | F6: =('Engine Requirements'!$B$24*'Solution of Isentropic Expansio'!D6)/'Solution of Isentropic Expansio'!E6 -> 0.00066721884 | G6: =F6*1550 -> 1.0341892 | H6: =(2*SQRT(F6/PI())) -> 0.029146688 | I6: =H6*39.3701 -> 1.147508 | K6: =SQRT('Combustion Analysis'!$B$58*'Combustion Analysis'!$B$69*'Solution of Isentropic Expansio'!C6) -> 859.0615
A7: 300 | B7: =A7*1000 -> 300000 | C7: ='Engine Requirements'!$G$62*(B7/'Engine Requirements'!$K$62)^(('Combustion Analysis'!$B$58-1)/'Combustion Analysis'!$B$58) -> 1871.9761 | D7: ='Engine Requirements'!$J$62*('Engine Requirements'!$K$62/B7)^(1/'Combustion Analysis'!$B$58) -> 1.9362413 | E7: =SQRT(((2*'Combustion Analysis'!$B$58)/('Combustion Analysis'!$B$58-1))*'Combustion Analysis'!$B$69*'Engine Requirements'!$G$62*(1-('Solution of Isentropic Expansio'!B7/'Engine Requirements'!$K$62)^(('Combustion Analysis'!$B$58-1)/'Combustion Analysis'!$B$58))) -> 1751.6794 | F7: =('Engine Requirements'!$B$24*'Solution of Isentropic Expansio'!D7)/'Solution of Isentropic Expansio'!E7 -> 0.00060100591 | G7: =F7*1550 -> 0.93155916 | H7: =(2*SQRT(F7/PI())) -> 0.027662691 | I7: =H7*39.3701 -> 1.0890829 | K7: =SQRT('Combustion Analysis'!$B$58*'Combustion Analysis'!$B$69*'Solution of Isentropic Expansio'!C7) -> 878.67573
A8: 350 | B8: =A8*1000 -> 350000 | C8: ='Engine Requirements'!$G$62*(B8/'Engine Requirements'!$K$62)^(('Combustion Analysis'!$B$58-1)/'Combustion Analysis'!$B$58) -> 1944.8193 | D8: ='Engine Requirements'!$J$62*('Engine Requirements'!$K$62/B8)^(1/'Combustion Analysis'!$B$58) -> 1.7242159 | E8: =SQRT(((2*'Combustion Analysis'!$B$58)/('Combustion Analysis'!$B$58-1))*'Combustion Analysis'!$B$69*'Engine Requirements'!$G$62*(1-('Solution of Isentropic Expansio'!B8/'Engine Requirements'!$K$62)^(('Combustion Analysis'!$B$58-1)/'Combustion Analysis'!$B$58))) -> 1698.7745 | F8: =('Engine Requirements'!$B$24*'Solution of Isentropic Expansio'!D8)/'Solution of Isentropic Expansio'!E8 -> 0.00055186112 | G8: =F8*1550 -> 0.85538474 | H8: =(2*SQRT(F8/PI())) -> 0.026507573 | I8: =H8*39.3701 -> 1.0436058 | K8: =SQRT('Combustion Analysis'!$B$58*'Combustion Analysis'!$B$69*'Solution of Isentropic Expansio'!C8) -> 895.6083
A9: 400 | B9: =A9*1000 -> 400000 | C9: ='Engine Requirements'!$G$62*(B9/'Engine Requirements'!$K$62)^(('Combustion Analysis'!$B$58-1)/'Combustion Analysis'!$B$58) -> 2010.2062 | D9: ='Engine Requirements'!$J$62*('Engine Requirements'!$K$62/B9)^(1/'Combustion Analysis'!$B$58) -> 1.5594127 | E9: =SQRT(((2*'Combustion Analysis'!$B$58)/('Combustion Analysis'!$B$58-1))*'Combustion Analysis'!$B$69*'Engine Requirements'!$G$62*(1-('Solution of Isentropic Expansio'!B9/'Engine Requirements'!$K$62)^(('Combustion Analysis'!$B$58-1)/'Combustion Analysis'!$B$58))) -> 1649.8408 | F9: =('Engine Requirements'!$B$24*'Solution of Isentropic Expansio'!D9)/'Solution of Isentropic Expansio'!E9 -> 0.0005139169 | G9: =F9*1550 -> 0.7965712 | H9: =(2*SQRT(F9/PI())) -> 0.025580057 | I9: =H9*39.3701 -> 1.0070894 | K9: =SQRT('Combustion Analysis'!$B$58*'Combustion Analysis'!$B$69*'Solution of Isentropic Expansio'!C9) -> 910.53949
A10: 450 | B10: =A10*1000 -> 450000 | C10: ='Engine Requirements'!$G$62*(B10/'Engine Requirements'!$K$62)^(('Combustion Analysis'!$B$58-1)/'Combustion Analysis'!$B$58) -> 2069.7039 | D10: ='Engine Requirements'!$J$62*('Engine Requirements'!$K$62/B10)^(1/'Combustion Analysis'!$B$58) -> 1.4271714 | E10: =SQRT(((2*'Combustion Analysis'!$B$58)/('Combustion Analysis'!$B$58-1))*'Combustion Analysis'!$B$69*'Engine Requirements'!$G$62*(1-('Solution of Isentropic Expansio'!B10/'Engine Requirements'!$K$62)^(('Combustion Analysis'!$B$58-1)/'Combustion Analysis'!$B$58))) -> 1604.0177 | F10: =('Engine Requirements'!$B$24*'Solution of Isentropic Expansio'!D10)/'Solution of Isentropic Expansio'!E10 -> 0.00048377215 | G10: =F10*1550 -> 0.74984684 | H10: =(2*SQRT(F10/PI())) -> 0.024818498 | I10: =H10*39.3701 -> 0.97710674 | K10: =SQRT('Combustion Analysis'!$B$58*'Combustion Analysis'!$B$69*'Solution of Isentropic Expansio'!C10) -> 923.91622
A11: 500 | B11: =A11*1000 -> 500000 | C11: ='Engine Requirements'!$G$62*(B11/'Engine Requirements'!$K$62)^(('Combustion Analysis'!$B$58-1)/'Combustion Analysis'!$B$58) -> 2124.417 | D11: ='Engine Requirements'!$J$62*('Engine Requirements'!$K$62/B11)^(1/'Combustion Analysis'!$B$58) -> 1.3184092 | E11: =SQRT(((2*'Combustion Analysis'!$B$58)/('Combustion Analysis'!$B$58-1))*'Combustion Analysis'!$B$69*'Engine Requirements'!$G$62*(1-('Solution of Isentropic Expansio'!B11/'Engine Requirements'!$K$62)^(('Combustion Analysis'!$B$58-1)/'Combustion Analysis'!$B$58))) -> 1560.6925 | F11: =('Engine Requirements'!$B$24*'Solution of Isentropic Expansio'!D11)/'Solution of Isentropic Expansio'!E11 -> 0.0004593109 | G11: =F11*1550 -> 0.7119319 | H11: =(2*SQRT(F11/PI())) -> 0.024182903 | I11: =H11*39.3701 -> 0.95208331 | K11: =SQRT('Combustion Analysis'!$B$58*'Combustion Analysis'!$B$69*'Solution of Isentropic Expansio'!C11) -> 936.04854
A12: 550 | B12: =A12*1000 -> 550000 | C12: ='Engine Requirements'!$G$62*(B12/'Engine Requirements'!$K$62)^(('Combustion Analysis'!$B$58-1)/'Combustion Analysis'!$B$58) -> 2175.1561 | D12: ='Engine Requirements'!$J$62*('Engine Requirements'!$K$62/B12)^(1/'Combustion Analysis'!$B$58) -> 1.2271797 | E12: =SQRT(((2*'Combustion Analysis'!$B$58)/('Combustion Analysis'!$B$58-1))*'Combustion Analysis'!$B$69*'Engine Requirements'!$G$62*(1-('Solution of Isentropic Expansio'!B12/'Engine Requirements'!$K$62)^(('Combustion Analysis'!$B$58-1)/'Combustion Analysis'!$B$58))) -> 1519.4106 | F12: =('Engine Requirements'!$B$24*'Solution of Isentropic Expansio'!D12)/'Solution of Isentropic Expansio'!E12 -> 0.00043914395 | G12: =F12*1550 -> 0.68067312 | H12: =(2*SQRT(F12/PI())) -> 0.023646045 | I12: =H12*39.3701 -> 0.93094716 | K12: =SQRT('Combustion Analysis'!$B$58*'Combustion Analysis'!$B$69*'Solution of Isentropic Expansio'!C12) -> 947.16075
A13: 600 | B13: =A13*1000 -> 600000 | C13: ='Engine Requirements'!$G$62*(B13/'Engine Requirements'!$K$62)^(('Combustion Analysis'!$B$58-1)/'Combustion Analysis'!$B$58) -> 2222.5346 | D13: ='Engine Requirements'!$J$62*('Engine Requirements'!$K$62/B13)^(1/'Combustion Analysis'!$B$58) -> 1.1494173 | E13: =SQRT(((2*'Combustion Analysis'!$B$58)/('Combustion Analysis'!$B$58-1))*'Combustion Analysis'!$B$69*'Engine Requirements'!$G$62*(1-('Solution of Isentropic Expansio'!B13/'Engine Requirements'!$K$62)^(('Combustion Analysis'!$B$58-1)/'Combustion Analysis'!$B$58))) -> 1479.8235 | F13: =('Engine Requirements'!$B$24*'Solution of Isentropic Expansio'!D13)/'Solution of Isentropic Expansio'!E13 -> 0.00042232004 | G13: =F13*1550 -> 0.65459606 | H13: =(2*SQRT(F13/PI())) -> 0.023188673 | I13: =H13*39.3701 -> 0.91294039 | K13: =SQRT('Combustion Analysis'!$B$58*'Combustion Analysis'!$B$69*'Solution of Isentropic Expansio'!C13) -> 957.42055
A14: 650 | B14: =A14*1000 -> 650000 | C14: ='Engine Requirements'!$G$62*(B14/'Engine Requirements'!$K$62)^(('Combustion Analysis'!$B$58-1)/'Combustion Analysis'!$B$58) -> 2267.0294 | D14: ='Engine Requirements'!$J$62*('Engine Requirements'!$K$62/B14)^(1/'Combustion Analysis'!$B$58) -> 1.0822416 | E14: =SQRT(((2*'Combustion Analysis'!$B$58)/('Combustion Analysis'!$B$58-1))*'Combustion Analysis'!$B$69*'Engine Requirements'!$G$62*(1-('Solution of Isentropic Expansio'!B14/'Engine Requirements'!$K$62)^(('Combustion Analysis'!$B$58-1)/'Combustion Analysis'!$B$58))) -> 1441.6564 | F14: =('Engine Requirements'!$B$24*'Solution of Isentropic Expansio'!D14)/'Solution of Isentropic Expansio'!E14 -> 0.00040816556 | G14: =F14*1550 -> 0.63265662 | H14: =(2*SQRT(F14/PI())) -> 0.022796766 | I14: =H14*39.3701 -> 0.89751095 | K14: =SQRT('Combustion Analysis'!$B$58*'Combustion Analysis'!$B$69*'Solution of Isentropic Expansio'!C14) -> 966.95677
A15: 700 | B15: =A15*1000 -> 700000 | C15: ='Engine Requirements'!$G$62*(B15/'Engine Requirements'!$K$62)^(('Combustion Analysis'!$B$58-1)/'Combustion Analysis'!$B$58) -> 2309.0189 | D15: ='Engine Requirements'!$J$62*('Engine Requirements'!$K$62/B15)^(1/'Combustion Analysis'!$B$58) -> 1.0235519 | E15: =SQRT(((2*'Combustion Analysis'!$B$58)/('Combustion Analysis'!$B$58-1))*'Combustion Analysis'!$B$69*'Engine Requirements'!$G$62*(1-('Solution of Isentropic Expansio'!B15/'Engine Requirements'!$K$62)^(('Combustion Analysis'!$B$58-1)/'Combustion Analysis'!$B$58))) -> 1404.6875 | F15: =('Engine Requirements'!$B$24*'Solution of Isentropic Expansio'!D15)/'Solution of Isentropic Expansio'!E15 -> 0.0003961905 | G15: =F15*1550 -> 0.61409528 | H15: =(2*SQRT(F15/PI())) -> 0.022459862 | I15: =H15*39.3701 -> 0.88424703 | K15: =SQRT('Combustion Analysis'!$B$58*'Combustion Analysis'!$B$69*'Solution of Isentropic Expansio'!C15) -> 975.87058 | L15: =F26*'Engine Requirements'!D2 -> 792.57982 | M15: N
A16: 750 | B16: =A16*1000 -> 750000 | C16: ='Engine Requirements'!$G$62*(B16/'Engine Requirements'!$K$62)^(('Combustion Analysis'!$B$58-1)/'Combustion Analysis'!$B$58) -> 2348.809 | D16: ='Engine Requirements'!$J$62*('Engine Requirements'!$K$62/B16)^(1/'Combustion Analysis'!$B$58) -> 0.97177757 | E16: =SQRT(((2*'Combustion Analysis'!$B$58)/('Combustion Analysis'!$B$58-1))*'Combustion Analysis'!$B$69*'Engine Requirements'!$G$62*(1-('Solution of Isentropic Expansio'!B16/'Engine Requirements'!$K$62)^(('Combustion Analysis'!$B$58-1)/'Combustion Analysis'!$B$58))) -> 1368.7339 | F16: =('Engine Requirements'!$B$24*'Solution of Isentropic Expansio'!D16)/'Solution of Isentropic Expansio'!E16 -> 0.00038603059 | G16: =F16*1550 -> 0.59834742 | H16: =(2*SQRT(F16/PI())) -> 0.022170012 | I16: =H16*39.3701 -> 0.87283557 | K16: =SQRT('Combustion Analysis'!$B$58*'Combustion Analysis'!$B$69*'Solution of Isentropic Expansio'!C16) -> 984.24299
A17: 800 | B17: =A17*1000 -> 800000 | C17: ='Engine Requirements'!$G$62*(B17/'Engine Requirements'!$K$62)^(('Combustion Analysis'!$B$58-1)/'Combustion Analysis'!$B$58) -> 2386.6506 | D17: ='Engine Requirements'!$J$62*('Engine Requirements'!$K$62/B17)^(1/'Combustion Analysis'!$B$58) -> 0.92571923 | E17: =SQRT(((2*'Combustion Analysis'!$B$58)/('Combustion Analysis'!$B$58-1))*'Combustion Analysis'!$B$69*'Engine Requirements'!$G$62*(1-('Solution of Isentropic Expansio'!B17/'Engine Requirements'!$K$62)^(('Combustion Analysis'!$B$58-1)/'Combustion Analysis'!$B$58))) -> 1333.6421 | F17: =('Engine Requirements'!$B$24*'Solution of Isentropic Expansio'!D17)/'Solution of Isentropic Expansio'!E17 -> 0.00037741042 | G17: =F17*1550 -> 0.58498616 | H17: =(2*SQRT(F17/PI())) -> 0.021921083 | I17: =H17*39.3701 -> 0.86303523 | K17: =SQRT('Combustion Analysis'!$B$58*'Combustion Analysis'!$B$69*'Solution of Isentropic Expansio'!C17) -> 992.13987
A18: 850 | B18: =A18*1000 -> 850000 | C18: ='Engine Requirements'!$G$62*(B18/'Engine Requirements'!$K$62)^(('Combustion Analysis'!$B$58-1)/'Combustion Analysis'!$B$58) -> 2422.7524 | D18: ='Engine Requirements'!$J$62*('Engine Requirements'!$K$62/B18)^(1/'Combustion Analysis'!$B$58) -> 0.88444442 | E18: =SQRT(((2*'Combustion Analysis'!$B$58)/('Combustion Analysis'!$B$58-1))*'Combustion Analysis'!$B$69*'Engine Requirements'!$G$62*(1-('Solution of Isentropic Expansio'!B18/'Engine Requirements'!$K$62)^(('Combustion Analysis'!$B$58-1)/'Combustion Analysis'!$B$58))) -> 1299.2804 | F18: =('Engine Requirements'!$B$24*'Solution of Isentropic Expansio'!D18)/'Solution of Isentropic Expansio'!E18 -> 0.00037011915 | G18: =F18*1550 -> 0.57368468 | H18: =(2*SQRT(F18/PI())) -> 0.021708301 | I18: =H18*39.3701 -> 0.85465799 | K18: =SQRT('Combustion Analysis'!$B$58*'Combustion Analysis'!$B$69*'Solution of Isentropic Expansio'!C18) -> 999.61554
A19: 900 | B19: =A19*1000 -> 900000 | C19: ='Engine Requirements'!$G$62*(B19/'Engine Requirements'!$K$62)^(('Combustion Analysis'!$B$58-1)/'Combustion Analysis'!$B$58) -> 2457.2902 | D19: ='Engine Requirements'!$J$62*('Engine Requirements'!$K$62/B19)^(1/'Combustion Analysis'!$B$58) -> 0.84721644 | E19: =SQRT(((2*'Combustion Analysis'!$B$58)/('Combustion Analysis'!$B$58-1))*'Combustion Analysis'!$B$69*'Engine Requirements'!$G$62*(1-('Solution of Isentropic Expansio'!B19/'Engine Requirements'!$K$62)^(('Combustion Analysis'!$B$58-1)/'Combustion Analysis'!$B$58))) -> 1265.5345 | F19: =('Engine Requirements'!$B$24*'Solution of Isentropic Expansio'!D19)/'Solution of Isentropic Expansio'!E19 -> 0.00036399404 | G19: =F19*1550 -> 0.56419077 | H19: =(2*SQRT(F19/PI())) -> 0.021527926 | I19: =H19*39.3701 -> 0.84755661 | K19: =SQRT('Combustion Analysis'!$B$58*'Combustion Analysis'!$B$69*'Solution of Isentropic Expansio'!C19) -> 1006.7154
A20: 950 | B20: =A20*1000 -> 950000 | C20: ='Engine Requirements'!$G$62*(B20/'Engine Requirements'!$K$62)^(('Combustion Analysis'!$B$58-1)/'Combustion Analysis'!$B$58) -> 2490.4131 | D20: ='Engine Requirements'!$J$62*('Engine Requirements'!$K$62/B20)^(1/'Combustion Analysis'!$B$58) -> 0.81344506 | E20: =SQRT(((2*'Combustion Analysis'!$B$58)/('Combustion Analysis'!$B$58-1))*'Combustion Analysis'!$B$69*'Engine Requirements'!$G$62*(1-('Solution of Isentropic Expansio'!B20/'Engine Requirements'!$K$62)^(('Combustion Analysis'!$B$58-1)/'Combustion Analysis'!$B$58))) -> 1232.3032 | F20: =('Engine Requirements'!$B$24*'Solution of Isentropic Expansio'!D20)/'Solution of Isentropic Expansio'!E20 -> 0.00035890916 | G20: =F20*1550 -> 0.5563092 | H20: =(2*SQRT(F20/PI())) -> 0.021377028 | I20: =H20*39.3701 -> 0.84161574 | K20: =SQRT('Combustion Analysis'!$B$58*'Combustion Analysis'!$B$69*'Solution of Isentropic Expansio'!C20) -> 1013.4777
A21: 1000 | B21: =A21*1000 -> 1000000 | C21: ='Engine Requirements'!$G$62*(B21/'Engine Requirements'!$K$62)^(('Combustion Analysis'!$B$58-1)/'Combustion Analysis'!$B$58) -> 2522.2493 | D21: ='Engine Requirements'!$J$62*('Engine Requirements'!$K$62/B21)^(1/'Combustion Analysis'!$B$58) -> 0.78265154 | E21: =SQRT(((2*'Combustion Analysis'!$B$58)/('Combustion Analysis'!$B$58-1))*'Combustion Analysis'!$B$69*'Engine Requirements'!$G$62*(1-('Solution of Isentropic Expansio'!B21/'Engine Requirements'!$K$62)^(('Combustion Analysis'!$B$58-1)/'Combustion Analysis'!$B$58))) -> 1199.4954 | F21: =('Engine Requirements'!$B$24*'Solution of Isentropic Expansio'!D21)/'Solution of Isentropic Expansio'!E21 -> 0.00035476742 | G21: =F21*1550 -> 0.54988949 | H21: =(2*SQRT(F21/PI())) -> 0.021253327 | I21: =H21*39.3701 -> 0.8367456 | K21: =SQRT('Combustion Analysis'!$B$58*'Combustion Analysis'!$B$69*'Solution of Isentropic Expansio'!C21) -> 1019.935
A22: 1050 | B22: =A22*1000 -> 1050000 | C22: ='Engine Requirements'!$G$62*(B22/'Engine Requirements'!$K$62)^(('Combustion Analysis'!$B$58-1)/'Combustion Analysis'!$B$58) -> 2552.9094 | D22: ='Engine Requirements'!$J$62*('Engine Requirements'!$K$62/B22)^(1/'Combustion Analysis'!$B$58) -> 0.75444319 | E22: =SQRT(((2*'Combustion Analysis'!$B$58)/('Combustion Analysis'!$B$58-1))*'Combustion Analysis'!$B$69*'Engine Requirements'!$G$62*(1-('Solution of Isentropic Expansio'!B22/'Engine Requirements'!$K$62)^(('Combustion Analysis'!$B$58-1)/'Combustion Analysis'!$B$58))) -> 1167.0281 | F22: =('Engine Requirements'!$B$24*'Solution of Isentropic Expansio'!D22)/'Solution of Isentropic Expansio'!E22 -> 0.00035149496 | G22: =F22*1550 -> 0.54481718 | H22: =(2*SQRT(F22/PI())) -> 0.021155077 | I22: =H22*39.3701 -> 0.83287749 | K22: =SQRT('Combustion Analysis'!$B$58*'Combustion Analysis'!$B$69*'Solution of Isentropic Expansio'!C22) -> 1026.1154
A23: 1100 | B23: =A23*1000 -> 1100000 | C23: ='Engine Requirements'!$G$62*(B23/'Engine Requirements'!$K$62)^(('Combustion Analysis'!$B$58-1)/'Combustion Analysis'!$B$58) -> 2582.49 | D23: ='Engine Requirements'!$J$62*('Engine Requirements'!$K$62/B23)^(1/'Combustion Analysis'!$B$58) -> 0.72849471 | E23: =SQRT(((2*'Combustion Analysis'!$B$58)/('Combustion Analysis'!$B$58-1))*'Combustion Analysis'!$B$69*'Engine Requirements'!$G$62*(1-('Solution of Isentropic Expansio'!B23/'Engine Requirements'!$K$62)^(('Combustion Analysis'!$B$58-1)/'Combustion Analysis'!$B$58))) -> 1134.824 | F23: =('Engine Requirements'!$B$24*'Solution of Isentropic Expansio'!D23)/'Solution of Isentropic Expansio'!E23 -> 0.00034903726 | G23: =F23*1550 -> 0.54100775 | H23: =(2*SQRT(F23/PI())) -> 0.021080988 | I23: =H23*39.3701 -> 0.82996059 | K23: =SQRT('Combustion Analysis'!$B$58*'Combustion Analysis'!$B$69*'Solution of Isentropic Expansio'!C23) -> 1032.043
A24: 1150 | B24: =A24*1000 -> 1150000 | C24: ='Engine Requirements'!$G$62*(B24/'Engine Requirements'!$K$62)^(('Combustion Analysis'!$B$58-1)/'Combustion Analysis'!$B$58) -> 2611.0756 | D24: ='Engine Requirements'!$J$62*('Engine Requirements'!$K$62/B24)^(1/'Combustion Analysis'!$B$58) -> 0.70453415 | E24: =SQRT(((2*'Combustion Analysis'!$B$58)/('Combustion Analysis'!$B$58-1))*'Combustion Analysis'!$B$69*'Engine Requirements'!$G$62*(1-('Solution of Isentropic Expansio'!B24/'Engine Requirements'!$K$62)^(('Combustion Analysis'!$B$58-1)/'Combustion Analysis'!$B$58))) -> 1102.8098 | F24: =('Engine Requirements'!$B$24*'Solution of Isentropic Expansio'!D24)/'Solution of Isentropic Expansio'!E24 -> 0.0003473564 | G24: =F24*1550 -> 0.53840242 | H24: =(2*SQRT(F24/PI())) -> 0.021030167 | I24: =H24*39.3701 -> 0.82795976 | K24: =SQRT('Combustion Analysis'!$B$58*'Combustion Analysis'!$B$69*'Solution of Isentropic Expansio'!C24) -> 1037.7392
A25: 1200 | B25: =A25*1000 -> 1200000 | C25: ='Engine Requirements'!$G$62*(B25/'Engine Requirements'!$K$62)^(('Combustion Analysis'!$B$58-1)/'Combustion Analysis'!$B$58) -> 2638.7409 | D25: ='Engine Requirements'!$J$62*('Engine Requirements'!$K$62/B25)^(1/'Combustion Analysis'!$B$58) -> 0.68233232 | E25: =SQRT(((2*'Combustion Analysis'!$B$58)/('Combustion Analysis'!$B$58-1))*'Combustion Analysis'!$B$69*'Engine Requirements'!$G$62*(1-('Solution of Isentropic Expansio'!B25/'Engine Requirements'!$K$62)^(('Combustion Analysis'!$B$58-1)/'Combustion Analysis'!$B$58))) -> 1070.9155 | F25: =('Engine Requirements'!$B$24*'Solution of Isentropic Expansio'!D25)/'Solution of Isentropic Expansio'!E25 -> 0.00034642931 | G25: =F25*1550 -> 0.53696543 | H25: =(2*SQRT(F25/PI())) -> 0.021002083 | I25: =H25*39.3701 -> 0.82685411 | K25: =SQRT('Combustion Analysis'!$B$58*'Combustion Analysis'!$B$69*'Solution of Isentropic Expansio'!C25) -> 1043.2223
A26: 1250 | B26: =A26*1000 -> 1250000 | C26: ='Engine Requirements'!$G$62*(B26/'Engine Requirements'!$K$62)^(('Combustion Analysis'!$B$58-1)/'Combustion Analysis'!$B$58) -> 2665.5521 | D26: ='Engine Requirements'!$J$62*('Engine Requirements'!$K$62/B26)^(1/'Combustion Analysis'!$B$58) -> 0.66169461 | E26: =SQRT(((2*'Combustion Analysis'!$B$58)/('Combustion Analysis'!$B$58-1))*'Combustion Analysis'!$B$69*'Engine Requirements'!$G$62*(1-('Solution of Isentropic Expansio'!B26/'Engine Requirements'!$K$62)^(('Combustion Analysis'!$B$58-1)/'Combustion Analysis'!$B$58))) -> 1039.0722 | F26: =('Engine Requirements'!$B$24*'Solution of Isentropic Expansio'!D26)/'Solution of Isentropic Expansio'!E26 -> 0.0003462468 | G26: =F26*1550 -> 0.53668255 | H26: =(2*SQRT(F26/PI())) -> 0.02099655 | I26: =H26*39.3701 -> 0.82663628 | J26: THROAT | K26: =SQRT('Combustion Analysis'!$B$58*'Combustion Analysis'!$B$69*'Solution of Isentropic Expansio'!C26) -> 1048.5088
A27: 1300 | B27: =A27*1000 -> 1300000 | C27: ='Engine Requirements'!$G$62*(B27/'Engine Requirements'!$K$62)^(('Combustion Analysis'!$B$58-1)/'Combustion Analysis'!$B$58) -> 2691.5681 | D27: ='Engine Requirements'!$J$62*('Engine Requirements'!$K$62/B27)^(1/'Combustion Analysis'!$B$58) -> 0.64245463 | E27: =SQRT(((2*'Combustion Analysis'!$B$58)/('Combustion Analysis'!$B$58-1))*'Combustion Analysis'!$B$69*'Engine Requirements'!$G$62*(1-('Solution of Isentropic Expansio'!B27/'Engine Requirements'!$K$62)^(('Combustion Analysis'!$B$58-1)/'Combustion Analysis'!$B$58))) -> 1007.2113 | F27: =('Engine Requirements'!$B$24*'Solution of Isentropic Expansio'!D27)/'Solution of Isentropic Expansio'!E27 -> 0.00034681333 | G27: =F27*1550 -> 0.53756065 | H27: =(2*SQRT(F27/PI())) -> 0.02101372 | I27: =H27*39.3701 -> 0.82731227 | K27: =SQRT('Combustion Analysis'!$B$58*'Combustion Analysis'!$B$69*'Solution of Isentropic Expansio'!C27) -> 1053.6131
A28: 1350 | B28: =A28*1000 -> 1350000 | C28: ='Engine Requirements'!$G$62*(B28/'Engine Requirements'!$K$62)^(('Combustion Analysis'!$B$58-1)/'Combustion Analysis'!$B$58) -> 2716.8419 | D28: ='Engine Requirements'!$J$62*('Engine Requirements'!$K$62/B28)^(1/'Combustion Analysis'!$B$58) -> 0.62446921 | E28: =SQRT(((2*'Combustion Analysis'!$B$58)/('Combustion Analysis'!$B$58-1))*'Combustion Analysis'!$B$69*'Engine Requirements'!$G$62*(1-('Solution of Isentropic Expansio'!B28/'Engine Requirements'!$K$62)^(('Combustion Analysis'!$B$58-1)/'Combustion Analysis'!$B$58))) -> 975.26316 | F28: =('Engine Requirements'!$B$24*'Solution of Isentropic Expansio'!D28)/'Solution of Isentropic Expansio'!E28 -> 0.00034814735 | G28: =F28*1550 -> 0.53962839 | H28: =(2*SQRT(F28/PI())) -> 0.021054096 | I28: =H28*39.3701 -> 0.82890188 | K28: =SQRT('Combustion Analysis'!$B$58*'Combustion Analysis'!$B$69*'Solution of Isentropic Expansio'!C28) -> 1058.5483
A29: 1400 | B29: =A29*1000 -> 1400000 | C29: ='Engine Requirements'!$G$62*(B29/'Engine Requirements'!$K$62)^(('Combustion Analysis'!$B$58-1)/'Combustion Analysis'!$B$58) -> 2741.4209 | D29: ='Engine Requirements'!$J$62*('Engine Requirements'!$K$62/B29)^(1/'Combustion Analysis'!$B$58) -> 0.60761448 | E29: =SQRT(((2*'Combustion Analysis'!$B$58)/('Combustion Analysis'!$B$58-1))*'Combustion Analysis'!$B$69*'Engine Requirements'!$G$62*(1-('Solution of Isentropic Expansio'!B29/'Engine Requirements'!$K$62)^(('Combustion Analysis'!$B$58-1)/'Combustion Analysis'!$B$58))) -> 943.15587 | F29: =('Engine Requirements'!$B$24*'Solution of Isentropic Expansio'!D29)/'Solution of Isentropic Expansio'!E29 -> 0.00035028257 | G29: =F29*1550 -> 0.54293798 | H29: =(2*SQRT(F29/PI())) -> 0.021118561 | I29: =H29*39.3701 -> 0.83143986 | K29: =SQRT('Combustion Analysis'!$B$58*'Combustion Analysis'!$B$69*'Solution of Isentropic Expansio'!C29) -> 1063.3258
A30: 1450 | B30: =A30*1000 -> 1450000 | C30: ='Engine Requirements'!$G$62*(B30/'Engine Requirements'!$K$62)^(('Combustion Analysis'!$B$58-1)/'Combustion Analysis'!$B$58) -> 2765.348 | D30: ='Engine Requirements'!$J$62*('Engine Requirements'!$K$62/B30)^(1/'Combustion Analysis'!$B$58) -> 0.59178266 | E30: =SQRT(((2*'Combustion Analysis'!$B$58)/('Combustion Analysis'!$B$58-1))*'Combustion Analysis'!$B$69*'Engine Requirements'!$G$62*(1-('Solution of Isentropic Expansio'!B30/'Engine Requirements'!$K$62)^(('Combustion Analysis'!$B$58-1)/'Combustion Analysis'!$B$58))) -> 910.81352 | F30: =('Engine Requirements'!$B$24*'Solution of Isentropic Expansio'!D30)/'Solution of Isentropic Expansio'!E30 -> 0.00035326991 | G30: =F30*1550 -> 0.54756837 | H30: =(2*SQRT(F30/PI())) -> 0.021208423 | I30: =H30*39.3701 -> 0.83497775 | K30: =SQRT('Combustion Analysis'!$B$58*'Combustion Analysis'!$B$69*'Solution of Isentropic Expansio'!C30) -> 1067.9561
A31: 1500 | B31: =A31*1000 -> 1500000 | C31: ='Engine Requirements'!$G$62*(B31/'Engine Requirements'!$K$62)^(('Combustion Analysis'!$B$58-1)/'Combustion Analysis'!$B$58) -> 2788.6623 | D31: ='Engine Requirements'!$J$62*('Engine Requirements'!$K$62/B31)^(1/'Combustion Analysis'!$B$58) -> 0.57687949 | E31: =SQRT(((2*'Combustion Analysis'!$B$58)/('Combustion Analysis'!$B$58-1))*'Combustion Analysis'!$B$69*'Engine Requirements'!$G$62*(1-('Solution of Isentropic Expansio'!B31/'Engine Requirements'!$K$62)^(('Combustion Analysis'!$B$58-1)/'Combustion Analysis'!$B$58))) -> 878.15462 | F31: =('Engine Requirements'!$B$24*'Solution of Isentropic Expansio'!D31)/'Solution of Isentropic Expansio'!E31 -> 0.00035718071 | G31: =F31*1550 -> 0.5536301 | H31: =(2*SQRT(F31/PI())) -> 0.021325492 | I31: =H31*39.3701 -> 0.83958675 | K31: =SQRT('Combustion Analysis'!$B$58*'Combustion Analysis'!$B$69*'Solution of Isentropic Expansio'!C31) -> 1072.4485
A32: 1550 | B32: =A32*1000 -> 1550000 | C32: ='Engine Requirements'!$G$62*(B32/'Engine Requirements'!$K$62)^(('Combustion Analysis'!$B$58-1)/'Combustion Analysis'!$B$58) -> 2811.399 | D32: ='Engine Requirements'!$J$62*('Engine Requirements'!$K$62/B32)^(1/'Combustion Analysis'!$B$58) -> 0.5628222 | E32: =SQRT(((2*'Combustion Analysis'!$B$58)/('Combustion Analysis'!$B$58-1))*'Combustion Analysis'!$B$69*'Engine Requirements'!$G$62*(1-('Solution of Isentropic Expansio'!B32/'Engine Requirements'!$K$62)^(('Combustion Analysis'!$B$58-1)/'Combustion Analysis'!$B$58))) -> 845.09004 | F32: =('Engine Requirements'!$B$24*'Solution of Isentropic Expansio'!D32)/'Solution of Isentropic Expansio'!E32 -> 0.00036211134 | G32: =F32*1550 -> 0.56127257 | H32: =(2*SQRT(F32/PI())) -> 0.021472179 | I32: =H32*39.3701 -> 0.84536184 | K32: =SQRT('Combustion Analysis'!$B$58*'Combustion Analysis'!$B$69*'Solution of Isentropic Expansio'!C32) -> 1076.8116
A33: 1600 | B33: =A33*1000 -> 1600000 | C33: ='Engine Requirements'!$G$62*(B33/'Engine Requirements'!$K$62)^(('Combustion Analysis'!$B$58-1)/'Combustion Analysis'!$B$58) -> 2833.5903 | D33: ='Engine Requirements'!$J$62*('Engine Requirements'!$K$62/B33)^(1/'Combustion Analysis'!$B$58) -> 0.54953774 | E33: =SQRT(((2*'Combustion Analysis'!$B$58)/('Combustion Analysis'!$B$58-1))*'Combustion Analysis'!$B$69*'Engine Requirements'!$G$62*(1-('Solution of Isentropic Expansio'!B33/'Engine Requirements'!$K$62)^(('Combustion Analysis'!$B$58-1)/'Combustion Analysis'!$B$58))) -> 811.52039 | F33: =('Engine Requirements'!$B$24*'Solution of Isentropic Expansio'!D33)/'Solution of Isentropic Expansio'!E33 -> 0.00036818998 | G33: =F33*1550 -> 0.57069448 | H33: =(2*SQRT(F33/PI())) -> 0.021651652 | I33: =H33*39.3701 -> 0.85242772 | K33: =SQRT('Combustion Analysis'!$B$58*'Combustion Analysis'!$B$69*'Solution of Isentropic Expansio'!C33) -> 1081.0531
A34: 1650 | B34: =A34*1000 -> 1650000 | C34: ='Engine Requirements'!$G$62*(B34/'Engine Requirements'!$K$62)^(('Combustion Analysis'!$B$58-1)/'Combustion Analysis'!$B$58) -> 2855.266 | D34: ='Engine Requirements'!$J$62*('Engine Requirements'!$K$62/B34)^(1/'Combustion Analysis'!$B$58) -> 0.53696139 | E34: =SQRT(((2*'Combustion Analysis'!$B$58)/('Combustion Analysis'!$B$58-1))*'Combustion Analysis'!$B$69*'Engine Requirements'!$G$62*(1-('Solution of Isentropic Expansio'!B34/'Engine Requirements'!$K$62)^(('Combustion Analysis'!$B$58-1)/'Combustion Analysis'!$B$58))) -> 777.33264 | F34: =('Engine Requirements'!$B$24*'Solution of Isentropic Expansio'!D34)/'Solution of Isentropic Expansio'!E34 -> 0.00037558656 | G34: =F34*1550 -> 0.58215917 | H34: =(2*SQRT(F34/PI())) -> 0.021868051 | I34: =H34*39.3701 -> 0.86094736 | K34: =SQRT('Combustion Analysis'!$B$58*'Combustion Analysis'!$B$69*'Solution of Isentropic Expansio'!C34) -> 1085.18
A35: 1700 | B35: =A35*1000 -> 1700000 | C35: ='Engine Requirements'!$G$62*(B35/'Engine Requirements'!$K$62)^(('Combustion Analysis'!$B$58-1)/'Combustion Analysis'!$B$58) -> 2876.4529 | D35: ='Engine Requirements'!$J$62*('Engine Requirements'!$K$62/B35)^(1/'Combustion Analysis'!$B$58) -> 0.52503564 | E35: =SQRT(((2*'Combustion Analysis'!$B$58)/('Combustion Analysis'!$B$58-1))*'Combustion Analysis'!$B$69*'Engine Requirements'!$G$62*(1-('Solution of Isentropic Expansio'!B35/'Engine Requirements'!$K$62)^(('Combustion Analysis'!$B$58-1)/'Combustion Analysis'!$B$58))) -> 742.3957 | F35: =('Engine Requirements'!$B$24*'Solution of Isentropic Expansio'!D35)/'Solution of Isentropic Expansio'!E35 -> 0.00038452733 | G35: =F35*1550 -> 0.59601737 | H35: =(2*SQRT(F35/PI())) -> 0.022126803 | I35: =H35*39.3701 -> 0.87113444 | K35: =SQRT('Combustion Analysis'!$B$58*'Combustion Analysis'!$B$69*'Solution of Isentropic Expansio'!C35) -> 1089.1987
A36: 1750 | B36: =A36*1000 -> 1750000 | C36: ='Engine Requirements'!$G$62*(B36/'Engine Requirements'!$K$62)^(('Combustion Analysis'!$B$58-1)/'Combustion Analysis'!$B$58) -> 2897.176 | D36: ='Engine Requirements'!$J$62*('Engine Requirements'!$K$62/B36)^(1/'Combustion Analysis'!$B$58) -> 0.51370912 | E36: =SQRT(((2*'Combustion Analysis'!$B$58)/('Combustion Analysis'!$B$58-1))*'Combustion Analysis'!$B$69*'Engine Requirements'!$G$62*(1-('Solution of Isentropic Expansio'!B36/'Engine Requirements'!$K$62)^(('Combustion Analysis'!$B$58-1)/'Combustion Analysis'!$B$58))) -> 706.55427 | F36: =('Engine Requirements'!$B$24*'Solution of Isentropic Expansio'!D36)/'Solution of Isentropic Expansio'!E36 -> 0.00039531713 | G36: =F36*1550 -> 0.61274155 | H36: =(2*SQRT(F36/PI())) -> 0.022435093 | I36: =H36*39.3701 -> 0.88327186 | K36: =SQRT('Combustion Analysis'!$B$58*'Combustion Analysis'!$B$69*'Solution of Isentropic Expansio'!C36) -> 1093.1152
A37: 1800 | B37: =A37*1000 -> 1800000 | C37: ='Engine Requirements'!$G$62*(B37/'Engine Requirements'!$K$62)^(('Combustion Analysis'!$B$58-1)/'Combustion Analysis'!$B$58) -> 2917.4584 | D37: ='Engine Requirements'!$J$62*('Engine Requirements'!$K$62/B37)^(1/'Combustion Analysis'!$B$58) -> 0.50293586 | E37: =SQRT(((2*'Combustion Analysis'!$B$58)/('Combustion Analysis'!$B$58-1))*'Combustion Analysis'!$B$69*'Engine Requirements'!$G$62*(1-('Solution of Isentropic Expansio'!B37/'Engine Requirements'!$K$62)^(('Combustion Analysis'!$B$58-1)/'Combustion Analysis'!$B$58))) -> 669.62013 | F37: =('Engine Requirements'!$B$24*'Solution of Isentropic Expansio'!D37)/'Solution of Isentropic Expansio'!E37 -> 0.00040837391 | G37: =F37*1550 -> 0.63297956 | H37: =(2*SQRT(F37/PI())) -> 0.022802583 | I37: =H37*39.3701 -> 0.89773999 | K37: =SQRT('Combustion Analysis'!$B$58*'Combustion Analysis'!$B$69*'Solution of Isentropic Expansio'!C37) -> 1096.9348
A38: 1850 | B38: =A38*1000 -> 1850000 | C38: ='Engine Requirements'!$G$62*(B38/'Engine Requirements'!$K$62)^(('Combustion Analysis'!$B$58-1)/'Combustion Analysis'!$B$58) -> 2937.3212 | D38: ='Engine Requirements'!$J$62*('Engine Requirements'!$K$62/B38)^(1/'Combustion Analysis'!$B$58) -> 0.49267458 | E38: =SQRT(((2*'Combustion Analysis'!$B$58)/('Combustion Analysis'!$B$58-1))*'Combustion Analysis'!$B$69*'Engine Requirements'!$G$62*(1-('Solution of Isentropic Expansio'!B38/'Engine Requirements'!$K$62)^(('Combustion Analysis'!$B$58-1)/'Combustion Analysis'!$B$58))) -> 631.35941 | F38: =('Engine Requirements'!$B$24*'Solution of Isentropic Expansio'!D38)/'Solution of Isentropic Expansio'!E38 -> 0.00042428471 | G38: =F38*1550 -> 0.6576413 | H38: =(2*SQRT(F38/PI())) -> 0.023242549 | I38: =H38*39.3701 -> 0.91506147 | K38: =SQRT('Combustion Analysis'!$B$58*'Combustion Analysis'!$B$69*'Solution of Isentropic Expansio'!C38) -> 1100.6626
... A46: 2250 | B46: =A46*1000 -> 2250000 | C46: ='Engine Requirements'!$G$62*(B46/'Engine Requirements'!$K$62)^(('Combustion Analysis'!$B$58-1)/'Combustion Analysis'!$B$58) -> 3083.2152 | D46: ='Engine Requirements'!$J$62*('Engine Requirements'!$K$62/B46)^(1/'Combustion Analysis'!$B$58) -> 0.42520833 | E46: =SQRT(((2*'Combustion Analysis'!$B$58)/('Combustion Analysis'!$B$58-1))*'Combustion Analysis'!$B$69*'Engine Requirements'!$G$62*(1-('Solution of Isentropic Expansio'!B46/'Engine Requirements'!$K$62)^(('Combustion Analysis'!$B$58-1)/'Combustion Analysis'!$B$58))) -> 181.66671 | F46: =('Engine Requirements'!$B$24*'Solution of Isentropic Expansio'!D46)/'Solution of Isentropic Expansio'!E46 -> 0.0012726246 | G46: =F46*1550 -> 1.9725681 | H46: =(2*SQRT(F46/PI())) -> 0.040253645 | I46: =H46*39.3701 -> 1.58479 | K46: =SQRT('Combustion Analysis'!$B$58*'Combustion Analysis'!$B$69*'Solution of Isentropic Expansio'!C46) -> 1127.6658
A47: 2300 | B47: =A47*1000 -> 2300000 | C47: ='Engine Requirements'!$G$62*(B47/'Engine Requirements'!$K$62)^(('Combustion Analysis'!$B$58-1)/'Combustion Analysis'!$B$58) -> 3100.0427 | D47: ='Engine Requirements'!$J$62*('Engine Requirements'!$K$62/B47)^(1/'Combustion Analysis'!$B$58) -> 0.41823491 | E47: =SQRT(((2*'Combustion Analysis'!$B$58)/('Combustion Analysis'!$B$58-1))*'Combustion Analysis'!$B$69*'Engine Requirements'!$G$62*(1-('Solution of Isentropic Expansio'!B47/'Engine Requirements'!$K$62)^(('Combustion Analysis'!$B$58-1)/'Combustion Analysis'!$B$58))) -> #NUM! | F47: =('Engine Requirements'!$B$24*'Solution of Isentropic Expansio'!D47)/'Solution of Isentropic Expansio'!E47 -> #NUM! | G47: =F47*1550 -> #NUM! | H47: =(2*SQRT(F47/PI())) -> #NUM! | I47: =H47*39.3701 -> #NUM!
...

Sheet Sheet1
A1: Cylindrical radius | B1: 41.94 | C1: mm
A2: Cylindrical length | B2: 30 | C2: mm
A3: average conical radius | B3: =AVERAGE(B1,B6) -> 26.2125 | C3: in
A4: Conical Length | B4: 88.04 | C4: mm
A5: Rough Design-Chamb Vol: | B5: =(PI()*(B1^2)*B2)+(PI()*(B3^2)*B4) -> 355819.19 | C5: mm^3 | D5: =B5/1000000000 -> 0.00035581919 | E5: m^3
A6: Throat radius: | B6: 10.485 | C6: mm
A7: Throat Area: | B7: =(PI())*(B6^2) -> 345.3717 | C7: mm^2
A8: L*: | B8: =B5/(B7) -> 1030.25 | C8: mm | D8: =B8/1000 -> 1.03025 | E8: m
A12: Steel 304
A13: "Typical" Yield Strenth: | B13: =D13*6.8948 -> 179.2648 | C13: MPa | D13: 26 | E13: ksi | F13: Source: | G13: MMPDS
A14: Ultimate Tensile Strength | B14: =D14*6.8948 -> 503.3204 | C14: Mpa | D14: 73 | E14: ksi | F14: Source: | G14: MMPDS | K14: Service Pressure: | L14: ='Engine Requirements'!D2 -> 2289060.3 | M14: Pa
A15: Chamber inner diameter: | B15: 0.08388 | C15: m | K15: Proof Pressure: | L15: =L14*1.5 -> 3433590.5 | M15: Pa
A16: Wall thickness: | B16: =D16*0.0254 -> 0.00635 | C16: m | D16: 0.25 | E16: in | K16: Burst Pressure: | L16: =L14*2.5 -> 5722650.8 | M16: Pa
A17: Service Pressure Hoop Stress: | B17: =(B15*L14)/(2*B16) -> 15118613 | C17: Pa | D17: =B17/1000000 -> 15.118613 | E17: Mpa
A18: Service Pressure Factor of Safety: | B18: =B13/D17 -> 11.857226 | C18: dim.
A19: Service Pressure Margin of Safety: | B19: =B18-1 -> 10.857226 | C19: dim.
A20: Proof Pressure Hoop Stress: | B20: =(B15*L15)/(2*B16) -> 22677919 | C20: Pa | D20: =B20/1000000 -> 22.677919 | E20: Mpa
A21: Proof Pressure Factor of Safety: | B21: =B13/D20 -> 7.9048171 | C21: dim.
A22: Proof Pressure Margin of Safety: | B22: =B21-1 -> 6.9048171 | C22: dim.
A23: Burst Pressure Hoop Stress: | B23: =(B15*L16)/(2*B16) -> 37796531 | C23: Pa | D23: =B23/1000000 -> 37.796531 | E23: Mpa
A24: Burst Pressure Factor of Safety: | B24: =B14/D23 -> 13.316576 | C24: dim.
A25: Burst Pressure Margin of Safety: | B25: =B24-1 -> 12.316576 | C25: dim.

Sheet Prices
A1: Part/Service | B1: Part Number | C1: Supplier | D1: Number | E1: Price | F1: Total cost: | G1: Weight lbs | H1: Max Pressure (PSI) | I1: Material | J1: Use Description
A3: Test Stand:
A4: Structure:
A5: Quickcrete | D5: 0 | E5: 5.25 | F5: =D5*E5 -> 0
A6: L-Shaped Rail 1.5x1.5 | B6: 4664T18 | C6: Mcmaster | D6: 2 | E6: 9.81 | F6: =E6*D6 -> 19.62 | I6: Zinc-plated Steel | J6: 4 foot long-members
A7: L-Shaped Rail 1.5x1.5 | B7: 4664T18 | C7: Mcmaster | D7: 7 | E7: 2.76 | F7: =E7*D7 -> 19.32 | I7: Zinc-plated Steel | J7: 1 foot cross-members
A8: 3/8 diameter 5/8" bolt | B8: McMaster 91309A621 | C8: TBD
A9: 3/8" nuts
F10: =D10*E10 -> 0
A11: Feed System | F11: =D11*E11 -> 0
A12: N2 Pressure Regulator CGA-580 0-500 psi | B12: 5KZ42 | C12: Grainger | D12: 1 | E12: 222.46 | F12: =E12*D12 -> 222.46 | H12: 500 | I12: Brass, Neoprene | J12: Regulator | K12: Cv = .17
A13: 22 Cu ft. Aluminum Cylinder | C13: beverage elements | D13: 1 | E13: 84.95 | F13: =D13*E13 -> 84.95 | G13: 10 | H13: 2216
A14: 20 cu ft Steel Cylinder | C14: beverage elements | D14: 1 | E14: 69.9 | F14: =D14*E14 -> 69.9 | G14: 16 | H14: 2015
A15: 23 cu ft Steel Cylinder - Recertified | C15: beverage elements | D15: 1 | E15: 34.9 | F15: =D15*E15 -> 34.9 | G15: 12 | H15: 2015
A16: Versa-Mount Precision Compressed Air Regulators | B16: 1810T2 | C16: Mcmaster-Carr | D16: 1 | E16: 202.86 | F16: =D16*E16 -> 202.86 | H16: 500 | J16: Feed Pressure. Might need to check that this would work…
A17: 45 deg Flared SAE Male Outlet Pressure Regulator | B17: 66325A23 | C17: Mcmaster-Carr | D17: 1 | E17: 213.11 | F17: =D17*E17 -> 213.11 | H17: 500
A18: Stainless Steel BP Regulator 1/4" NPTF 500 PSI | C18: Swagelok | D18: 1 | E18: 398 | F18: =D18*E18 -> 398
A19: Panel-Mount High-Pressure-Regulating Valve | B19: 3811T11 | C19: Mcmaster-Carr | D19: 1 | E19: 322.86 | F19: =D19*E19 -> 322.86 | H19: 500
A20: Stainless Steel Pipe Schedule 40 | B20: 1XAR5 | C20: Grainger | D20: 1 | E20: 4.79 | F20: =D20*E20 -> 4.79 | I20: 304 Stainless | J20: Connects Regulator to Cross
A21: HP20 Tank | B21: 7822A11 | C21: Mcmaster-Carr | D21: 1 | E21: 131.35 | F21: =D21*E21 -> 131.35 | G21: 9.6 | H21: 2015 | I21: Steel | J21: N2 Tank option
A23: Cryogenic System
A24: Parker Lift check Valve | E24: 178 | F24: =D24*E24 -> 0 | I24: Bronze | J24: Less-good flow characteristics
A25: Parker Swing CheckValve | E25: 570 | F25: =D25*E25 -> 0 | J25: Better flow characteristics
A26: Flo-tite Cryogenic Valve | B26: NPT | C26: Flo-Tite | D26: 3
