Workbook

Sheet AR5 Gear Ratios
A1: Gear | B1: Gear Ratios | D1: Total | E1: top speed MPH
A2: 1 | B2: 3.75 | D2: =B2*$B$9 -> 13.3125 | E2: =(60*$B$11/D2)*(($B$12*3.14)/63360) -> 35.179257
A3: 2 | B3: 2.26 | D3: =B3*$B$9 -> 8.023 | E3: =(60*$B$11/D3)*(($B$12*3.14)/63360) -> 58.372662
A4: 3 | B4: 1.37 | D4: =B4*$B$9 -> 4.8635 | E4: =(60*$B$11/D4)*(($B$12*3.14)/63360) -> 96.293588
A5: 4 | B5: 1 | D5: =B5*$B$9 -> 3.55 | E5: =(60*$B$11/D5)*(($B$12*3.14)/63360) -> 131.92222
A6: 5 | B6: 0.73 | D6: =B6*$B$9 -> 2.5915 | E6: =(60*$B$11/D6)*(($B$12*3.14)/63360) -> 180.71536
A8: Reverse | B8: 2.9 | D8: =B8*$B$9 -> 10.295
A9: Final Drive | B9: 3.55
A11: Redline | B11: 6300 | C11: Rpm
A12: Tire Effective Diam | B12: 25 | C12: in | E12: original est: 26.14
B20: "something in the 3.08 to 3.55 range is probably ideal for most 25-27 inch tire cars."

Sheet W&B
C1: lbs | D1: Qty | E1: Total Weight: | F1: Veh STA | G1: CG Moment (in-lbs) | H1: Unit Cost | I1: est cost | J1: notes
A2: Powertrain | I2: =H2*D2 -> 0
B3: Engine | C3: 450 | D3: 1 | E3: =C3*D3 -> 450 | F3: 80.6 | G3: =E3*F3 -> 36270 | H3: 500 | I3: =H3*D3 -> 500
B4: Turbo, Piping | C4: 20 | D4: 1 | E4: =C4*D4 -> 20 | F4: 80.6 | G4: =E4*F4 -> 1612 | I4: =H4*D4 -> 0
B5: Radiator | C5: 14 | D5: 1 | E5: =C5*D5 -> 14 | F5: 33 | G5: =E5*F5 -> 462 | H5: 90 | I5: =H5*D5 -> 90
B6: Intercooler | C6: 0 | E6: =C6*D6 -> 0 | G6: =E6*F6 -> 0 | I6: =H6*D6 -> 0
B7: PCM/ECU | C7: 0 | E7: =C7*D7 -> 0 | G7: =E7*F7 -> 0 | I7: =H7*D7 -> 0 | J7: Assumes included with Engine
B8: exhaust system? | I8: =H8*D8 -> 0 | J8: Not Necessary for Phase I, but will be for regular use. Est ~ 200. ~100 for muffler, 100 for tubing and unforseen complications
E9: =C9*D9 -> 0 | G9: =E9*F9 -> 0 | I9: =H9*D9 -> 0
A10: Driveline | E10: =C10*D10 -> 0 | G10: =E10*F10 -> 0
B11: Trans | C11: 107 | D11: 1 | E11: =C11*D11 -> 107 | F11: 92 | G11: =E11*F11 -> 9844 | H11: 250 | I11: =H11*D11 -> 250
B12: Driveshaft | E12: =C12*D12 -> 0 | F12: 124.25 | G12: =E12*F12 -> 0 | H12: 500 | I12: =H12*D12 -> 0 | J12: Assumes Custom/Mod
B13: Differential and housing | C13: 100 | D13: 1 | E13: =C13*D13 -> 100 | F13: 145 | G13: =E13*F13 -> 14500 | H13: 500 | I13: =H13*D13 -> 500
B14: Drive axles | C14: 40 | D14: 2 | E14: =C14*D14 -> 80 | F14: 146.75 | G14: =E14*F14 -> 11740 | H14: 100 | I14: =H14*D14 -> 200
E15: =C15*D15 -> 0 | G15: =E15*F15 -> 0 | I15: =H15*D15 -> 0
A16: Chassis | E16: =C16*D16 -> 0 | G16: =E16*F16 -> 0
B17: Monocoque | C17: 200 | D17: 1 | E17: =C17*D17 -> 200 | F17: 105.5 | G17: =E17*F17 -> 21100 | H17: 800 | I17: 1000 | J17: Wild guess. Need to refine
B18: Windshield | C18: 40 | D18: 1 | E18: =C18*D18 -> 40 | F18: 97 | G18: =E18*F18 -> 3880 | H18: 0 | I18: =H18*D18 -> 0 | J18: Not necessary for Phase I
B19: Rear window(s) | E19: =C19*D19 -> 0 | G19: =E19*F19 -> 0 | H19: 0 | I19: =H19*D19 -> 0 | J19: Not necessary for Phase I
B20: Fwd Subframe | C20: 100 | D20: 1 | E20: =C20*D20 -> 100 | F20: 53 | G20: =E20*F20 -> 5300 | H20: 650 | I20: =H20*D20 -> 650 | J20: Assumes .065" wall Chromoly. Needs Updated
B21: Rear Subframe | C21: 50 | D21: 1 | E21: =C21*D21 -> 50 | F21: 141 | G21: =E21*F21 -> 7050 | H21: 300 | I21: =H21*D21 -> 300 | J21: Assumes .065" wall Chromoly
B22: Front Bumper | C22: 5 | D22: 1 | E22: =C22*D22 -> 5 | F22: 23 | G22: =E22*F22 -> 115 | H22: 100 | I22: =H22*D22 -> 100
B23: Rear Bumper | C23: 5 | D23: 1 | E23: =C23*D23 -> 5 | F23: 163 | G23: =E23*F23 -> 815 | H23: 100 | I23: =H23*D23 -> 100
B24: Left Door | C24: 8 | D24: 1 | E24: =C24*D24 -> 8 | F24: 105 | G24: =E24*F24 -> 840 | I24: =H24*D24 -> 0 | J24: Not necessary for Phase I
B25: Right Door | C25: 8 | D25: 1 | E25: =C25*D25 -> 8 | F25: 105 | G25: =E25*F25 -> 840 | I25: =H25*D25 -> 0 | J25: Not necessary for Phase I
G26: =E26*F26 -> 0 | I26: =H26*D26 -> 0
A27: Suspension | G27: =E27*F27 -> 0
B28: Upper Control Arms (fwd) | C28: 20 | D28: 2 | E28: =C28*D28 -> 40 | F28: 43.75 | G28: =E28*F28 -> 1750 | H28: 70 | I28: =H28*D28 -> 140
B29: Upper Control Arms (rear) | C29: 20 | D29: 2 | E29: =C29*D29 -> 40 | F29: 146.75 | G29: =E29*F29 -> 5870 | H29: 70 | I29: =H29*D29 -> 140
B30: Lower Control Arms (fwd) | C30: 20 | D30: 2 | E30: =C30*D30 -> 40 | F30: 43.75 | G30: =E30*F30 -> 1750 | H30: 75 | I30: =H30*D30 -> 150
B31: Lower Control Arms (rear) | C31: 20 | D31: 2 | E31: =C31*D31 -> 40 | F31: 146.75 | G31: =E31*F31 -> 5870 | H31: 75 | I31: =H31*D31 -> 150
B32: Uprights (fwd) | C32: 20 | D32: 2 | E32: =C32*D32 -> 40 | F32: 43.75 | G32: =E32*F32 -> 1750 | H32: 100 | I32: =H32*D32 -> 200
B33: Fwd Brake calipers, Rotors | C33: 15 | D33: 2 | E33: =C33*D33 -> 30 | F33: 43.75 | G33: =E33*F33 -> 1312.5 | H33: 500 | I33: =H33*D33 -> 1000 | J33: Wild guess. Need to refine
B34: Fwd Bearing Arms | D34: 2 | E34: =C34*D34 -> 0 | F34: 43.75 | G34: =E34*F34 -> 0 | I34: =H34*D34 -> 0
B35: Uprights (rear) | C35: 15 | D35: 2 | E35: =C35*D35 -> 30 | F35: 146.75 | G35: =E35*F35 -> 4402.5 | H35: 100 | I35: =H35*D35 -> 200
B36: Rear Brake Calipers, Rotors | D36: 2 | E36: =C36*D36 -> 0 | F36: 146.75 | G36: =E36*F36 -> 0 | H36: 400 | I36: =H36*D36 -> 800
B37: Rear Bearing Arms | D37: 2 | E37: =C37*D37 -> 0 | F37: 146.75 | G37: =E37*F37 -> 0 | I37: =H37*D37 -> 0
B38: Rack and pinion | C38: 20 | D38: 1 | E38: =C38*D38 -> 20 | F38: 35 | G38: =E38*F38 -> 700 | H38: 200 | I38: =H38*D38 -> 200
B39: Steering turnbuckles | C39: 10 | E39: =C39*D39 -> 0 | F39: 35 | G39: =E39*F39 -> 0 | I39: =H39*D39 -> 0 | J39: Hopefully can be included with the rack and pinion
B40: Power steering | D40: 1 | E40: =C40*D40 -> 0 | G40: =E40*F40 -> 0 | H40: 180 | I40: =H40*D40 -> 180 | J40: Looked up "Prius power steering column"
...

Sheet Components
A1: Monocoque | E1: Size
B2: 3K Carbon Fabric | C2: 50 | D2: per yard
B3: 1" 4130 1" .065" Wall | C3: 16.8 | D3: per foot? (one at a time)
A5: Tires
B6: Michelin Pilot Super Sport 275/35ZR19 | C6: 402 | D6: per tire
B7: Continental Extreme Contact Sport (summer) 275/35ZR19 | C7: 341 | D7: per tire
B8: Continental Extreme Contact Sport (summer) 235/35zR19 | C8: 271 | D8: per tire
B9: Continental Extreme Contact Sport (summer) 235/40ZR19 | C9: 297 | D9: per tire
B10: Continental Extreme Contact DWS06 (All Season) 275/35ZR19 | C10: 273 | D10: per tire
A11: Wheels:
B12: Enkei PX-10 Gloss Black (offset +45) | C12: 262.5 | D12: per wheel | E12: 19x8 | F12: https://www.fitmentindustries.com/buy-wheel-offset/536-980-6545BK/enkei-px-10-19x8-45?vehicle_type=Car&year=2019&make=Ford&model=Mustang&trim=GT&suspension=Stock
B13: 9SiX9 Six-1 19 x 10 + 35mm | C13: 213.96 | D13: per wheel | E13: 19x10 | F13: https://www.fitmentindustries.com/buy-wheel-offset/9001-1910-35-514-DGR/9six9-six-1-19x10-35?vehicle_type=Car&year=2019&make=Ford&model=Mustang&trim=GT&suspension=Stock
B14: F1R F103 19x10 +35 F10319105114GB38 | C14: 285 | D14: per wheel | E14: 19x10 | F14: https://www.fitmentindustries.com/buy-wheel-offset/F10319105114GB38/f1r-f103-19x10-35?vehicle_type=Car&year=2019&make=Ford&model=Mustang&trim=GT&suspension=Stock
B16: AR5 Trans | C16: 1000 | D16: used
B17: Atlas Engine: | C17: 650
B18: Mustang CV Joints
B19: Mustang Differential and housing
B20: Custom Driveshaft | C20: 750
B22: Brake Calipers | C22: 1000
B23: Wilwood Pedal Set | C23: 390
L35: 12000 | M35: sq in
L36: =L35/144 -> 83.333333 | M36: sq ft
L37: 4 | M37: plies
L38: =L36*L37 -> 333.33333 | M38: Sq ft of carbon Fiber
L39: =L38*7.5 -> 2500 | M39: Dollars

Sheet Drivetrain
A2: CV Joint: | B2: info from: | D2: https://partshawk.com/ford-mustang-rear-right-cv-axle-shaft-trakmotive-fd-8281.html

Sheet Acceleration Inputs
B2: CrankShaft Power | C2: 275 | D2: hp | E2: 6000 | F2: RPM
B3: CrankShaft Torque | C3: 277 | D3: ft-lbs | E3: 3600 | F3: RPM
B4: Axle Power Fraction: | C4: 0.8 | D4: dim
B5: Axle Power | C5: =C2*C4 -> 220 | D5: hp
B6: Axle Power | C6: =C5*745.7 -> 164054 | D6: kW
B7: Est Vehicle Mass | C7: 2000 | D7: lbs | G7: 2809-2952
B8: Mass | C8: =C7/2.2046 -> 907.19405 | D8: kg
B9: Power-to-weight: | C9: =C2/C7 -> 0.1375 | D9: hp/lb
B10: Weight/lb | C10: =C7/C2 -> 7.2727273 | D10: lb/hp
B12: Theoretical Max Acceleration:
B13: A: | C13: =SQRT((C6*2)/$C$8) -> 19.017714 | D13: m/s^2
B14: A: | C14: =C13*2.236 -> 42.523609 | D14: mph/s
B16: theoretical Time to 60: | C16: =60/C14 -> 1.4109809 | D16: s
B20: Transmission info:

Sheet Torque Curve Estimation
T1: Value | U1: RPM
B2: RPM | C2: Rev/s | D2: rad/s | E2: Power (HP) | F2: Power (ft-lbs/s) | G2: Power (kW) | H2: Torque ft-lbs | I2: Theoretical Accel (m/s^2) | J2: Theoret. Accel (mph/s) | K2: Average Accel mph/s | L2: 1st Gear | M2: 2nd | N2: 3rd | O2: 4th | P2: 5th | S2: Reference Power | T2: ='Acceleration Inputs'!C2 -> 275 | U2: ='Acceleration Inputs'!E2 -> 6000
B3: 0 | C3: =B3/60 -> 0 | D3: =C3*2*3.14 -> 0 | E3: 0 | F3: 0 | G3: =E3*745.7 -> 0 | S3: Reference Torque | T3: ='Acceleration Inputs'!C3 -> 277 | U3: ='Acceleration Inputs'!E3 -> 3600
A4: 1 | B4: 100 | C4: =B4/60 -> 1.6666667 | D4: =C4*2*3.14 -> 10.466667 | E4: =(B4/$B$63)*$T$2 -> 4.5833333 | F4: =E4*550 -> 2520.8333 | G4: =E4*745.7 -> 3417.7917 | H4: =F4/D4 -> 240.84395 | I4: =SQRT((G4*2)/'Acceleration Inputs'!$C$8) -> 2.7449706 | J4: =I4*2.236 -> 6.1377542 | K4: =AVERAGE($J$4:J4) -> 6.1377542 | L4: =(60*B4/'AR5 Gear Ratios'!$D$2)*(('AR5 Gear Ratios'!$B$12*3.14)/63360) -> 0.55840091 | M4: =(60*B4/'AR5 Gear Ratios'!$D$3)*(('AR5 Gear Ratios'!$B$12*3.14)/63360) -> 0.92655018 | N4: =(60*B4/'AR5 Gear Ratios'!$D$4)*(('AR5 Gear Ratios'!$B$12*3.14)/63360) -> 1.5284696 | O4: =(60*B4/'AR5 Gear Ratios'!$D$5)*(('AR5 Gear Ratios'!$B$12*3.14)/63360) -> 2.0940034 | P4: =(60*B4/'AR5 Gear Ratios'!$D$6)*(('AR5 Gear Ratios'!$B$12*3.14)/63360) -> 2.8684978
A5: 2 | B5: 200 | C5: =B5/60 -> 3.3333333 | D5: =C5*2*3.14 -> 20.933333 | E5: =(B5/$B$63)*$T$2 -> 9.1666667 | F5: =E5*550 -> 5041.6667 | G5: =E5*745.7 -> 6835.5833 | H5: =F5/D5 -> 240.84395 | I5: =SQRT((G5*2)/'Acceleration Inputs'!$C$8) -> 3.8819746 | J5: =I5*2.236 -> 8.6800953 | K5: =AVERAGE($J$4:J5) -> 7.4089247 | L5: =(60*B5/'AR5 Gear Ratios'!$D$2)*(('AR5 Gear Ratios'!$B$12*3.14)/63360) -> 1.1168018 | M5: =(60*B5/'AR5 Gear Ratios'!$D$3)*(('AR5 Gear Ratios'!$B$12*3.14)/63360) -> 1.8531004 | N5: =(60*B5/'AR5 Gear Ratios'!$D$4)*(('AR5 Gear Ratios'!$B$12*3.14)/63360) -> 3.0569393 | O5: =(60*B5/'AR5 Gear Ratios'!$D$5)*(('AR5 Gear Ratios'!$B$12*3.14)/63360) -> 4.1880068 | P5: =(60*B5/'AR5 Gear Ratios'!$D$6)*(('AR5 Gear Ratios'!$B$12*3.14)/63360) -> 5.7369957
A6: 3 | B6: 300 | C6: =B6/60 -> 5 | D6: =C6*2*3.14 -> 31.4 | E6: =(B6/$B$63)*$T$2 -> 13.75 | F6: =E6*550 -> 7562.5 | G6: =E6*745.7 -> 10253.375 | H6: =F6/D6 -> 240.84395 | I6: =SQRT((G6*2)/'Acceleration Inputs'!$C$8) -> 4.7544285 | J6: =I6*2.236 -> 10.630902 | K6: =AVERAGE($J$4:J6) -> 8.4829172 | L6: =(60*B6/'AR5 Gear Ratios'!$D$2)*(('AR5 Gear Ratios'!$B$12*3.14)/63360) -> 1.6752027 | M6: =(60*B6/'AR5 Gear Ratios'!$D$3)*(('AR5 Gear Ratios'!$B$12*3.14)/63360) -> 2.7796506 | N6: =(60*B6/'AR5 Gear Ratios'!$D$4)*(('AR5 Gear Ratios'!$B$12*3.14)/63360) -> 4.5854089 | O6: =(60*B6/'AR5 Gear Ratios'!$D$5)*(('AR5 Gear Ratios'!$B$12*3.14)/63360) -> 6.2820102 | P6: =(60*B6/'AR5 Gear Ratios'!$D$6)*(('AR5 Gear Ratios'!$B$12*3.14)/63360) -> 8.6054935
A7: 4 | B7: 400 | C7: =B7/60 -> 6.6666667 | D7: =C7*2*3.14 -> 41.866667 | E7: =(B7/$B$63)*$T$2 -> 18.333333 | F7: =E7*550 -> 10083.333 | G7: =E7*745.7 -> 13671.167 | H7: =F7/D7 -> 240.84395 | I7: =SQRT((G7*2)/'Acceleration Inputs'!$C$8) -> 5.4899412 | J7: =I7*2.236 -> 12.275508 | K7: =AVERAGE($J$4:J7) -> 9.431065 | L7: =(60*B7/'AR5 Gear Ratios'!$D$2)*(('AR5 Gear Ratios'!$B$12*3.14)/63360) -> 2.2336036 | M7: =(60*B7/'AR5 Gear Ratios'!$D$3)*(('AR5 Gear Ratios'!$B$12*3.14)/63360) -> 3.7062007 | N7: =(60*B7/'AR5 Gear Ratios'!$D$4)*(('AR5 Gear Ratios'!$B$12*3.14)/63360) -> 6.1138786 | O7: =(60*B7/'AR5 Gear Ratios'!$D$5)*(('AR5 Gear Ratios'!$B$12*3.14)/63360) -> 8.3760137 | P7: =(60*B7/'AR5 Gear Ratios'!$D$6)*(('AR5 Gear Ratios'!$B$12*3.14)/63360) -> 11.473991
A8: 5 | B8: 500 | C8: =B8/60 -> 8.3333333 | D8: =C8*2*3.14 -> 52.333333 | E8: =(B8/$B$63)*$T$2 -> 22.916667 | F8: =E8*550 -> 12604.167 | G8: =E8*745.7 -> 17088.958 | H8: =F8/D8 -> 240.84395 | I8: =SQRT((G8*2)/'Acceleration Inputs'!$C$8) -> 6.1379408 | J8: =I8*2.236 -> 13.724436 | K8: =AVERAGE($J$4:J8) -> 10.289739 | L8: =(60*B8/'AR5 Gear Ratios'!$D$2)*(('AR5 Gear Ratios'!$B$12*3.14)/63360) -> 2.7920046 | M8: =(60*B8/'AR5 Gear Ratios'!$D$3)*(('AR5 Gear Ratios'!$B$12*3.14)/63360) -> 4.6327509 | N8: =(60*B8/'AR5 Gear Ratios'!$D$4)*(('AR5 Gear Ratios'!$B$12*3.14)/63360) -> 7.6423482 | O8: =(60*B8/'AR5 Gear Ratios'!$D$5)*(('AR5 Gear Ratios'!$B$12*3.14)/63360) -> 10.470017 | P8: =(60*B8/'AR5 Gear Ratios'!$D$6)*(('AR5 Gear Ratios'!$B$12*3.14)/63360) -> 14.342489
A9: 6 | B9: 600 | C9: =B9/60 -> 10 | D9: =C9*2*3.14 -> 62.8 | E9: =(B9/$B$63)*$T$2 -> 27.5 | F9: =E9*550 -> 15125 | G9: =E9*745.7 -> 20506.75 | H9: =F9/D9 -> 240.84395 | I9: =SQRT((G9*2)/'Acceleration Inputs'!$C$8) -> 6.7237773 | J9: =I9*2.236 -> 15.034366 | K9: =AVERAGE($J$4:J9) -> 11.08051 | L9: =(60*B9/'AR5 Gear Ratios'!$D$2)*(('AR5 Gear Ratios'!$B$12*3.14)/63360) -> 3.3504055 | M9: =(60*B9/'AR5 Gear Ratios'!$D$3)*(('AR5 Gear Ratios'!$B$12*3.14)/63360) -> 5.5593011 | N9: =(60*B9/'AR5 Gear Ratios'!$D$4)*(('AR5 Gear Ratios'!$B$12*3.14)/63360) -> 9.1708179 | O9: =(60*B9/'AR5 Gear Ratios'!$D$5)*(('AR5 Gear Ratios'!$B$12*3.14)/63360) -> 12.56402 | P9: =(60*B9/'AR5 Gear Ratios'!$D$6)*(('AR5 Gear Ratios'!$B$12*3.14)/63360) -> 17.210987
A10: 7 | B10: 700 | C10: =B10/60 -> 11.666667 | D10: =C10*2*3.14 -> 73.266667 | E10: =(B10/$B$63)*$T$2 -> 32.083333 | F10: =E10*550 -> 17645.833 | G10: =E10*745.7 -> 23924.542 | H10: =F10/D10 -> 240.84395 | I10: =SQRT((G10*2)/'Acceleration Inputs'!$C$8) -> 7.2625095 | J10: =I10*2.236 -> 16.238971 | K10: =AVERAGE($J$4:J10) -> 11.817433 | L10: =(60*B10/'AR5 Gear Ratios'!$D$2)*(('AR5 Gear Ratios'!$B$12*3.14)/63360) -> 3.9088064 | M10: =(60*B10/'AR5 Gear Ratios'!$D$3)*(('AR5 Gear Ratios'!$B$12*3.14)/63360) -> 6.4858513 | N10: =(60*B10/'AR5 Gear Ratios'!$D$4)*(('AR5 Gear Ratios'!$B$12*3.14)/63360) -> 10.699288 | O10: =(60*B10/'AR5 Gear Ratios'!$D$5)*(('AR5 Gear Ratios'!$B$12*3.14)/63360) -> 14.658024 | P10: =(60*B10/'AR5 Gear Ratios'!$D$6)*(('AR5 Gear Ratios'!$B$12*3.14)/63360) -> 20.079485
A11: 8 | B11: 800 | C11: =B11/60 -> 13.333333 | D11: =C11*2*3.14 -> 83.733333 | E11: =(B11/$B$63)*$T$2 -> 36.666667 | F11: =E11*550 -> 20166.667 | G11: =E11*745.7 -> 27342.333 | H11: =F11/D11 -> 240.84395 | I11: =SQRT((G11*2)/'Acceleration Inputs'!$C$8) -> 7.7639493 | J11: =I11*2.236 -> 17.360191 | K11: =AVERAGE($J$4:J11) -> 12.510278 | L11: =(60*B11/'AR5 Gear Ratios'!$D$2)*(('AR5 Gear Ratios'!$B$12*3.14)/63360) -> 4.4672073 | M11: =(60*B11/'AR5 Gear Ratios'!$D$3)*(('AR5 Gear Ratios'!$B$12*3.14)/63360) -> 7.4124015 | N11: =(60*B11/'AR5 Gear Ratios'!$D$4)*(('AR5 Gear Ratios'!$B$12*3.14)/63360) -> 12.227757 | O11: =(60*B11/'AR5 Gear Ratios'!$D$5)*(('AR5 Gear Ratios'!$B$12*3.14)/63360) -> 16.752027 | P11: =(60*B11/'AR5 Gear Ratios'!$D$6)*(('AR5 Gear Ratios'!$B$12*3.14)/63360) -> 22.947983
A12: 9 | B12: 900 | C12: =B12/60 -> 15 | D12: =C12*2*3.14 -> 94.2 | E12: =(B12/$B$63)*$T$2 -> 41.25 | F12: =E12*550 -> 22687.5 | G12: =E12*745.7 -> 30760.125 | H12: =F12/D12 -> 240.84395 | I12: =SQRT((G12*2)/'Acceleration Inputs'!$C$8) -> 8.2349118 | J12: =I12*2.236 -> 18.413263 | K12: =AVERAGE($J$4:J12) -> 13.166165 | L12: =(60*B12/'AR5 Gear Ratios'!$D$2)*(('AR5 Gear Ratios'!$B$12*3.14)/63360) -> 5.0256082 | M12: =(60*B12/'AR5 Gear Ratios'!$D$3)*(('AR5 Gear Ratios'!$B$12*3.14)/63360) -> 8.3389517 | N12: =(60*B12/'AR5 Gear Ratios'!$D$4)*(('AR5 Gear Ratios'!$B$12*3.14)/63360) -> 13.756227 | O12: =(60*B12/'AR5 Gear Ratios'!$D$5)*(('AR5 Gear Ratios'!$B$12*3.14)/63360) -> 18.846031 | P12: =(60*B12/'AR5 Gear Ratios'!$D$6)*(('AR5 Gear Ratios'!$B$12*3.14)/63360) -> 25.81648
A13: 10 | B13: 1000 | C13: =B13/60 -> 16.666667 | D13: =C13*2*3.14 -> 104.66667 | E13: =(B13/$B$63)*$T$2 -> 45.833333 | F13: =E13*550 -> 25208.333 | G13: =E13*745.7 -> 34177.917 | H13: =F13/D13 -> 240.84395 | I13: =SQRT((G13*2)/'Acceleration Inputs'!$C$8) -> 8.6803592 | J13: =I13*2.236 -> 19.409283 | K13: =AVERAGE($J$4:J13) -> 13.790477 | L13: =(60*B13/'AR5 Gear Ratios'!$D$2)*(('AR5 Gear Ratios'!$B$12*3.14)/63360) -> 5.5840091 | M13: =(60*B13/'AR5 Gear Ratios'!$D$3)*(('AR5 Gear Ratios'!$B$12*3.14)/63360) -> 9.2655018 | N13: =(60*B13/'AR5 Gear Ratios'!$D$4)*(('AR5 Gear Ratios'!$B$12*3.14)/63360) -> 15.284696 | O13: =(60*B13/'AR5 Gear Ratios'!$D$5)*(('AR5 Gear Ratios'!$B$12*3.14)/63360) -> 20.940034 | P13: =(60*B13/'AR5 Gear Ratios'!$D$6)*(('AR5 Gear Ratios'!$B$12*3.14)/63360) -> 28.684978
A14: 11 | B14: 1100 | C14: =B14/60 -> 18.333333 | D14: =C14*2*3.14 -> 115.13333 | E14: =(B14/$B$63)*$T$2 -> 50.416667 | F14: =E14*550 -> 27729.167 | G14: =E14*745.7 -> 37595.708 | H14: =F14/D14 -> 240.84395 | I14: =SQRT((G14*2)/'Acceleration Inputs'!$C$8) -> 9.1040375 | J14: =I14*2.236 -> 20.356628 | K14: =AVERAGE($J$4:J14) -> 14.3874 | L14: =(60*B14/'AR5 Gear Ratios'!$D$2)*(('AR5 Gear Ratios'!$B$12*3.14)/63360) -> 6.14241 | M14: =(60*B14/'AR5 Gear Ratios'!$D$3)*(('AR5 Gear Ratios'!$B$12*3.14)/63360) -> 10.192052 | N14: =(60*B14/'AR5 Gear Ratios'!$D$4)*(('AR5 Gear Ratios'!$B$12*3.14)/63360) -> 16.813166 | O14: =(60*B14/'AR5 Gear Ratios'!$D$5)*(('AR5 Gear Ratios'!$B$12*3.14)/63360) -> 23.034038 | P14: =(60*B14/'AR5 Gear Ratios'!$D$6)*(('AR5 Gear Ratios'!$B$12*3.14)/63360) -> 31.553476
A15: 12 | B15: 1200 | C15: =B15/60 -> 20 | D15: =C15*2*3.14 -> 125.6 | E15: =(B15/$B$63)*$T$2 -> 55 | F15: =E15*550 -> 30250 | G15: =E15*745.7 -> 41013.5 | H15: =F15/D15 -> 240.84395 | I15: =SQRT((G15*2)/'Acceleration Inputs'!$C$8) -> 9.508857 | J15: =I15*2.236 -> 21.261804 | K15: =AVERAGE($J$4:J15) -> 14.960267 | L15: =(60*B15/'AR5 Gear Ratios'!$D$2)*(('AR5 Gear Ratios'!$B$12*3.14)/63360) -> 6.7008109 | M15: =(60*B15/'AR5 Gear Ratios'!$D$3)*(('AR5 Gear Ratios'!$B$12*3.14)/63360) -> 11.118602 | N15: =(60*B15/'AR5 Gear Ratios'!$D$4)*(('AR5 Gear Ratios'!$B$12*3.14)/63360) -> 18.341636 | O15: =(60*B15/'AR5 Gear Ratios'!$D$5)*(('AR5 Gear Ratios'!$B$12*3.14)/63360) -> 25.128041 | P15: =(60*B15/'AR5 Gear Ratios'!$D$6)*(('AR5 Gear Ratios'!$B$12*3.14)/63360) -> 34.421974
... A63: 60 | B63: 6000 | C63: =B63/60 -> 100 | D63: =C63*2*3.14 -> 628 | E63: =(B63/$B$63)*$T$2 -> 275 | F63: =E63*550 -> 151250 | G63: =E63*745.7 -> 205067.5 | H63: =F63/D63 -> 240.84395 | I63: =SQRT((G63*2)/'Acceleration Inputs'!$C$8) -> 21.262451 | J63: =I63*2.236 -> 47.54284 | K63: =AVERAGE($J$4:J63) -> 32.070701 | L63: =(60*B63/'AR5 Gear Ratios'!$D$2)*(('AR5 Gear Ratios'!$B$12*3.14)/63360) -> 33.504055 | M63: =(60*B63/'AR5 Gear Ratios'!$D$3)*(('AR5 Gear Ratios'!$B$12*3.14)/63360) -> 55.593011 | N63: =(60*B63/'AR5 Gear Ratios'!$D$4)*(('AR5 Gear Ratios'!$B$12*3.14)/63360) -> 91.708179 | O63: =(60*B63/'AR5 Gear Ratios'!$D$5)*(('AR5 Gear Ratios'!$B$12*3.14)/63360) -> 125.6402 | P63: =(60*B63/'AR5 Gear Ratios'!$D$6)*(('AR5 Gear Ratios'!$B$12*3.14)/63360) -> 172.10987
A64: 61 | B64: 6100 | C64: =B64/60 -> 101.66667 | D64: =C64*2*3.14 -> 638.46667 | E64: =$T$2 -> 275 | F64: =E64*550 -> 151250 | G64: =E64*745.7 -> 205067.5 | H64: =F64/D64 -> 236.89569 | I64: =SQRT((G64*2)/'Acceleration Inputs'!$C$8) -> 21.262451 | J64: =I64*2.236 -> 47.54284 | K64: =AVERAGE($J$4:J64) -> 32.324343 | L64: =(60*B64/'AR5 Gear Ratios'!$D$2)*(('AR5 Gear Ratios'!$B$12*3.14)/63360) -> 34.062456 | M64: =(60*B64/'AR5 Gear Ratios'!$D$3)*(('AR5 Gear Ratios'!$B$12*3.14)/63360) -> 56.519561 | N64: =(60*B64/'AR5 Gear Ratios'!$D$4)*(('AR5 Gear Ratios'!$B$12*3.14)/63360) -> 93.236648 | O64: =(60*B64/'AR5 Gear Ratios'!$D$5)*(('AR5 Gear Ratios'!$B$12*3.14)/63360) -> 127.73421 | P64: =(60*B64/'AR5 Gear Ratios'!$D$6)*(('AR5 Gear Ratios'!$B$12*3.14)/63360) -> 174.97837
A65: 62 | B65: 6200 | C65: =B65/60 -> 103.33333 | D65: =C65*2*3.14 -> 648.93333 | E65: =$T$2 -> 275 | F65: =E65*550 -> 151250 | G65: =E65*745.7 -> 205067.5 | H65: =F65/D65 -> 233.07479 | I65: =SQRT((G65*2)/'Acceleration Inputs'!$C$8) -> 21.262451 | J65: =I65*2.236 -> 47.54284 | K65: =AVERAGE($J$4:J65) -> 32.569802 | L65: =(60*B65/'AR5 Gear Ratios'!$D$2)*(('AR5 Gear Ratios'!$B$12*3.14)/63360) -> 34.620856 | M65: =(60*B65/'AR5 Gear Ratios'!$D$3)*(('AR5 Gear Ratios'!$B$12*3.14)/63360) -> 57.446111 | N65: =(60*B65/'AR5 Gear Ratios'!$D$4)*(('AR5 Gear Ratios'!$B$12*3.14)/63360) -> 94.765118 | O65: =(60*B65/'AR5 Gear Ratios'!$D$5)*(('AR5 Gear Ratios'!$B$12*3.14)/63360) -> 129.82821 | P65: =(60*B65/'AR5 Gear Ratios'!$D$6)*(('AR5 Gear Ratios'!$B$12*3.14)/63360) -> 177.84687
A66: 63 | B66: 6300 | C66: =B66/60 -> 105 | D66: =C66*2*3.14 -> 659.4 | E66: =$T$2 -> 275 | F66: =E66*550 -> 151250 | G66: =E66*745.7 -> 205067.5 | H66: =F66/D66 -> 229.37519 | I66: =SQRT((G66*2)/'Acceleration Inputs'!$C$8) -> 21.262451 | J66: =I66*2.236 -> 47.54284 | K66: =AVERAGE($J$4:J66) -> 32.80747 | L66: =(60*B66/'AR5 Gear Ratios'!$D$2)*(('AR5 Gear Ratios'!$B$12*3.14)/63360) -> 35.179257 | M66: =(60*B66/'AR5 Gear Ratios'!$D$3)*(('AR5 Gear Ratios'!$B$12*3.14)/63360) -> 58.372662 | N66: =(60*B66/'AR5 Gear Ratios'!$D$4)*(('AR5 Gear Ratios'!$B$12*3.14)/63360) -> 96.293588 | O66: =(60*B66/'AR5 Gear Ratios'!$D$5)*(('AR5 Gear Ratios'!$B$12*3.14)/63360) -> 131.92222 | P66: =(60*B66/'AR5 Gear Ratios'!$D$6)*(('AR5 Gear Ratios'!$B$12*3.14)/63360) -> 180.71536
J69: Average: | K69: =AVERAGE(K4:K66) -> 22.514549
K71: Time Elapsed: | L71: =L66/$K$69 -> 1.5625122 | M71: =M55/$K$69 -> 2.1399767
K72: Shift Time: | L72: 0.5
K74: Total 0-60 time: | L74: =L71+M71+L72 -> 4.2024889 | M74: seconds
K75: This value does not account for aero drag

Sheet Torque Curve Estimation w drag
L1: Cd | M1: 0.4 | O1: A: | P1: 21.5 | AG1: Value | AH1: RPM
B2: RPM | C2: Rev/s | D2: rad/s | E2: Power (HP) | F2: Power (ft-lbs/s) | G2: Power (kW) | H2: Torque ft-lbs | I2: Theoretical Accel (m/s^2) | J2: Theoret. Accel (mph/s) | K2: Average Accel mph/s | L2: 1st Gear | M2: Drag Force | N2: Drive force | O2: 2nd | P2: Drag Force | Q2: Drive force | R2: 3rd | S2: Drag Force | T2: Drive force | U2: 4th | V2: Drag Force | W2: Drive force | X2: 5th | Y2: Drag Force | Z2: Drive force | AA2: 6th | AB2: Drag Force | AC2: Drive force | AF2: Reference Power | AG2: ='Acceleration Inputs'!C2 -> 275 | AH2: ='Acceleration Inputs'!E2 -> 6000
B3: 0 | C3: =B3/60 -> 0 | D3: =C3*2*3.14 -> 0 | E3: 0 | F3: 0 | G3: =E3*745.7 -> 0 | AF3: Reference Torque | AG3: ='Acceleration Inputs'!C3 -> 277 | AH3: ='Acceleration Inputs'!E3 -> 3600
A4: 1 | B4: 100 | C4: =B4/60 -> 1.6666667 | D4: =C4*2*3.14 -> 10.466667 | E4: =(B4/$B$63)*$AG$2 -> 4.5833333 | F4: =E4*550 -> 2520.8333 | G4: =E4*745.7 -> 3417.7917 | H4: =F4/D4 -> 240.84395 | I4: =SQRT((G4*2)/'Acceleration Inputs'!$C$8) -> 2.7449706 | J4: =I4*2.236 -> 6.1377542 | K4: =AVERAGE($J$4:J4) -> 6.1377542 | L4: =(60*B4/'AR5 Gear Ratios'!$D$2)*(('AR5 Gear Ratios'!$B$12*3.14)/63360) -> 0.55840091 | M4: =0.5*0.00238*(L4*1.46)^2*$M$1*$P$1 -> 0.0068021054 | N4: =$H4*'AR5 Gear Ratios'!$D$2/('AR5 Gear Ratios'!$B$12/24) -> 3077.9857 | O4: =(60*B4/'AR5 Gear Ratios'!$D$3)*(('AR5 Gear Ratios'!$B$12*3.14)/63360) -> 0.92655018 | P4: =0.5*0.00238*(O4*1.46)^2*$M$1*$P$1 -> 0.018727897 | Q4: =$H4*'AR5 Gear Ratios'!$D$3/('AR5 Gear Ratios'!$B$12/24) -> 1854.9994 | R4: =(60*B4/'AR5 Gear Ratios'!$D$4)*(('AR5 Gear Ratios'!$B$12*3.14)/63360) -> 1.5284696 | S4: =0.5*0.00238*(R4*1.46)^2*$M$1*$P$1 -> 0.050964147 | T4: =$H4*'AR5 Gear Ratios'!$D$4/('AR5 Gear Ratios'!$B$12/24) -> 1124.4908 | U4: =(60*B4/'AR5 Gear Ratios'!$D$5)*(('AR5 Gear Ratios'!$B$12*3.14)/63360) -> 2.0940034 | V4: =0.5*0.00238*(U4*1.46)^2*$M$1*$P$1 -> 0.095654608 | W4: =$H4*'AR5 Gear Ratios'!$D$5/('AR5 Gear Ratios'!$B$12/24) -> 820.79618 | X4: =(60*B4/'AR5 Gear Ratios'!$D$6)*(('AR5 Gear Ratios'!$B$12*3.14)/63360) -> 2.8684978 | Y4: =0.5*0.00238*(X4*1.46)^2*$M$1*$P$1 -> 0.17949823 | Z4: =$H4*'AR5 Gear Ratios'!$D$6/('AR5 Gear Ratios'!$B$12/24) -> 599.18121 | AA4: =(60*B4/'AR5 Gear Ratios'!$D$7)*(('AR5 Gear Ratios'!$B$12*3.14)/63360) -> #DIV/0! | AB4: =0.5*0.00238*(AA4*1.46)^2*$M$1*$P$1 -> #DIV/0! | AC4: =$H4*'AR5 Gear Ratios'!$D$7/('AR5 Gear Ratios'!$B$12/24) -> 0
A5: 2 | B5: 200 | C5: =B5/60 -> 3.3333333 | D5: =C5*2*3.14 -> 20.933333 | E5: =(B5/$B$63)*$AG$2 -> 9.1666667 | F5: =E5*550 -> 5041.6667 | G5: =E5*745.7 -> 6835.5833 | H5: =F5/D5 -> 240.84395 | I5: =SQRT((G5*2)/'Acceleration Inputs'!$C$8) -> 3.8819746 | J5: =I5*2.236 -> 8.6800953 | K5: =AVERAGE($J$4:J5) -> 7.4089247 | L5: =(60*B5/'AR5 Gear Ratios'!$D$2)*(('AR5 Gear Ratios'!$B$12*3.14)/63360) -> 1.1168018 | M5: =0.5*0.00238*(L5*1.46)^2*$M$1*$P$1 -> 0.027208422 | N5: =$H5*'AR5 Gear Ratios'!$D$2/('AR5 Gear Ratios'!$B$12/24) -> 3077.9857 | O5: =(60*B5/'AR5 Gear Ratios'!$D$3)*(('AR5 Gear Ratios'!$B$12*3.14)/63360) -> 1.8531004 | P5: =0.5*0.00238*(O5*1.46)^2*$M$1*$P$1 -> 0.074911589 | Q5: =$H5*'AR5 Gear Ratios'!$D$3/('AR5 Gear Ratios'!$B$12/24) -> 1854.9994 | R5: =(60*B5/'AR5 Gear Ratios'!$D$4)*(('AR5 Gear Ratios'!$B$12*3.14)/63360) -> 3.0569393 | S5: =0.5*0.00238*(R5*1.46)^2*$M$1*$P$1 -> 0.20385659 | T5: =$H5*'AR5 Gear Ratios'!$D$4/('AR5 Gear Ratios'!$B$12/24) -> 1124.4908 | U5: =(60*B5/'AR5 Gear Ratios'!$D$5)*(('AR5 Gear Ratios'!$B$12*3.14)/63360) -> 4.1880068 | V5: =0.5*0.00238*(U5*1.46)^2*$M$1*$P$1 -> 0.38261843 | W5: =$H5*'AR5 Gear Ratios'!$D$5/('AR5 Gear Ratios'!$B$12/24) -> 820.79618 | X5: =(60*B5/'AR5 Gear Ratios'!$D$6)*(('AR5 Gear Ratios'!$B$12*3.14)/63360) -> 5.7369957 | Y5: =0.5*0.00238*(X5*1.46)^2*$M$1*$P$1 -> 0.71799293 | Z5: =$H5*'AR5 Gear Ratios'!$D$6/('AR5 Gear Ratios'!$B$12/24) -> 599.18121 | AA5: =(60*B5/'AR5 Gear Ratios'!$D$7)*(('AR5 Gear Ratios'!$B$12*3.14)/63360) -> #DIV/0! | AB5: =0.5*0.00238*(AA5*1.46)^2*$M$1*$P$1 -> #DIV/0! | AC5: =$H5*'AR5 Gear Ratios'!$D$7/('AR5 Gear Ratios'!$B$12/24) -> 0
A6: 3 | B6: 300 | C6: =B6/60 -> 5 | D6: =C6*2*3.14 -> 31.4 | E6: =(B6/$B$63)*$AG$2 -> 13.75 | F6: =E6*550 -> 7562.5 | G6: =E6*745.7 -> 10253.375 | H6: =F6/D6 -> 240.84395 | I6: =SQRT((G6*2)/'Acceleration Inputs'!$C$8) -> 4.7544285 | J6: =I6*2.236 -> 10.630902 | K6: =AVERAGE($J$4:J6) -> 8.4829172 | L6: =(60*B6/'AR5 Gear Ratios'!$D$2)*(('AR5 Gear Ratios'!$B$12*3.14)/63360) -> 1.6752027 | M6: =0.5*0.00238*(L6*1.46)^2*$M$1*$P$1 -> 0.061218949 | N6: =$H6*'AR5 Gear Ratios'!$D$2/('AR5 Gear Ratios'!$B$12/24) -> 3077.9857 | O6: =(60*B6/'AR5 Gear Ratios'!$D$3)*(('AR5 Gear Ratios'!$B$12*3.14)/63360) -> 2.7796506 | P6: =0.5*0.00238*(O6*1.46)^2*$M$1*$P$1 -> 0.16855107 | Q6: =$H6*'AR5 Gear Ratios'!$D$3/('AR5 Gear Ratios'!$B$12/24) -> 1854.9994 | R6: =(60*B6/'AR5 Gear Ratios'!$D$4)*(('AR5 Gear Ratios'!$B$12*3.14)/63360) -> 4.5854089 | S6: =0.5*0.00238*(R6*1.46)^2*$M$1*$P$1 -> 0.45867732 | T6: =$H6*'AR5 Gear Ratios'!$D$4/('AR5 Gear Ratios'!$B$12/24) -> 1124.4908 | U6: =(60*B6/'AR5 Gear Ratios'!$D$5)*(('AR5 Gear Ratios'!$B$12*3.14)/63360) -> 6.2820102 | V6: =0.5*0.00238*(U6*1.46)^2*$M$1*$P$1 -> 0.86089147 | W6: =$H6*'AR5 Gear Ratios'!$D$5/('AR5 Gear Ratios'!$B$12/24) -> 820.79618 | X6: =(60*B6/'AR5 Gear Ratios'!$D$6)*(('AR5 Gear Ratios'!$B$12*3.14)/63360) -> 8.6054935 | Y6: =0.5*0.00238*(X6*1.46)^2*$M$1*$P$1 -> 1.6154841 | Z6: =$H6*'AR5 Gear Ratios'!$D$6/('AR5 Gear Ratios'!$B$12/24) -> 599.18121 | AA6: =(60*B6/'AR5 Gear Ratios'!$D$7)*(('AR5 Gear Ratios'!$B$12*3.14)/63360) -> #DIV/0! | AB6: =0.5*0.00238*(AA6*1.46)^2*$M$1*$P$1 -> #DIV/0! | AC6: =$H6*'AR5 Gear Ratios'!$D$7/('AR5 Gear Ratios'!$B$12/24) -> 0
A7: 4 | B7: 400 | C7: =B7/60 -> 6.6666667 | D7: =C7*2*3.14 -> 41.866667 | E7: =(B7/$B$63)*$AG$2 -> 18.333333 | F7: =E7*550 -> 10083.333 | G7: =E7*745.7 -> 13671.167 | H7: =F7/D7 -> 240.84395 | I7: =SQRT((G7*2)/'Acceleration Inputs'!$C$8) -> 5.4899412 | J7: =I7*2.236 -> 12.275508 | K7: =AVERAGE($J$4:J7) -> 9.431065 | L7: =(60*B7/'AR5 Gear Ratios'!$D$2)*(('AR5 Gear Ratios'!$B$12*3.14)/63360) -> 2.2336036 | M7: =0.5*0.00238*(L7*1.46)^2*$M$1*$P$1 -> 0.10883369 | N7: =$H7*'AR5 Gear Ratios'!$D$2/('AR5 Gear Ratios'!$B$12/24) -> 3077.9857 | O7: =(60*B7/'AR5 Gear Ratios'!$D$3)*(('AR5 Gear Ratios'!$B$12*3.14)/63360) -> 3.7062007 | P7: =0.5*0.00238*(O7*1.46)^2*$M$1*$P$1 -> 0.29964636 | Q7: =$H7*'AR5 Gear Ratios'!$D$3/('AR5 Gear Ratios'!$B$12/24) -> 1854.9994 | R7: =(60*B7/'AR5 Gear Ratios'!$D$4)*(('AR5 Gear Ratios'!$B$12*3.14)/63360) -> 6.1138786 | S7: =0.5*0.00238*(R7*1.46)^2*$M$1*$P$1 -> 0.81542635 | T7: =$H7*'AR5 Gear Ratios'!$D$4/('AR5 Gear Ratios'!$B$12/24) -> 1124.4908 | U7: =(60*B7/'AR5 Gear Ratios'!$D$5)*(('AR5 Gear Ratios'!$B$12*3.14)/63360) -> 8.3760137 | V7: =0.5*0.00238*(U7*1.46)^2*$M$1*$P$1 -> 1.5304737 | W7: =$H7*'AR5 Gear Ratios'!$D$5/('AR5 Gear Ratios'!$B$12/24) -> 820.79618 | X7: =(60*B7/'AR5 Gear Ratios'!$D$6)*(('AR5 Gear Ratios'!$B$12*3.14)/63360) -> 11.473991 | Y7: =0.5*0.00238*(X7*1.46)^2*$M$1*$P$1 -> 2.8719717 | Z7: =$H7*'AR5 Gear Ratios'!$D$6/('AR5 Gear Ratios'!$B$12/24) -> 599.18121 | AA7: =(60*B7/'AR5 Gear Ratios'!$D$7)*(('AR5 Gear Ratios'!$B$12*3.14)/63360) -> #DIV/0! | AB7: =0.5*0.00238*(AA7*1.46)^2*$M$1*$P$1 -> #DIV/0! | AC7: =$H7*'AR5 Gear Ratios'!$D$7/('AR5 Gear Ratios'!$B$12/24) -> 0
A8: 5 | B8: 500 | C8: =B8/60 -> 8.3333333 | D8: =C8*2*3.14 -> 52.333333 | E8: =(B8/$B$63)*$AG$2 -> 22.916667 | F8: =E8*550 -> 12604.167 | G8: =E8*745.7 -> 17088.958 | H8: =F8/D8 -> 240.84395 | I8: =SQRT((G8*2)/'Acceleration Inputs'!$C$8) -> 6.1379408 | J8: =I8*2.236 -> 13.724436 | K8: =AVERAGE($J$4:J8) -> 10.289739 | L8: =(60*B8/'AR5 Gear Ratios'!$D$2)*(('AR5 Gear Ratios'!$B$12*3.14)/63360) -> 2.7920046 | M8: =0.5*0.00238*(L8*1.46)^2*$M$1*$P$1 -> 0.17005264 | N8: =$H8*'AR5 Gear Ratios'!$D$2/('AR5 Gear Ratios'!$B$12/24) -> 3077.9857 | O8: =(60*B8/'AR5 Gear Ratios'!$D$3)*(('AR5 Gear Ratios'!$B$12*3.14)/63360) -> 4.6327509 | P8: =0.5*0.00238*(O8*1.46)^2*$M$1*$P$1 -> 0.46819743 | Q8: =$H8*'AR5 Gear Ratios'!$D$3/('AR5 Gear Ratios'!$B$12/24) -> 1854.9994 | R8: =(60*B8/'AR5 Gear Ratios'!$D$4)*(('AR5 Gear Ratios'!$B$12*3.14)/63360) -> 7.6423482 | S8: =0.5*0.00238*(R8*1.46)^2*$M$1*$P$1 -> 1.2741037 | T8: =$H8*'AR5 Gear Ratios'!$D$4/('AR5 Gear Ratios'!$B$12/24) -> 1124.4908 | U8: =(60*B8/'AR5 Gear Ratios'!$D$5)*(('AR5 Gear Ratios'!$B$12*3.14)/63360) -> 10.470017 | V8: =0.5*0.00238*(U8*1.46)^2*$M$1*$P$1 -> 2.3913652 | W8: =$H8*'AR5 Gear Ratios'!$D$5/('AR5 Gear Ratios'!$B$12/24) -> 820.79618 | X8: =(60*B8/'AR5 Gear Ratios'!$D$6)*(('AR5 Gear Ratios'!$B$12*3.14)/63360) -> 14.342489 | Y8: =0.5*0.00238*(X8*1.46)^2*$M$1*$P$1 -> 4.4874558 | Z8: =$H8*'AR5 Gear Ratios'!$D$6/('AR5 Gear Ratios'!$B$12/24) -> 599.18121 | AA8: =(60*B8/'AR5 Gear Ratios'!$D$7)*(('AR5 Gear Ratios'!$B$12*3.14)/63360) -> #DIV/0! | AB8: =0.5*0.00238*(AA8*1.46)^2*$M$1*$P$1 -> #DIV/0! | AC8: =$H8*'AR5 Gear Ratios'!$D$7/('AR5 Gear Ratios'!$B$12/24) -> 0
A9: 6 | B9: 600 | C9: =B9/60 -> 10 | D9: =C9*2*3.14 -> 62.8 | E9: =(B9/$B$63)*$AG$2 -> 27.5 | F9: =E9*550 -> 15125 | G9: =E9*745.7 -> 20506.75 | H9: =F9/D9 -> 240.84395 | I9: =SQRT((G9*2)/'Acceleration Inputs'!$C$8) -> 6.7237773 | J9: =I9*2.236 -> 15.034366 | K9: =AVERAGE($J$4:J9) -> 11.08051 | L9: =(60*B9/'AR5 Gear Ratios'!$D$2)*(('AR5 Gear Ratios'!$B$12*3.14)/63360) -> 3.3504055 | M9: =0.5*0.00238*(L9*1.46)^2*$M$1*$P$1 -> 0.2448758 | N9: =$H9*'AR5 Gear Ratios'!$D$2/('AR5 Gear Ratios'!$B$12/24) -> 3077.9857 | O9: =(60*B9/'AR5 Gear Ratios'!$D$3)*(('AR5 Gear Ratios'!$B$12*3.14)/63360) -> 5.5593011 | P9: =0.5*0.00238*(O9*1.46)^2*$M$1*$P$1 -> 0.6742043 | Q9: =$H9*'AR5 Gear Ratios'!$D$3/('AR5 Gear Ratios'!$B$12/24) -> 1854.9994 | R9: =(60*B9/'AR5 Gear Ratios'!$D$4)*(('AR5 Gear Ratios'!$B$12*3.14)/63360) -> 9.1708179 | S9: =0.5*0.00238*(R9*1.46)^2*$M$1*$P$1 -> 1.8347093 | T9: =$H9*'AR5 Gear Ratios'!$D$4/('AR5 Gear Ratios'!$B$12/24) -> 1124.4908 | U9: =(60*B9/'AR5 Gear Ratios'!$D$5)*(('AR5 Gear Ratios'!$B$12*3.14)/63360) -> 12.56402 | V9: =0.5*0.00238*(U9*1.46)^2*$M$1*$P$1 -> 3.4435659 | W9: =$H9*'AR5 Gear Ratios'!$D$5/('AR5 Gear Ratios'!$B$12/24) -> 820.79618 | X9: =(60*B9/'AR5 Gear Ratios'!$D$6)*(('AR5 Gear Ratios'!$B$12*3.14)/63360) -> 17.210987 | Y9: =0.5*0.00238*(X9*1.46)^2*$M$1*$P$1 -> 6.4619363 | Z9: =$H9*'AR5 Gear Ratios'!$D$6/('AR5 Gear Ratios'!$B$12/24) -> 599.18121 | AA9: =(60*B9/'AR5 Gear Ratios'!$D$7)*(('AR5 Gear Ratios'!$B$12*3.14)/63360) -> #DIV/0! | AB9: =0.5*0.00238*(AA9*1.46)^2*$M$1*$P$1 -> #DIV/0! | AC9: =$H9*'AR5 Gear Ratios'!$D$7/('AR5 Gear Ratios'!$B$12/24) -> 0
A10: 7 | B10: 700 | C10: =B10/60 -> 11.666667 | D10: =C10*2*3.14 -> 73.266667 | E10: =(B10/$B$63)*$AG$2 -> 32.083333 | F10: =E10*550 -> 17645.833 | G10: =E10*745.7 -> 23924.542 | H10: =F10/D10 -> 240.84395 | I10: =SQRT((G10*2)/'Acceleration Inputs'!$C$8) -> 7.2625095 | J10: =I10*2.236 -> 16.238971 | K10: =AVERAGE($J$4:J10) -> 11.817433 | L10: =(60*B10/'AR5 Gear Ratios'!$D$2)*(('AR5 Gear Ratios'!$B$12*3.14)/63360) -> 3.9088064 | M10: =0.5*0.00238*(L10*1.46)^2*$M$1*$P$1 -> 0.33330317 | N10: =$H10*'AR5 Gear Ratios'!$D$2/('AR5 Gear Ratios'!$B$12/24) -> 3077.9857 | O10: =(60*B10/'AR5 Gear Ratios'!$D$3)*(('AR5 Gear Ratios'!$B$12*3.14)/63360) -> 6.4858513 | P10: =0.5*0.00238*(O10*1.46)^2*$M$1*$P$1 -> 0.91766696 | Q10: =$H10*'AR5 Gear Ratios'!$D$3/('AR5 Gear Ratios'!$B$12/24) -> 1854.9994 | R10: =(60*B10/'AR5 Gear Ratios'!$D$4)*(('AR5 Gear Ratios'!$B$12*3.14)/63360) -> 10.699288 | S10: =0.5*0.00238*(R10*1.46)^2*$M$1*$P$1 -> 2.4972432 | T10: =$H10*'AR5 Gear Ratios'!$D$4/('AR5 Gear Ratios'!$B$12/24) -> 1124.4908 | U10: =(60*B10/'AR5 Gear Ratios'!$D$5)*(('AR5 Gear Ratios'!$B$12*3.14)/63360) -> 14.658024 | V10: =0.5*0.00238*(U10*1.46)^2*$M$1*$P$1 -> 4.6870758 | W10: =$H10*'AR5 Gear Ratios'!$D$5/('AR5 Gear Ratios'!$B$12/24) -> 820.79618 | X10: =(60*B10/'AR5 Gear Ratios'!$D$6)*(('AR5 Gear Ratios'!$B$12*3.14)/63360) -> 20.079485 | Y10: =0.5*0.00238*(X10*1.46)^2*$M$1*$P$1 -> 8.7954134 | Z10: =$H10*'AR5 Gear Ratios'!$D$6/('AR5 Gear Ratios'!$B$12/24) -> 599.18121 | AA10: =(60*B10/'AR5 Gear Ratios'!$D$7)*(('AR5 Gear Ratios'!$B$12*3.14)/63360) -> #DIV/0! | AB10: =0.5*0.00238*(AA10*1.46)^2*$M$1*$P$1 -> #DIV/0! | AC10: =$H10*'AR5 Gear Ratios'!$D$7/('AR5 Gear Ratios'!$B$12/24) -> 0
A11: 8 | B11: 800 | C11: =B11/60 -> 13.333333 | D11: =C11*2*3.14 -> 83.733333 | E11: =(B11/$B$63)*$AG$2 -> 36.666667 | F11: =E11*550 -> 20166.667 | G11: =E11*745.7 -> 27342.333 | H11: =F11/D11 -> 240.84395 | I11: =SQRT((G11*2)/'Acceleration Inputs'!$C$8) -> 7.7639493 | J11: =I11*2.236 -> 17.360191 | K11: =AVERAGE($J$4:J11) -> 12.510278 | L11: =(60*B11/'AR5 Gear Ratios'!$D$2)*(('AR5 Gear Ratios'!$B$12*3.14)/63360) -> 4.4672073 | M11: =0.5*0.00238*(L11*1.46)^2*$M$1*$P$1 -> 0.43533475 | N11: =$H11*'AR5 Gear Ratios'!$D$2/('AR5 Gear Ratios'!$B$12/24) -> 3077.9857 | O11: =(60*B11/'AR5 Gear Ratios'!$D$3)*(('AR5 Gear Ratios'!$B$12*3.14)/63360) -> 7.4124015 | P11: =0.5*0.00238*(O11*1.46)^2*$M$1*$P$1 -> 1.1985854 | Q11: =$H11*'AR5 Gear Ratios'!$D$3/('AR5 Gear Ratios'!$B$12/24) -> 1854.9994 | R11: =(60*B11/'AR5 Gear Ratios'!$D$4)*(('AR5 Gear Ratios'!$B$12*3.14)/63360) -> 12.227757 | S11: =0.5*0.00238*(R11*1.46)^2*$M$1*$P$1 -> 3.2617054 | T11: =$H11*'AR5 Gear Ratios'!$D$4/('AR5 Gear Ratios'!$B$12/24) -> 1124.4908 | U11: =(60*B11/'AR5 Gear Ratios'!$D$5)*(('AR5 Gear Ratios'!$B$12*3.14)/63360) -> 16.752027 | V11: =0.5*0.00238*(U11*1.46)^2*$M$1*$P$1 -> 6.1218949 | W11: =$H11*'AR5 Gear Ratios'!$D$5/('AR5 Gear Ratios'!$B$12/24) -> 820.79618 | X11: =(60*B11/'AR5 Gear Ratios'!$D$6)*(('AR5 Gear Ratios'!$B$12*3.14)/63360) -> 22.947983 | Y11: =0.5*0.00238*(X11*1.46)^2*$M$1*$P$1 -> 11.487887 | Z11: =$H11*'AR5 Gear Ratios'!$D$6/('AR5 Gear Ratios'!$B$12/24) -> 599.18121 | AA11: =(60*B11/'AR5 Gear Ratios'!$D$7)*(('AR5 Gear Ratios'!$B$12*3.14)/63360) -> #DIV/0! | AB11: =0.5*0.00238*(AA11*1.46)^2*$M$1*$P$1 -> #DIV/0! | AC11: =$H11*'AR5 Gear Ratios'!$D$7/('AR5 Gear Ratios'!$B$12/24) -> 0
A12: 9 | B12: 900 | C12: =B12/60 -> 15 | D12: =C12*2*3.14 -> 94.2 | E12: =(B12/$B$63)*$AG$2 -> 41.25 | F12: =E12*550 -> 22687.5 | G12: =E12*745.7 -> 30760.125 | H12: =F12/D12 -> 240.84395 | I12: =SQRT((G12*2)/'Acceleration Inputs'!$C$8) -> 8.2349118 | J12: =I12*2.236 -> 18.413263 | K12: =AVERAGE($J$4:J12) -> 13.166165 | L12: =(60*B12/'AR5 Gear Ratios'!$D$2)*(('AR5 Gear Ratios'!$B$12*3.14)/63360) -> 5.0256082 | M12: =0.5*0.00238*(L12*1.46)^2*$M$1*$P$1 -> 0.55097054 | N12: =$H12*'AR5 Gear Ratios'!$D$2/('AR5 Gear Ratios'!$B$12/24) -> 3077.9857 | O12: =(60*B12/'AR5 Gear Ratios'!$D$3)*(('AR5 Gear Ratios'!$B$12*3.14)/63360) -> 8.3389517 | P12: =0.5*0.00238*(O12*1.46)^2*$M$1*$P$1 -> 1.5169597 | Q12: =$H12*'AR5 Gear Ratios'!$D$3/('AR5 Gear Ratios'!$B$12/24) -> 1854.9994 | R12: =(60*B12/'AR5 Gear Ratios'!$D$4)*(('AR5 Gear Ratios'!$B$12*3.14)/63360) -> 13.756227 | S12: =0.5*0.00238*(R12*1.46)^2*$M$1*$P$1 -> 4.1280959 | T12: =$H12*'AR5 Gear Ratios'!$D$4/('AR5 Gear Ratios'!$B$12/24) -> 1124.4908 | U12: =(60*B12/'AR5 Gear Ratios'!$D$5)*(('AR5 Gear Ratios'!$B$12*3.14)/63360) -> 18.846031 | V12: =0.5*0.00238*(U12*1.46)^2*$M$1*$P$1 -> 7.7480232 | W12: =$H12*'AR5 Gear Ratios'!$D$5/('AR5 Gear Ratios'!$B$12/24) -> 820.79618 | X12: =(60*B12/'AR5 Gear Ratios'!$D$6)*(('AR5 Gear Ratios'!$B$12*3.14)/63360) -> 25.81648 | Y12: =0.5*0.00238*(X12*1.46)^2*$M$1*$P$1 -> 14.539357 | Z12: =$H12*'AR5 Gear Ratios'!$D$6/('AR5 Gear Ratios'!$B$12/24) -> 599.18121 | AA12: =(60*B12/'AR5 Gear Ratios'!$D$7)*(('AR5 Gear Ratios'!$B$12*3.14)/63360) -> #DIV/0! | AB12: =0.5*0.00238*(AA12*1.46)^2*$M$1*$P$1 -> #DIV/0! | AC12: =$H12*'AR5 Gear Ratios'!$D$7/('AR5 Gear Ratios'!$B$12/24) -> 0
A13: 10 | B13: 1000 | C13: =B13/60 -> 16.666667 | D13: =C13*2*3.14 -> 104.66667 | E13: =(B13/$B$63)*$AG$2 -> 45.833333 | F13: =E13*550 -> 25208.333 | G13: =E13*745.7 -> 34177.917 | H13: =F13/D13 -> 240.84395 | I13: =SQRT((G13*2)/'Acceleration Inputs'!$C$8) -> 8.6803592 | J13: =I13*2.236 -> 19.409283 | K13: =AVERAGE($J$4:J13) -> 13.790477 | L13: =(60*B13/'AR5 Gear Ratios'!$D$2)*(('AR5 Gear Ratios'!$B$12*3.14)/63360) -> 5.5840091 | M13: =0.5*0.00238*(L13*1.46)^2*$M$1*$P$1 -> 0.68021054 | N13: =$H13*'AR5 Gear Ratios'!$D$2/('AR5 Gear Ratios'!$B$12/24) -> 3077.9857 | O13: =(60*B13/'AR5 Gear Ratios'!$D$3)*(('AR5 Gear Ratios'!$B$12*3.14)/63360) -> 9.2655018 | P13: =0.5*0.00238*(O13*1.46)^2*$M$1*$P$1 -> 1.8727897 | Q13: =$H13*'AR5 Gear Ratios'!$D$3/('AR5 Gear Ratios'!$B$12/24) -> 1854.9994 | R13: =(60*B13/'AR5 Gear Ratios'!$D$4)*(('AR5 Gear Ratios'!$B$12*3.14)/63360) -> 15.284696 | S13: =0.5*0.00238*(R13*1.46)^2*$M$1*$P$1 -> 5.0964147 | T13: =$H13*'AR5 Gear Ratios'!$D$4/('AR5 Gear Ratios'!$B$12/24) -> 1124.4908 | U13: =(60*B13/'AR5 Gear Ratios'!$D$5)*(('AR5 Gear Ratios'!$B$12*3.14)/63360) -> 20.940034 | V13: =0.5*0.00238*(U13*1.46)^2*$M$1*$P$1 -> 9.5654608 | W13: =$H13*'AR5 Gear Ratios'!$D$5/('AR5 Gear Ratios'!$B$12/24) -> 820.79618 | X13: =(60*B13/'AR5 Gear Ratios'!$D$6)*(('AR5 Gear Ratios'!$B$12*3.14)/63360) -> 28.684978 | Y13: =0.5*0.00238*(X13*1.46)^2*$M$1*$P$1 -> 17.949823 | Z13: =$H13*'AR5 Gear Ratios'!$D$6/('AR5 Gear Ratios'!$B$12/24) -> 599.18121 | AA13: =(60*B13/'AR5 Gear Ratios'!$D$7)*(('AR5 Gear Ratios'!$B$12*3.14)/63360) -> #DIV/0! | AB13: =0.5*0.00238*(AA13*1.46)^2*$M$1*$P$1 -> #DIV/0! | AC13: =$H13*'AR5 Gear Ratios'!$D$7/('AR5 Gear Ratios'!$B$12/24) -> 0
A14: 11 | B14: 1100 | C14: =B14/60 -> 18.333333 | D14: =C14*2*3.14 -> 115.13333 | E14: =(B14/$B$63)*$AG$2 -> 50.416667 | F14: =E14*550 -> 27729.167 | G14: =E14*745.7 -> 37595.708 | H14: =F14/D14 -> 240.84395 | I14: =SQRT((G14*2)/'Acceleration Inputs'!$C$8) -> 9.1040375 | J14: =I14*2.236 -> 20.356628 | K14: =AVERAGE($J$4:J14) -> 14.3874 | L14: =(60*B14/'AR5 Gear Ratios'!$D$2)*(('AR5 Gear Ratios'!$B$12*3.14)/63360) -> 6.14241 | M14: =0.5*0.00238*(L14*1.46)^2*$M$1*$P$1 -> 0.82305476 | N14: =$H14*'AR5 Gear Ratios'!$D$2/('AR5 Gear Ratios'!$B$12/24) -> 3077.9857 | O14: =(60*B14/'AR5 Gear Ratios'!$D$3)*(('AR5 Gear Ratios'!$B$12*3.14)/63360) -> 10.192052 | P14: =0.5*0.00238*(O14*1.46)^2*$M$1*$P$1 -> 2.2660756 | Q14: =$H14*'AR5 Gear Ratios'!$D$3/('AR5 Gear Ratios'!$B$12/24) -> 1854.9994 | R14: =(60*B14/'AR5 Gear Ratios'!$D$4)*(('AR5 Gear Ratios'!$B$12*3.14)/63360) -> 16.813166 | S14: =0.5*0.00238*(R14*1.46)^2*$M$1*$P$1 -> 6.1666618 | T14: =$H14*'AR5 Gear Ratios'!$D$4/('AR5 Gear Ratios'!$B$12/24) -> 1124.4908 | U14: =(60*B14/'AR5 Gear Ratios'!$D$5)*(('AR5 Gear Ratios'!$B$12*3.14)/63360) -> 23.034038 | V14: =0.5*0.00238*(U14*1.46)^2*$M$1*$P$1 -> 11.574208 | W14: =$H14*'AR5 Gear Ratios'!$D$5/('AR5 Gear Ratios'!$B$12/24) -> 820.79618 | X14: =(60*B14/'AR5 Gear Ratios'!$D$6)*(('AR5 Gear Ratios'!$B$12*3.14)/63360) -> 31.553476 | Y14: =0.5*0.00238*(X14*1.46)^2*$M$1*$P$1 -> 21.719286 | Z14: =$H14*'AR5 Gear Ratios'!$D$6/('AR5 Gear Ratios'!$B$12/24) -> 599.18121 | AA14: =(60*B14/'AR5 Gear Ratios'!$D$7)*(('AR5 Gear Ratios'!$B$12*3.14)/63360) -> #DIV/0! | AB14: =0.5*0.00238*(AA14*1.46)^2*$M$1*$P$1 -> #DIV/0! | AC14: =$H14*'AR5 Gear Ratios'!$D$7/('AR5 Gear Ratios'!$B$12/24) -> 0
A15: 12 | B15: 1200 | C15: =B15/60 -> 20 | D15: =C15*2*3.14 -> 125.6 | E15: =(B15/$B$63)*$AG$2 -> 55 | F15: =E15*550 -> 30250 | G15: =E15*745.7 -> 41013.5 | H15: =F15/D15 -> 240.84395 | I15: =SQRT((G15*2)/'Acceleration Inputs'!$C$8) -> 9.508857 | J15: =I15*2.236 -> 21.261804 | K15: =AVERAGE($J$4:J15) -> 14.960267 | L15: =(60*B15/'AR5 Gear Ratios'!$D$2)*(('AR5 Gear Ratios'!$B$12*3.14)/63360) -> 6.7008109 | M15: =0.5*0.00238*(L15*1.46)^2*$M$1*$P$1 -> 0.97950318 | N15: =$H15*'AR5 Gear Ratios'!$D$2/('AR5 Gear Ratios'!$B$12/24) -> 3077.9857 | O15: =(60*B15/'AR5 Gear Ratios'!$D$3)*(('AR5 Gear Ratios'!$B$12*3.14)/63360) -> 11.118602 | P15: =0.5*0.00238*(O15*1.46)^2*$M$1*$P$1 -> 2.6968172 | Q15: =$H15*'AR5 Gear Ratios'!$D$3/('AR5 Gear Ratios'!$B$12/24) -> 1854.9994 | R15: =(60*B15/'AR5 Gear Ratios'!$D$4)*(('AR5 Gear Ratios'!$B$12*3.14)/63360) -> 18.341636 | S15: =0.5*0.00238*(R15*1.46)^2*$M$1*$P$1 -> 7.3388372 | T15: =$H15*'AR5 Gear Ratios'!$D$4/('AR5 Gear Ratios'!$B$12/24) -> 1124.4908 | U15: =(60*B15/'AR5 Gear Ratios'!$D$5)*(('AR5 Gear Ratios'!$B$12*3.14)/63360) -> 25.128041 | V15: =0.5*0.00238*(U15*1.46)^2*$M$1*$P$1 -> 13.774264 | W15: =$H15*'AR5 Gear Ratios'!$D$5/('AR5 Gear Ratios'!$B$12/24) -> 820.79618 | X15: =(60*B15/'AR5 Gear Ratios'!$D$6)*(('AR5 Gear Ratios'!$B$12*3.14)/63360) -> 34.421974 | Y15: =0.5*0.00238*(X15*1.46)^2*$M$1*$P$1 -> 25.847745 | Z15: =$H15*'AR5 Gear Ratios'!$D$6/('AR5 Gear Ratios'!$B$12/24) -> 599.18121 | AA15: =(60*B15/'AR5 Gear Ratios'!$D$7)*(('AR5 Gear Ratios'!$B$12*3.14)/63360) -> #DIV/0! | AB15: =0.5*0.00238*(AA15*1.46)^2*$M$1*$P$1 -> #DIV/0! | AC15: =$H15*'AR5 Gear Ratios'!$D$7/('AR5 Gear Ratios'!$B$12/24) -> 0
... A63: 60 | B63: 6000 | C63: =B63/60 -> 100 | D63: =C63*2*3.14 -> 628 | E63: =(B63/$B$63)*$AG$2 -> 275 | F63: =E63*550 -> 151250 | G63: =E63*745.7 -> 205067.5 | H63: =F63/D63 -> 240.84395 | I63: =SQRT((G63*2)/'Acceleration Inputs'!$C$8) -> 21.262451 | J63: =I63*2.236 -> 47.54284 | K63: =AVERAGE($J$4:J63) -> 32.070701 | L63: =(60*B63/'AR5 Gear Ratios'!$D$2)*(('AR5 Gear Ratios'!$B$12*3.14)/63360) -> 33.504055 | M63: =0.5*0.00238*(L63*1.46)^2*$M$1*$P$1 -> 24.48758 | N63: =$H63*'AR5 Gear Ratios'!$D$2/('AR5 Gear Ratios'!$B$12/24) -> 3077.9857 | O63: =(60*B63/'AR5 Gear Ratios'!$D$3)*(('AR5 Gear Ratios'!$B$12*3.14)/63360) -> 55.593011 | P63: =0.5*0.00238*(O63*1.46)^2*$M$1*$P$1 -> 67.42043 | Q63: =$H63*'AR5 Gear Ratios'!$D$3/('AR5 Gear Ratios'!$B$12/24) -> 1854.9994 | R63: =(60*B63/'AR5 Gear Ratios'!$D$4)*(('AR5 Gear Ratios'!$B$12*3.14)/63360) -> 91.708179 | S63: =0.5*0.00238*(R63*1.46)^2*$M$1*$P$1 -> 183.47093 | T63: =$H63*'AR5 Gear Ratios'!$D$4/('AR5 Gear Ratios'!$B$12/24) -> 1124.4908 | U63: =(60*B63/'AR5 Gear Ratios'!$D$5)*(('AR5 Gear Ratios'!$B$12*3.14)/63360) -> 125.6402 | V63: =0.5*0.00238*(U63*1.46)^2*$M$1*$P$1 -> 344.35659 | W63: =$H63*'AR5 Gear Ratios'!$D$5/('AR5 Gear Ratios'!$B$12/24) -> 820.79618 | X63: =(60*B63/'AR5 Gear Ratios'!$D$6)*(('AR5 Gear Ratios'!$B$12*3.14)/63360) -> 172.10987 | Y63: =0.5*0.00238*(X63*1.46)^2*$M$1*$P$1 -> 646.19363 | Z63: =$H63*'AR5 Gear Ratios'!$D$6/('AR5 Gear Ratios'!$B$12/24) -> 599.18121 | AA63: =(60*B63/'AR5 Gear Ratios'!$D$7)*(('AR5 Gear Ratios'!$B$12*3.14)/63360) -> #DIV/0! | AB63: =0.5*0.00238*(AA63*1.46)^2*$M$1*$P$1 -> #DIV/0! | AC63: =$H63*'AR5 Gear Ratios'!$D$7/('AR5 Gear Ratios'!$B$12/24) -> 0
A64: 61 | B64: 6100 | C64: =B64/60 -> 101.66667 | D64: =C64*2*3.14 -> 638.46667 | E64: =$E$63 -> 275 | F64: =E64*550 -> 151250 | G64: =E64*745.7 -> 205067.5 | H64: =F64/D64 -> 236.89569 | I64: =SQRT((G64*2)/'Acceleration Inputs'!$C$8) -> 21.262451 | J64: =I64*2.236 -> 47.54284 | K64: =AVERAGE($J$4:J64) -> 32.324343 | L64: =(60*B64/'AR5 Gear Ratios'!$D$2)*(('AR5 Gear Ratios'!$B$12*3.14)/63360) -> 34.062456 | M64: =0.5*0.00238*(L64*1.46)^2*$M$1*$P$1 -> 25.310634 | N64: =$H64*'AR5 Gear Ratios'!$D$2/('AR5 Gear Ratios'!$B$12/24) -> 3027.5269 | O64: =(60*B64/'AR5 Gear Ratios'!$D$3)*(('AR5 Gear Ratios'!$B$12*3.14)/63360) -> 56.519561 | P64: =0.5*0.00238*(O64*1.46)^2*$M$1*$P$1 -> 69.686505 | Q64: =$H64*'AR5 Gear Ratios'!$D$3/('AR5 Gear Ratios'!$B$12/24) -> 1824.5895 | R64: =(60*B64/'AR5 Gear Ratios'!$D$4)*(('AR5 Gear Ratios'!$B$12*3.14)/63360) -> 93.236648 | S64: =0.5*0.00238*(R64*1.46)^2*$M$1*$P$1 -> 189.63759 | T64: =$H64*'AR5 Gear Ratios'!$D$4/('AR5 Gear Ratios'!$B$12/24) -> 1106.0565 | U64: =(60*B64/'AR5 Gear Ratios'!$D$5)*(('AR5 Gear Ratios'!$B$12*3.14)/63360) -> 127.73421 | V64: =0.5*0.00238*(U64*1.46)^2*$M$1*$P$1 -> 355.9308 | W64: =$H64*'AR5 Gear Ratios'!$D$5/('AR5 Gear Ratios'!$B$12/24) -> 807.3405 | X64: =(60*B64/'AR5 Gear Ratios'!$D$6)*(('AR5 Gear Ratios'!$B$12*3.14)/63360) -> 174.97837 | Y64: =0.5*0.00238*(X64*1.46)^2*$M$1*$P$1 -> 667.91292 | Z64: =$H64*'AR5 Gear Ratios'!$D$6/('AR5 Gear Ratios'!$B$12/24) -> 589.35857 | AA64: =(60*B64/'AR5 Gear Ratios'!$D$7)*(('AR5 Gear Ratios'!$B$12*3.14)/63360) -> #DIV/0! | AB64: =0.5*0.00238*(AA64*1.46)^2*$M$1*$P$1 -> #DIV/0! | AC64: =$H64*'AR5 Gear Ratios'!$D$7/('AR5 Gear Ratios'!$B$12/24) -> 0
A65: 62 | B65: 6200 | C65: =B65/60 -> 103.33333 | D65: =C65*2*3.14 -> 648.93333 | E65: =$E$63 -> 275 | F65: =E65*550 -> 151250 | G65: =E65*745.7 -> 205067.5 | H65: =F65/D65 -> 233.07479 | I65: =SQRT((G65*2)/'Acceleration Inputs'!$C$8) -> 21.262451 | J65: =I65*2.236 -> 47.54284 | K65: =AVERAGE($J$4:J65) -> 32.569802 | L65: =(60*B65/'AR5 Gear Ratios'!$D$2)*(('AR5 Gear Ratios'!$B$12*3.14)/63360) -> 34.620856 | M65: =0.5*0.00238*(L65*1.46)^2*$M$1*$P$1 -> 26.147293 | N65: =$H65*'AR5 Gear Ratios'!$D$2/('AR5 Gear Ratios'!$B$12/24) -> 2978.6958 | O65: =(60*B65/'AR5 Gear Ratios'!$D$3)*(('AR5 Gear Ratios'!$B$12*3.14)/63360) -> 57.446111 | P65: =0.5*0.00238*(O65*1.46)^2*$M$1*$P$1 -> 71.990037 | Q65: =$H65*'AR5 Gear Ratios'!$D$3/('AR5 Gear Ratios'!$B$12/24) -> 1795.1607 | R65: =(60*B65/'AR5 Gear Ratios'!$D$4)*(('AR5 Gear Ratios'!$B$12*3.14)/63360) -> 94.765118 | S65: =0.5*0.00238*(R65*1.46)^2*$M$1*$P$1 -> 195.90618 | T65: =$H65*'AR5 Gear Ratios'!$D$4/('AR5 Gear Ratios'!$B$12/24) -> 1088.2169 | U65: =(60*B65/'AR5 Gear Ratios'!$D$5)*(('AR5 Gear Ratios'!$B$12*3.14)/63360) -> 129.82821 | V65: =0.5*0.00238*(U65*1.46)^2*$M$1*$P$1 -> 367.69631 | W65: =$H65*'AR5 Gear Ratios'!$D$5/('AR5 Gear Ratios'!$B$12/24) -> 794.31888 | X65: =(60*B65/'AR5 Gear Ratios'!$D$6)*(('AR5 Gear Ratios'!$B$12*3.14)/63360) -> 177.84687 | Y65: =0.5*0.00238*(X65*1.46)^2*$M$1*$P$1 -> 689.9912 | Z65: =$H65*'AR5 Gear Ratios'!$D$6/('AR5 Gear Ratios'!$B$12/24) -> 579.85278 | AA65: =(60*B65/'AR5 Gear Ratios'!$D$7)*(('AR5 Gear Ratios'!$B$12*3.14)/63360) -> #DIV/0! | AB65: =0.5*0.00238*(AA65*1.46)^2*$M$1*$P$1 -> #DIV/0! | AC65: =$H65*'AR5 Gear Ratios'!$D$7/('AR5 Gear Ratios'!$B$12/24) -> 0
A66: 63 | B66: 6300 | C66: =B66/60 -> 105 | D66: =C66*2*3.14 -> 659.4 | E66: =$E$63 -> 275 | F66: =E66*550 -> 151250 | G66: =E66*745.7 -> 205067.5 | H66: =F66/D66 -> 229.37519 | I66: =SQRT((G66*2)/'Acceleration Inputs'!$C$8) -> 21.262451 | J66: =I66*2.236 -> 47.54284 | K66: =AVERAGE($J$4:J66) -> 32.80747 | L66: =(60*B66/'AR5 Gear Ratios'!$D$2)*(('AR5 Gear Ratios'!$B$12*3.14)/63360) -> 35.179257 | M66: =0.5*0.00238*(L66*1.46)^2*$M$1*$P$1 -> 26.997556 | N66: =$H66*'AR5 Gear Ratios'!$D$2/('AR5 Gear Ratios'!$B$12/24) -> 2931.4149 | O66: =(60*B66/'AR5 Gear Ratios'!$D$3)*(('AR5 Gear Ratios'!$B$12*3.14)/63360) -> 58.372662 | P66: =0.5*0.00238*(O66*1.46)^2*$M$1*$P$1 -> 74.331024 | Q66: =$H66*'AR5 Gear Ratios'!$D$3/('AR5 Gear Ratios'!$B$12/24) -> 1766.6661 | R66: =(60*B66/'AR5 Gear Ratios'!$D$4)*(('AR5 Gear Ratios'!$B$12*3.14)/63360) -> 96.293588 | S66: =0.5*0.00238*(R66*1.46)^2*$M$1*$P$1 -> 202.2767 | T66: =$H66*'AR5 Gear Ratios'!$D$4/('AR5 Gear Ratios'!$B$12/24) -> 1070.9436 | U66: =(60*B66/'AR5 Gear Ratios'!$D$5)*(('AR5 Gear Ratios'!$B$12*3.14)/63360) -> 131.92222 | V66: =0.5*0.00238*(U66*1.46)^2*$M$1*$P$1 -> 379.65314 | W66: =$H66*'AR5 Gear Ratios'!$D$5/('AR5 Gear Ratios'!$B$12/24) -> 781.71065 | X66: =(60*B66/'AR5 Gear Ratios'!$D$6)*(('AR5 Gear Ratios'!$B$12*3.14)/63360) -> 180.71536 | Y66: =0.5*0.00238*(X66*1.46)^2*$M$1*$P$1 -> 712.42848 | Z66: =$H66*'AR5 Gear Ratios'!$D$6/('AR5 Gear Ratios'!$B$12/24) -> 570.64877 | AA66: =(60*B66/'AR5 Gear Ratios'!$D$7)*(('AR5 Gear Ratios'!$B$12*3.14)/63360) -> #DIV/0! | AB66: =0.5*0.00238*(AA66*1.46)^2*$M$1*$P$1 -> #DIV/0! | AC66: =$H66*'AR5 Gear Ratios'!$D$7/('AR5 Gear Ratios'!$B$12/24) -> 0
J69: Average: | K69: =AVERAGE(K4:K66) -> 22.514549 | L69: mph/s
K71: Time Elapsed: | L71: =L66/$K$69 -> 1.5625122 | M71: s | O71: =O66/$K$69 -> 2.5926641 | P71: s
K72: Shift Time: | L72: 0.5 | M72: s
K74: Total 0-60 time: | L74: =L71+O71+L72 -> 4.6551763 | O74: seconds
K75: This value does not account for aero drag
