Workbook

Sheet Levers
A1: Concepts for Vehicle Improvement (for study):
A2: aerodynamic instability for better hovering stability--Including eliminating roll/rudder-coupling
A3: Computer-augmented stability in forward flight to fix the problem created by the above
A4: Possible Solar-augmented power system --- Need to do the trade study against having more batteries
A5: Don't have exposed landing gear. Less Drag
A6: Gotta Streamline the the vtol motor mounts, make the pivot system lightweight
A7: Swappable Hybrid-Electric Generator
A8: Long-range communications and telemetry
A9: Increase the aircraft wing-loading for higher cruise speed
A10: Current concept or Flying Wing? → WHAT ELSE?
A13: Things to Improve or Implemet:
A14: Better aerodynamic models for various shapes
... A17: Look into improving the Solar Panel Model. What kinds of panels are available, and what really is the realistic power performance?

Sheet Aircraft W+B
B2: Payload
C3: Mass (kg) | D3: X-axis Position
B4: Other Payload | C4: 4.55 | D4: kg | E4: ?????????????? | F4: =C4*2.2 -> 10.01 | G4: lbs
B5: Receiver | C5: 0.004 | E5: Satellite Receiver
B6: Pixhawk Weight | C6: 0.06 | E6: Approximate, probably under-estimate
B7: GPS Antenna | C7: 0.03 | E7: Doesn't inlclude any wire extensions that may be needed
B8: Cell Hardware | C8: 0
B9: Glow-stick Dropper | C9: 0.05
B10: individual solar panel | C10: 0.011 | E10: Approximation
B11: Solar power regulation hardware | C11: 0.2 | E11: Just the device, not including wires
B12: Total solar weight | C12: =C10*'Systems Param+Perf'!C64+C11 -> 0.552 | E12: seems optimistic. Does not include wire.
B13: camera 1 | C13: 0.06
B14: camera 2 | C14: 0
B15: Camera Mounting Hardware | C15: 0.05
B16: Cameras and hardware total | C16: =C13+C14 -> 0.06
B19: Aircraft | I19: Torque Calculation of Motor Pivot
C20: Mass (kg) | D20: X-axis Position | I20: Validation that moving pivot axis beneath motor is practical
B21: Fuselage Structure weight | C21: 0.4746 | E21: Measured with aft incomplete | I21: mass | J21: 0.3 | K21: kg
B22: Wing center Structure weight | C22: 0.316 | E22: Update this please | I22: force | J22: =J21*9.81 -> 2.943 | K22: N
B23: Outer Wing Structure mass (1 side) | C23: 0.285 | E23: Currently measured as .342 | I23: lever | J23: 1.7 | K23: in
B24: Nose Landing Gear | C24: 0
B25: Main Gear | C25: 0 | E25: Update this
B26: Tail Structure mass | C26: 0.15 | E26: Measured v-tail only. No Rudder
B27: Weight per Flight Cont servo | C27: 0.055 | E27: HS-645MG | I27: lever | J27: =J23*0.0254 -> 0.04318 | K27: m
B28: Motor 1 weight (with prop) | C28: 0.29 | I28: Static Torque | J28: =J22*J27 -> 0.12707874 | K28: N*m
B29: Motor 2 weight (with prop) | C29: 0.29
B30: Motor 3 weight (with prop) | C30: 0.3 | I30: Mass Estimation of VTOL arm | K30: assuming cylindrical shape
B31: Motor 4 weight (with prop) | C31: 0.3 | I31: Carbon Fiber Thickness | J31: 0.0004572 | K31: m
B32: Motor mounting hardware | I32: diameter | J32: 0.03 | K32: m
B33: ESC 1 | C33: 0.089 | I33: length | J33: 0.8 | K33: m
B34: ESC 2 | C34: 0.089 | I34: Volume: | J34: =(PI()*(J32/2)^2)*J33 -> 0.00056548668 | K34: m^3
B35: ESC 3 | C35: 0.089 | I35: Foam Mass | J35: =J34*45 -> 0.0254469 | K35: kg
B36: ESC 4 | C36: 0.089 | I36: Carbon Fiber Vol | J36: =PI()*J32*J31*J33 -> 3.4472068e-05 | K36: m^3
B37: Weight of VTOL Motor Mountings | C37: 0.5 | E37: 0.324 est on inventor, w/o foam. Wood arms were .322, composite estimate is ~.250 per side (including servos and pivot mounts) as of 4/8/2020. Mass of right composite arm (not including anything else) is ~146 | I37: Carbon Fiber Density | J37: 1700 | K37: kg/m^3
B38: Mass of 1 Motor Arm & power sys | C38: =C33+C35+C28+C30+(C37/2) -> 1.018 | I38: Carbon Fiber Mass | J38: =J36*J37 -> 0.058602515 | K38: kg
B39: Engine Mass: | C39: 0 | E39: needs updated | F39: 0.35
B40: Generator Mass: | C40: 0 | E40: needs updated | F40: 0.15
B41: Mounting, Gearing, other hybrid mass | C41: 0 | E41: needs updated | F41: 0.05
B42: Fuel (Gasoline) Density: | C42: 748.9 | D42: kg/m^3 | E42: Does not account for oil density difference
B43: Fuel Volume: | C43: =(C44/C42)*1000 -> 0 | D43: Liters | E43: =C43*0.264 -> 0 | F43: Gal | G43: =C43*1000 -> 0 | H43: cm^3
...

Sheet Systems Param+Perf
A1: Motors in Hover:
B2: Motor 1 Selection: | F2: Front Left
B3: Power = F(thrust) Eq: | D3: W=f(kg)
B4: A: | C4: 35.7 | F4: Thrust = F(power) Eq:
B5: B: | C5: 88.4
B6: C: | C6: -2.67
B7: Max Thrust: | C7: 4.116 | D7: kg
B9: Motor 2 Selection: | F9: Front Right
B10: Power = F(thrust) Eq: | D10: W=f(kg) | F10: Thrust = F(power) Eq:
B11: A: | C11: 35.7
B12: B: | C12: 88.4
B13: C: | C13: -2.67
B14: Max Thrust: | C14: 4.116 | D14: kg
B16: Motor 3 Selection: | F16: Aft Motor
B17: Power = F(thrust) Eq: | D17: W=f(kg) | F17: Thrust = F(power) Eq:
B18: A: | C18: 25.97
B19: B: | C19: 87.83
B20: C: | C20: 12.83
B21: Max Thrust: | C21: 4.55 | D21: kg
B23: Motor 4 Selection: | F23: Aft Motor
B24: Power = F(thrust) Eq: | D24: W=f(kg) | F24: Thrust = F(power) Eq:
B25: A: | C25: 25.97
B26: B: | C26: 87.83
B27: C: | C27: 12.83
B28: Max Thrust: | C28: 4.55 | D28: kg
A30: Motors in Cruise:
B31: Motor 1 Selection: | F31: Front Left
B32: Power = F(thrust) Eq: | D32: W=f(kg)
B33: A: | C33: 35.7 | F33: Thrust = F(power) Eq:
B34: B: | C34: 88.4
B35: C: | C35: -2.67
B36: Max Static Thrust: | C36: 4.116 | D36: kg
B38: Motor 2 Selection: | F38: Front Right
B39: Power = F(thrust) Eq: | D39: W=f(kg) | F39: Thrust = F(power) Eq:
B40: A: | C40: 35.7
B41: B: | C41: 88.4
B42: C: | C42: -2.67
B43: Max Thrust: | C43: 4.116 | D43: kg
A44: Hybrid-Electric System
B45: Energy Density of Gasoline | C45: 45000000 | D45: J/kg
...

Sheet Aerodynamic Perf
A1: Fuselage Drag Coeff.
A2: Fuselage Drag Coeff. | B2: 0 | C2: dim. | D2: update this. What is this with respect to? | J2: 0.01
A4: Wing
A5: Wing Zero Lift Drag Coeff. | B5: 0.016 | C5: dim. | D5: Approximation made using airfoiltools.com and assuming NACA 2414
A6: Approx Max. Lift Coeff. | B6: 1.25 | C6: dim. | D6: Approximation made using airfoiltools.com and assuming NACA 2415 at Re = 200,000
A7: Oswald Efficiency Factor | B7: 0.85 | C7: %
A8: Root Chord | B8: 11 | C8: in | D8: =B8/39.37 -> 0.27940056 | E8: m
A9: Tip Chord | B9: 9.5 | C9: in | D9: =B9/39.37 -> 0.24130048 | E9: m
A10: Aspect Ratio | B10: =B11/(B12) -> 12.292683 | C10: dim.
A11: Wingspan: | B11: 126 | C11: in | D11: =B11/39.37 -> 3.2004064 | E11: m
A12: Mean Chord: | B12: =AVERAGE(B8:B9) -> 10.25 | C12: dim.
A13: Wing Area: | B13: =B11*B12 -> 1291.5 | C13: in^2 | D13: =B13/1550 -> 0.83322581 | E13: m^2
A14: Wing Area: | B14: =B13/1550 -> 0.83322581 | C14: m^2
A16: Landing Gear Effects
A17: Landing Gear Cd | B17: 0 | C17: dim. | D17: With respect to wheel frontal area: | F17: 1.01
A18: Number of Wheels | B18: 0
A19: Wheel Diameter | B19: 3 | C19: in
A20: Wheel width | B20: 1 | C20: in | H20: fixed drag: | I20: =('Aerodynamic Perf'!$B$21+'Aerodynamic Perf'!$B$29+'Aerodynamic Perf'!$B$2+'Aerodynamic Perf'!$B$28+'Aerodynamic Perf'!$B$5) -> 0.016
A21: Drag Coefficient w/respect to wing | B21: =B18*(B17*((B19*B20)/(B13))) -> 0 | C21: dim.
A23: Atmosphere
A24: Air Density | B24: 1.225 | C24: kg/m³
A25: Air Density | B25: =B24*0.00194 -> 0.0023765 | C25: slug/ft^3
A27: VTOL Mods
A28: Cruise Cd from Extra motors | C28: dim. | J28: 0.01
A33: Lift Coefficient | B33: 1.5
A34: Coefficient of Drag | B34: =(B2+B5)+B33^2/(PI()*B7*B10) -> 0.08454362
A43: Lift | B43: 54 | C43: N
A44: Drag | B44: 0.089 | C44: N | E44: 1/2roev^2(Cl)(A)
A45: reference area | B45: =3.2*0.2921 -> 0.93472 | C45: m^2
A46: velocity | B46: 11.5
A47: Lift Coefficient | B47: =(2*B43)/($B$24*$B$45*(B45^2)) -> 107.95507
A48: Drag Coefficient | B48: =(2*B44)/($B$24*$B$45*(B46^2)) -> 0.0011754569 | C48: dim.

Sheet Performance Calculator
A1: 1-Way Cruise Performance
A2: Cruise Endurance | B2: =MAX('Cruise Trends'!C4:C83) -> 238.37619 | C2: min | D2: =B2/60 -> 3.9729365 | E2: hours | G2: =126-23.5 -> 102.5 | H2: =G2/2 -> 51.25
A3: Cruise Range | B3: =MAX('Cruise Trends'!D4:D83) -> 276.68216 | C3: km | D3: =B3*0.621 -> 171.81962 | E3: miles
A4: Theoretical Stall Speed | B4: =SQRT((2*'Aircraft W+B'!C60*9.81)/('Aerodynamic Perf'!B24*'Aerodynamic Perf'!B6*'Aerodynamic Perf'!B14)) -> 13.238171 | C4: m/s | D4: =B4*2.237 -> 29.613788 | E4: mph
A5: Stall Margin | C5: m/s | D5: This currently means nothing
A6: 2-Motor Max Thrust/Weight | B6: =(2*'Systems Param+Perf'!C7)/'Aircraft W+B'!C60 -> 0.72233654 | C6: dim.
A7: Wing Loading | B7: ='Aircraft W+B'!C60/'Aerodynamic Perf'!B14 -> 13.677385 | C7: kg/m^3 | D7: =B7*3.27 -> 44.725048 | E7: oz/ft^2
A24: Hover Performance
A25: Hover Power Draw Per Forward Motor | B25: =('Systems Param+Perf'!$C$4*(('Aircraft W+B'!C60/4)^2)+'Systems Param+Perf'!$C$5*(('Aircraft W+B'!C60/4))+'Systems Param+Perf'!$C$6) -> 538.97693 | C25: W | D25: per motor
A26: Hover Power Draw Per Aft Motor | B26: =('Systems Param+Perf'!$C$18*(('Aircraft W+B'!C60/4)^2)+'Systems Param+Perf'!$C$19*(('Aircraft W+B'!C60/4))+'Systems Param+Perf'!$C$20) -> 473.87163 | C26: W
A27: Hover Motor Power Draw: | B27: =(2*B25)+(2*B26) -> 2025.6971 | C27: W | D27: TOTAL POWER DRAW DURING HOVER! Fully loaded, a Muse-size aircraft would draw over 1600W.
A28: Hover Motor Approx Current Draw: | B28: =B27/'Systems Param+Perf'!C58 -> 91.247618 | C28: amps
A29: Hover Time | B29: =(((('Systems Param+Perf'!$C$57/1000)*'Systems Param+Perf'!$C$60)/(((2*(B25+B26)-'Systems Param+Perf'!$C$66+'Systems Param+Perf'!$C$76+'Systems Param+Perf'!$C$83+'Systems Param+Perf'!$C$86)/'Systems Param+Perf'!$C$58)))*60) -> 12.278633 | C29: min | F29: =B25*2+(B26*2) -> 2025.6971 | G29: watts
A30: Aircraft Thrust to weight: | B30: =(4*'Systems Param+Perf'!C7)/'Aircraft W+B'!C60 -> 1.4446731 | C30: dim. | F30: =F29/22.2 -> 91.247618 | G30: amps
A33: Vertical Takeoff/Landing then Cruise Performance | D33: THIS NEEDS UPDATING TO WORK WITH THE HYBRID-ELECTRIC SYSTEM
A34: Hover Power Draw Per Motor | B34: =B25 -> 538.97693 | C34: W
A35: Hover Power Draw Per Aft Motor | B35: =('Systems Param+Perf'!$C$18*(('Aircraft W+B'!C60/4)^2)+'Systems Param+Perf'!$C$19*(('Aircraft W+B'!C60/4))+'Systems Param+Perf'!$C$20) -> 473.87163 | C35: W
A36: Total Hover Time | B36: 2 | C36: min
A37: Energy Remaining after Hover | B37: =(('Systems Param+Perf'!C57/1000)*'Systems Param+Perf'!C58*'Systems Param+Perf'!C60)*3600-(B27*(B36*60)) -> 1251420.3 | C37: W*s (J)
A38: Remaining Cruise Endurance | B38: =MAX('Post-Hover Cruise Trends'!C4:C83) -> 199.60389 | C38: mins
A39: Remaining Cruise Range | B39: =MAX('Post-Hover Cruise Trends'!D4:D80) -> 231.67933 | C39: km

Sheet Requirements
B2: 1-Way Cruise Requirements
B3: Cruise Endurance | C3: 59 | D3: min
B4: Cruise Range | C4: 1 | D4: km
B5: Stall Margin | C5: 3 | D5: m/s
B6: Min Airspeed | C6: 10 | D6: m/s
B9: Hover Mission Requirements
B10: Hover Time | C10: 15 | D10: min
B12: H-takeoff to hover Mission Requirements
B13: Hover Time | C13: 8 | D13: min
B14: Trip time (One-Way) | C14: 59 | D14: min
B15: Mission Radius | C15: 1 | D15: km
B17: V-takeoff/Landing to hover Mission Requirements
B18: Takeoff Time | C18: 1 | D18: min
B19: Destination Hover Time | C19: 10 | D19: min
B20: Trip time (One-Way) | C20: 59 | D20: min
B21: Mission Radius | C21: 1 | D21: km
B22: Landing Time | C22: 1.5 | D22: min

Sheet Cruise Trends
A1: Airspeed (m/s) | C1: Flight Time (min) | D1: Range (km) | F1: Drag (N) | G1: Drag (kg) | H1: Drag Coefficient | I1: Lift Coefficient | J1: Lift (N) | K1: L/D | L1: Approx Current per motor(A) | M1: Power Draw Per Motor
A2: ='[1]Irrelevant Example'!K12 -> #REF! | B2: Cruise Airspeed
A3: ='[1]Irrelevant Example'!K9 -> #REF! | B3: Min Airspeed
A4: 4 | C4: =((((('Aircraft W+B'!$C$44*'Systems Param+Perf'!$C$45*'Systems Param+Perf'!$C$46*'Systems Param+Perf'!$C$47)/(3600*'Systems Param+Perf'!$C$58)+('Systems Param+Perf'!$C$57/1000)*'Systems Param+Perf'!$C$60)/((((2)*M4-'Systems Param+Perf'!$C$66+'Systems Param+Perf'!$C$76+'Systems Param+Perf'!$C$83+'Systems Param+Perf'!$C$86)/'Systems Param+Perf'!$C$58)))*60)) -> 10.149032 | D4: =C4*60*A4/1000 -> 2.4357676 | F4: =0.5*('Aerodynamic Perf'!$B$24*A4^2*H4*'Aerodynamic Perf'!$B$14) -> 46.66562 | G4: =F4/9.81 -> 4.756944 | H4: =('Aerodynamic Perf'!$B$21+'Aerodynamic Perf'!$B$29+'Aerodynamic Perf'!$B$2+'Aerodynamic Perf'!$B$28+'Aerodynamic Perf'!$B$5)+I4^2/(PI()*'Aerodynamic Perf'!$B$7*'Aerodynamic Perf'!$B$10) -> 5.714895 | I4: =('Aircraft W+B'!$C$61)/(0.5*'Aerodynamic Perf'!$B$24*A4^2*'Aerodynamic Perf'!$B$14) -> 13.677385 | J4: =I4*0.5*'Aerodynamic Perf'!$B$24*A4^2*'Aerodynamic Perf'!$B$14 -> 111.68423 | K4: =I4/H4 -> 2.3932872 | L4: =M4/'Systems Param+Perf'!$C$58 -> 55.210895 | M4: =('Systems Param+Perf'!$C$4*((G4)^2)+'Systems Param+Perf'!$C$5*((G4))+'Systems Param+Perf'!$C$6) -> 1225.6819
A5: =A4+0.5 -> 4.5 | C5: =((((('Aircraft W+B'!$C$44*'Systems Param+Perf'!$C$45*'Systems Param+Perf'!$C$46*'Systems Param+Perf'!$C$47)/(3600*'Systems Param+Perf'!$C$58)+('Systems Param+Perf'!$C$57/1000)*'Systems Param+Perf'!$C$60)/((((2)*M5-'Systems Param+Perf'!$C$66+'Systems Param+Perf'!$C$76+'Systems Param+Perf'!$C$83+'Systems Param+Perf'!$C$86)/'Systems Param+Perf'!$C$58)))*60)) -> 14.868417 | D5: =C5*60*A5/1000 -> 4.0144725 | F5: =0.5*('Aerodynamic Perf'!$B$24*A5^2*H5*'Aerodynamic Perf'!$B$14) -> 36.933725 | G5: =F5/9.81 -> 3.7649057 | H5: =('Aerodynamic Perf'!$B$21+'Aerodynamic Perf'!$B$29+'Aerodynamic Perf'!$B$2+'Aerodynamic Perf'!$B$28+'Aerodynamic Perf'!$B$5)+I5^2/(PI()*'Aerodynamic Perf'!$B$7*'Aerodynamic Perf'!$B$10) -> 3.5737921 | I5: =('Aircraft W+B'!$C$61)/(0.5*'Aerodynamic Perf'!$B$24*A5^2*'Aerodynamic Perf'!$B$14) -> 10.806823 | J5: =I5*0.5*'Aerodynamic Perf'!$B$24*A5^2*'Aerodynamic Perf'!$B$14 -> 111.68423 | K5: =I5/H5 -> 3.0239091 | L5: =M5/'Systems Param+Perf'!$C$58 -> 37.66567 | M5: =('Systems Param+Perf'!$C$4*((G5)^2)+'Systems Param+Perf'!$C$5*((G5))+'Systems Param+Perf'!$C$6) -> 836.17786
A6: =A5+0.5 -> 5 | C6: =((((('Aircraft W+B'!$C$44*'Systems Param+Perf'!$C$45*'Systems Param+Perf'!$C$46*'Systems Param+Perf'!$C$47)/(3600*'Systems Param+Perf'!$C$58)+('Systems Param+Perf'!$C$57/1000)*'Systems Param+Perf'!$C$60)/((((2)*M6-'Systems Param+Perf'!$C$66+'Systems Param+Perf'!$C$76+'Systems Param+Perf'!$C$83+'Systems Param+Perf'!$C$86)/'Systems Param+Perf'!$C$58)))*60)) -> 20.668765 | D6: =C6*60*A6/1000 -> 6.2006296 | F6: =0.5*('Aerodynamic Perf'!$B$24*A6^2*H6*'Aerodynamic Perf'!$B$14) -> 29.986521 | G6: =F6/9.81 -> 3.05673 | H6: =('Aerodynamic Perf'!$B$21+'Aerodynamic Perf'!$B$29+'Aerodynamic Perf'!$B$2+'Aerodynamic Perf'!$B$28+'Aerodynamic Perf'!$B$5)+I6^2/(PI()*'Aerodynamic Perf'!$B$7*'Aerodynamic Perf'!$B$10) -> 2.3502674 | I6: =('Aircraft W+B'!$C$61)/(0.5*'Aerodynamic Perf'!$B$24*A6^2*'Aerodynamic Perf'!$B$14) -> 8.7535263 | J6: =I6*0.5*'Aerodynamic Perf'!$B$24*A6^2*'Aerodynamic Perf'!$B$14 -> 111.68423 | K6: =I6/H6 -> 3.724481 | L6: =M6/'Systems Param+Perf'!$C$58 -> 27.07709 | M6: =('Systems Param+Perf'!$C$4*((G6)^2)+'Systems Param+Perf'!$C$5*((G6))+'Systems Param+Perf'!$C$6) -> 601.11139
A7: =A6+0.5 -> 5.5 | C7: =((((('Aircraft W+B'!$C$44*'Systems Param+Perf'!$C$45*'Systems Param+Perf'!$C$46*'Systems Param+Perf'!$C$47)/(3600*'Systems Param+Perf'!$C$58)+('Systems Param+Perf'!$C$57/1000)*'Systems Param+Perf'!$C$60)/((((2)*M7-'Systems Param+Perf'!$C$66+'Systems Param+Perf'!$C$76+'Systems Param+Perf'!$C$83+'Systems Param+Perf'!$C$86)/'Systems Param+Perf'!$C$58)))*60)) -> 27.548908 | D7: =C7*60*A7/1000 -> 9.0911396 | F7: =0.5*('Aerodynamic Perf'!$B$24*A7^2*H7*'Aerodynamic Perf'!$B$14) -> 24.860548 | G7: =F7/9.81 -> 2.5342047 | H7: =('Aerodynamic Perf'!$B$21+'Aerodynamic Perf'!$B$29+'Aerodynamic Perf'!$B$2+'Aerodynamic Perf'!$B$28+'Aerodynamic Perf'!$B$5)+I7^2/(PI()*'Aerodynamic Perf'!$B$7*'Aerodynamic Perf'!$B$10) -> 1.610336 | I7: =('Aircraft W+B'!$C$61)/(0.5*'Aerodynamic Perf'!$B$24*A7^2*'Aerodynamic Perf'!$B$14) -> 7.2343192 | J7: =I7*0.5*'Aerodynamic Perf'!$B$24*A7^2*'Aerodynamic Perf'!$B$14 -> 111.68423 | K7: =I7/H7 -> 4.4924283 | L7: =M7/'Systems Param+Perf'!$C$58 -> 20.298468 | M7: =('Systems Param+Perf'!$C$4*((G7)^2)+'Systems Param+Perf'!$C$5*((G7))+'Systems Param+Perf'!$C$6) -> 450.626
A8: =A7+0.5 -> 6 | C8: =((((('Aircraft W+B'!$C$44*'Systems Param+Perf'!$C$45*'Systems Param+Perf'!$C$46*'Systems Param+Perf'!$C$47)/(3600*'Systems Param+Perf'!$C$58)+('Systems Param+Perf'!$C$57/1000)*'Systems Param+Perf'!$C$60)/((((2)*M8-'Systems Param+Perf'!$C$66+'Systems Param+Perf'!$C$76+'Systems Param+Perf'!$C$83+'Systems Param+Perf'!$C$86)/'Systems Param+Perf'!$C$58)))*60)) -> 35.479602 | D8: =C8*60*A8/1000 -> 12.772657 | F8: =0.5*('Aerodynamic Perf'!$B$24*A8^2*H8*'Aerodynamic Perf'!$B$14) -> 20.976171 | G8: =F8/9.81 -> 2.1382437 | H8: =('Aerodynamic Perf'!$B$21+'Aerodynamic Perf'!$B$29+'Aerodynamic Perf'!$B$2+'Aerodynamic Perf'!$B$28+'Aerodynamic Perf'!$B$5)+I8^2/(PI()*'Aerodynamic Perf'!$B$7*'Aerodynamic Perf'!$B$10) -> 1.1417077 | I8: =('Aircraft W+B'!$C$61)/(0.5*'Aerodynamic Perf'!$B$24*A8^2*'Aerodynamic Perf'!$B$14) -> 6.0788377 | J8: =I8*0.5*'Aerodynamic Perf'!$B$24*A8^2*'Aerodynamic Perf'!$B$14 -> 111.68423 | K8: =I8/H8 -> 5.3243382 | L8: =M8/'Systems Param+Perf'!$C$58 -> 15.746587 | M8: =('Systems Param+Perf'!$C$4*((G8)^2)+'Systems Param+Perf'!$C$5*((G8))+'Systems Param+Perf'!$C$6) -> 349.57423
A9: =A8+0.5 -> 6.5 | C9: =((((('Aircraft W+B'!$C$44*'Systems Param+Perf'!$C$45*'Systems Param+Perf'!$C$46*'Systems Param+Perf'!$C$47)/(3600*'Systems Param+Perf'!$C$58)+('Systems Param+Perf'!$C$57/1000)*'Systems Param+Perf'!$C$60)/((((2)*M9-'Systems Param+Perf'!$C$66+'Systems Param+Perf'!$C$76+'Systems Param+Perf'!$C$83+'Systems Param+Perf'!$C$86)/'Systems Param+Perf'!$C$58)))*60)) -> 44.407618 | D9: =C9*60*A9/1000 -> 17.318971 | F9: =0.5*('Aerodynamic Perf'!$B$24*A9^2*H9*'Aerodynamic Perf'!$B$14) -> 17.967708 | G9: =F9/9.81 -> 1.8315706 | H9: =('Aerodynamic Perf'!$B$21+'Aerodynamic Perf'!$B$29+'Aerodynamic Perf'!$B$2+'Aerodynamic Perf'!$B$28+'Aerodynamic Perf'!$B$5)+I9^2/(PI()*'Aerodynamic Perf'!$B$7*'Aerodynamic Perf'!$B$10) -> 0.8332919 | I9: =('Aircraft W+B'!$C$61)/(0.5*'Aerodynamic Perf'!$B$24*A9^2*'Aerodynamic Perf'!$B$14) -> 5.1796014 | J9: =I9*0.5*'Aerodynamic Perf'!$B$24*A9^2*'Aerodynamic Perf'!$B$14 -> 111.68423 | K9: =I9/H9 -> 6.2158307 | L9: =M9/'Systems Param+Perf'!$C$58 -> 12.567652 | M9: =('Systems Param+Perf'!$C$4*((G9)^2)+'Systems Param+Perf'!$C$5*((G9))+'Systems Param+Perf'!$C$6) -> 279.00188
A10: =A9+0.5 -> 7 | C10: =((((('Aircraft W+B'!$C$44*'Systems Param+Perf'!$C$45*'Systems Param+Perf'!$C$46*'Systems Param+Perf'!$C$47)/(3600*'Systems Param+Perf'!$C$58)+('Systems Param+Perf'!$C$57/1000)*'Systems Param+Perf'!$C$60)/((((2)*M10-'Systems Param+Perf'!$C$66+'Systems Param+Perf'!$C$76+'Systems Param+Perf'!$C$83+'Systems Param+Perf'!$C$86)/'Systems Param+Perf'!$C$58)))*60)) -> 54.258688 | D10: =C10*60*A10/1000 -> 22.788649 | F10: =0.5*('Aerodynamic Perf'!$B$24*A10^2*H10*'Aerodynamic Perf'!$B$14) -> 15.595207 | G10: =F10/9.81 -> 1.5897255 | H10: =('Aerodynamic Perf'!$B$21+'Aerodynamic Perf'!$B$29+'Aerodynamic Perf'!$B$2+'Aerodynamic Perf'!$B$28+'Aerodynamic Perf'!$B$5)+I10^2/(PI()*'Aerodynamic Perf'!$B$7*'Aerodynamic Perf'!$B$10) -> 0.62362895 | I10: =('Aircraft W+B'!$C$61)/(0.5*'Aerodynamic Perf'!$B$24*A10^2*'Aerodynamic Perf'!$B$14) -> 4.4660848 | J10: =I10*0.5*'Aerodynamic Perf'!$B$24*A10^2*'Aerodynamic Perf'!$B$14 -> 111.68423 | K10: =I10/H10 -> 7.1614456 | L10: =M10/'Systems Param+Perf'!$C$58 -> 10.274043 | M10: =('Systems Param+Perf'!$C$4*((G10)^2)+'Systems Param+Perf'!$C$5*((G10))+'Systems Param+Perf'!$C$6) -> 228.08375
A11: =A10+0.5 -> 7.5 | C11: =((((('Aircraft W+B'!$C$44*'Systems Param+Perf'!$C$45*'Systems Param+Perf'!$C$46*'Systems Param+Perf'!$C$47)/(3600*'Systems Param+Perf'!$C$58)+('Systems Param+Perf'!$C$57/1000)*'Systems Param+Perf'!$C$60)/((((2)*M11-'Systems Param+Perf'!$C$66+'Systems Param+Perf'!$C$76+'Systems Param+Perf'!$C$83+'Systems Param+Perf'!$C$86)/'Systems Param+Perf'!$C$58)))*60)) -> 64.939509 | D11: =C11*60*A11/1000 -> 29.222779 | F11: =0.5*('Aerodynamic Perf'!$B$24*A11^2*H11*'Aerodynamic Perf'!$B$14) -> 13.69593 | G11: =F11/9.81 -> 1.3961192 | H11: =('Aerodynamic Perf'!$B$21+'Aerodynamic Perf'!$B$29+'Aerodynamic Perf'!$B$2+'Aerodynamic Perf'!$B$28+'Aerodynamic Perf'!$B$5)+I11^2/(PI()*'Aerodynamic Perf'!$B$7*'Aerodynamic Perf'!$B$10) -> 0.47708985 | I11: =('Aircraft W+B'!$C$61)/(0.5*'Aerodynamic Perf'!$B$24*A11^2*'Aerodynamic Perf'!$B$14) -> 3.8904561 | J11: =I11*0.5*'Aerodynamic Perf'!$B$24*A11^2*'Aerodynamic Perf'!$B$14 -> 111.68423 | K11: =I11/H11 -> 8.1545564 | L11: =M11/'Systems Param+Perf'!$C$58 -> 8.5734934 | M11: =('Systems Param+Perf'!$C$4*((G11)^2)+'Systems Param+Perf'!$C$5*((G11))+'Systems Param+Perf'!$C$6) -> 190.33155
A12: =A11+0.5 -> 8 | C12: =((((('Aircraft W+B'!$C$44*'Systems Param+Perf'!$C$45*'Systems Param+Perf'!$C$46*'Systems Param+Perf'!$C$47)/(3600*'Systems Param+Perf'!$C$58)+('Systems Param+Perf'!$C$57/1000)*'Systems Param+Perf'!$C$60)/((((2)*M12-'Systems Param+Perf'!$C$66+'Systems Param+Perf'!$C$76+'Systems Param+Perf'!$C$83+'Systems Param+Perf'!$C$86)/'Systems Param+Perf'!$C$58)))*60)) -> 76.33916 | D12: =C12*60*A12/1000 -> 36.642797 | F12: =0.5*('Aerodynamic Perf'!$B$24*A12^2*H12*'Aerodynamic Perf'!$B$14) -> 12.156342 | G12: =F12/9.81 -> 1.2391786 | H12: =('Aerodynamic Perf'!$B$21+'Aerodynamic Perf'!$B$29+'Aerodynamic Perf'!$B$2+'Aerodynamic Perf'!$B$28+'Aerodynamic Perf'!$B$5)+I12^2/(PI()*'Aerodynamic Perf'!$B$7*'Aerodynamic Perf'!$B$10) -> 0.37218094 | I12: =('Aircraft W+B'!$C$61)/(0.5*'Aerodynamic Perf'!$B$24*A12^2*'Aerodynamic Perf'!$B$14) -> 3.4193462 | J12: =I12*0.5*'Aerodynamic Perf'!$B$24*A12^2*'Aerodynamic Perf'!$B$14 -> 111.68423 | K12: =I12/H12 -> 9.1873223 | L12: =M12/'Systems Param+Perf'!$C$58 -> 7.2834687 | M12: =('Systems Param+Perf'!$C$4*((G12)^2)+'Systems Param+Perf'!$C$5*((G12))+'Systems Param+Perf'!$C$6) -> 161.693
A13: =A12+0.5 -> 8.5 | C13: =((((('Aircraft W+B'!$C$44*'Systems Param+Perf'!$C$45*'Systems Param+Perf'!$C$46*'Systems Param+Perf'!$C$47)/(3600*'Systems Param+Perf'!$C$58)+('Systems Param+Perf'!$C$57/1000)*'Systems Param+Perf'!$C$60)/((((2)*M13-'Systems Param+Perf'!$C$66+'Systems Param+Perf'!$C$76+'Systems Param+Perf'!$C$83+'Systems Param+Perf'!$C$86)/'Systems Param+Perf'!$C$58)))*60)) -> 88.330333 | D13: =C13*60*A13/1000 -> 45.04847 | F13: =0.5*('Aerodynamic Perf'!$B$24*A13^2*H13*'Aerodynamic Perf'!$B$14) -> 10.895288 | G13: =F13/9.81 -> 1.1106308 | H13: =('Aerodynamic Perf'!$B$21+'Aerodynamic Perf'!$B$29+'Aerodynamic Perf'!$B$2+'Aerodynamic Perf'!$B$28+'Aerodynamic Perf'!$B$5)+I13^2/(PI()*'Aerodynamic Perf'!$B$7*'Aerodynamic Perf'!$B$10) -> 0.29548269 | I13: =('Aircraft W+B'!$C$61)/(0.5*'Aerodynamic Perf'!$B$24*A13^2*'Aerodynamic Perf'!$B$14) -> 3.0289018 | J13: =I13*0.5*'Aerodynamic Perf'!$B$24*A13^2*'Aerodynamic Perf'!$B$14 -> 111.68423 | K13: =I13/H13 -> 10.250691 | L13: =M13/'Systems Param+Perf'!$C$58 -> 6.2858438 | M13: =('Systems Param+Perf'!$C$4*((G13)^2)+'Systems Param+Perf'!$C$5*((G13))+'Systems Param+Perf'!$C$6) -> 139.54573
A14: =A13+0.5 -> 9 | C14: =((((('Aircraft W+B'!$C$44*'Systems Param+Perf'!$C$45*'Systems Param+Perf'!$C$46*'Systems Param+Perf'!$C$47)/(3600*'Systems Param+Perf'!$C$58)+('Systems Param+Perf'!$C$57/1000)*'Systems Param+Perf'!$C$60)/((((2)*M14-'Systems Param+Perf'!$C$66+'Systems Param+Perf'!$C$76+'Systems Param+Perf'!$C$83+'Systems Param+Perf'!$C$86)/'Systems Param+Perf'!$C$58)))*60)) -> 100.77076 | D14: =C14*60*A14/1000 -> 54.416212 | F14: =0.5*('Aerodynamic Perf'!$B$24*A14^2*H14*'Aerodynamic Perf'!$B$14) -> 9.8535076 | G14: =F14/9.81 -> 1.004435 | H14: =('Aerodynamic Perf'!$B$21+'Aerodynamic Perf'!$B$29+'Aerodynamic Perf'!$B$2+'Aerodynamic Perf'!$B$28+'Aerodynamic Perf'!$B$5)+I14^2/(PI()*'Aerodynamic Perf'!$B$7*'Aerodynamic Perf'!$B$10) -> 0.23836201 | I14: =('Aircraft W+B'!$C$61)/(0.5*'Aerodynamic Perf'!$B$24*A14^2*'Aerodynamic Perf'!$B$14) -> 2.7017056 | J14: =I14*0.5*'Aerodynamic Perf'!$B$24*A14^2*'Aerodynamic Perf'!$B$14 -> 111.68423 | K14: =I14/H14 -> 11.334464 | L14: =M14/'Systems Param+Perf'!$C$58 -> 5.5017756 | M14: =('Systems Param+Perf'!$C$4*((G14)^2)+'Systems Param+Perf'!$C$5*((G14))+'Systems Param+Perf'!$C$6) -> 122.13942
A15: =A14+0.5 -> 9.5 | C15: =((((('Aircraft W+B'!$C$44*'Systems Param+Perf'!$C$45*'Systems Param+Perf'!$C$46*'Systems Param+Perf'!$C$47)/(3600*'Systems Param+Perf'!$C$58)+('Systems Param+Perf'!$C$57/1000)*'Systems Param+Perf'!$C$60)/((((2)*M15-'Systems Param+Perf'!$C$66+'Systems Param+Perf'!$C$76+'Systems Param+Perf'!$C$83+'Systems Param+Perf'!$C$86)/'Systems Param+Perf'!$C$58)))*60)) -> 113.50516 | D15: =C15*60*A15/1000 -> 64.697939 | F15: =0.5*('Aerodynamic Perf'!$B$24*A15^2*H15*'Aerodynamic Perf'!$B$14) -> 8.9869136 | G15: =F15/9.81 -> 0.91609721 | H15: =('Aerodynamic Perf'!$B$21+'Aerodynamic Perf'!$B$29+'Aerodynamic Perf'!$B$2+'Aerodynamic Perf'!$B$28+'Aerodynamic Perf'!$B$5)+I15^2/(PI()*'Aerodynamic Perf'!$B$7*'Aerodynamic Perf'!$B$10) -> 0.19511675 | I15: =('Aircraft W+B'!$C$61)/(0.5*'Aerodynamic Perf'!$B$24*A15^2*'Aerodynamic Perf'!$B$14) -> 2.4247995 | J15: =I15*0.5*'Aerodynamic Perf'!$B$24*A15^2*'Aerodynamic Perf'!$B$14 -> 111.68423 | K15: =I15/H15 -> 12.427429 | L15: =M15/'Systems Param+Perf'!$C$58 -> 4.8771915 | M15: =('Systems Param+Perf'!$C$4*((G15)^2)+'Systems Param+Perf'!$C$5*((G15))+'Systems Param+Perf'!$C$6) -> 108.27365
A16: =A15+0.5 -> 10 | C16: =((((('Aircraft W+B'!$C$44*'Systems Param+Perf'!$C$45*'Systems Param+Perf'!$C$46*'Systems Param+Perf'!$C$47)/(3600*'Systems Param+Perf'!$C$58)+('Systems Param+Perf'!$C$57/1000)*'Systems Param+Perf'!$C$60)/((((2)*M16-'Systems Param+Perf'!$C$66+'Systems Param+Perf'!$C$76+'Systems Param+Perf'!$C$83+'Systems Param+Perf'!$C$86)/'Systems Param+Perf'!$C$58)))*60)) -> 126.36781 | D16: =C16*60*A16/1000 -> 75.820685 | F16: =0.5*('Aerodynamic Perf'!$B$24*A16^2*H16*'Aerodynamic Perf'!$B$14) -> 8.2621566 | G16: =F16/9.81 -> 0.84221779 | H16: =('Aerodynamic Perf'!$B$21+'Aerodynamic Perf'!$B$29+'Aerodynamic Perf'!$B$2+'Aerodynamic Perf'!$B$28+'Aerodynamic Perf'!$B$5)+I16^2/(PI()*'Aerodynamic Perf'!$B$7*'Aerodynamic Perf'!$B$10) -> 0.16189171 | I16: =('Aircraft W+B'!$C$61)/(0.5*'Aerodynamic Perf'!$B$24*A16^2*'Aerodynamic Perf'!$B$14) -> 2.1883816 | J16: =I16*0.5*'Aerodynamic Perf'!$B$24*A16^2*'Aerodynamic Perf'!$B$14 -> 111.68423 | K16: =I16/H16 -> 13.517564 | L16: =M16/'Systems Param+Perf'!$C$58 -> 4.3741064 | M16: =('Systems Param+Perf'!$C$4*((G16)^2)+'Systems Param+Perf'!$C$5*((G16))+'Systems Param+Perf'!$C$6) -> 97.105163
... A80: =A79+0.5 -> 42 | C80: =((((('Aircraft W+B'!$C$44*'Systems Param+Perf'!$C$45*'Systems Param+Perf'!$C$46*'Systems Param+Perf'!$C$47)/(3600*'Systems Param+Perf'!$C$58)+('Systems Param+Perf'!$C$57/1000)*'Systems Param+Perf'!$C$60)/((((2)*M80-'Systems Param+Perf'!$C$66+'Systems Param+Perf'!$C$76+'Systems Param+Perf'!$C$83+'Systems Param+Perf'!$C$86)/'Systems Param+Perf'!$C$58)))*60)) -> 58.217275 | D80: =C80*60*A80/1000 -> 146.70753 | F80: =0.5*('Aerodynamic Perf'!$B$24*A80^2*H80*'Aerodynamic Perf'!$B$14) -> 14.826227 | G80: =F80/9.81 -> 1.5113381 | H80: =('Aerodynamic Perf'!$B$21+'Aerodynamic Perf'!$B$29+'Aerodynamic Perf'!$B$2+'Aerodynamic Perf'!$B$28+'Aerodynamic Perf'!$B$5)+I80^2/(PI()*'Aerodynamic Perf'!$B$7*'Aerodynamic Perf'!$B$10) -> 0.01646885 | I80: =('Aircraft W+B'!$C$61)/(0.5*'Aerodynamic Perf'!$B$24*A80^2*'Aerodynamic Perf'!$B$14) -> 0.12405791 | J80: =I80*0.5*'Aerodynamic Perf'!$B$24*A80^2*'Aerodynamic Perf'!$B$14 -> 111.68423 | K80: =I80/H80 -> 7.5328827 | L80: =M80/'Systems Param+Perf'!$C$58 -> 9.5709997 | M80: =('Systems Param+Perf'!$C$4*((G80)^2)+'Systems Param+Perf'!$C$5*((G80))+'Systems Param+Perf'!$C$6) -> 212.47619
A96: Airspeed (m/s) | C96: Power (W)
A97: ='[1]Irrelevant Example'!K8 -> #REF! | B97: Min Power Airspeed
A98: =A2 -> #REF! | B98: Cruise Airspeed
A99: =A4 -> 4 | C99: #REF!
A100: =A5 -> 4.5 | C100: #REF!
A101: =A6 -> 5 | C101: #REF!
A102: =A7 -> 5.5 | C102: #REF!
A103: =A8 -> 6 | C103: #REF!
A104: =A9 -> 6.5 | C104: #REF!
A105: =A10 -> 7 | C105: #REF!
A106: =A11 -> 7.5 | C106: #REF!
A107: =A12 -> 8 | C107: #REF!
A108: =A13 -> 8.5 | C108: #REF!
A109: =A14 -> 9 | C109: #REF!
A110: =A15 -> 9.5 | C110: #REF!
... A175: =A80 -> 42 | C175: #REF!
A177: Airspeed (m/s) | C177: Drag (N)
A178: ='[1]Irrelevant Example'!K7 -> #REF! | B178: Min Drag Airspeed
A179: =A98 -> #REF! | B179: Cruise AIrspeed
A180: =A99 -> 4 | C180: #REF!
A181: =A100 -> 4.5 | C181: #REF!
A182: =A101 -> 5 | C182: #REF!
A183: =A102 -> 5.5 | C183: #REF!
...

Sheet Post-Hover Cruise Trends
A1: Airspeed (m/s) | C1: Flight Time (min) | D1: Range (km) | F1: Drag (N) | G1: Drag (kg) | H1: Drag Coefficient | I1: Lift Coefficient | J1: Lift (N) | K1: L/D | L1: Approx Current per motor(A) | M1: Power Draw Per Motor
A2: ='[1]Irrelevant Example'!K12 -> #REF! | B2: Cruise Airspeed
A3: ='[1]Irrelevant Example'!K9 -> #REF! | B3: Min Airspeed
A4: 4 | C4: =(('Performance Calculator'!$B$37/(((2)*M4-'Systems Param+Perf'!$C$66+'Systems Param+Perf'!$C$76+'Systems Param+Perf'!$C$83+'Systems Param+Perf'!$C$86)))/60) -> 8.4982741 | D4: =C4*60*A4/1000 -> 2.0395858 | F4: =0.5*('Aerodynamic Perf'!$B$24*A4^2*H4*'Aerodynamic Perf'!$B$14) -> 46.66562 | G4: =F4/9.81 -> 4.756944 | H4: =('Aerodynamic Perf'!$B$21+'Aerodynamic Perf'!$B$29+'Aerodynamic Perf'!$B$2+'Aerodynamic Perf'!$B$28+'Aerodynamic Perf'!$B$5)+I4^2/(PI()*'Aerodynamic Perf'!$B$7*'Aerodynamic Perf'!$B$10) -> 5.714895 | I4: =('Aircraft W+B'!$C$61)/(0.5*'Aerodynamic Perf'!$B$24*A4^2*'Aerodynamic Perf'!$B$14) -> 13.677385 | J4: =I4*0.5*'Aerodynamic Perf'!$B$24*A4^2*'Aerodynamic Perf'!$B$14 -> 111.68423 | K4: =I4/H4 -> 2.3932872 | L4: =M4/'Systems Param+Perf'!$C$58 -> 55.210895 | M4: =('Systems Param+Perf'!$C$4*((G4)^2)+'Systems Param+Perf'!$C$5*((G4))+'Systems Param+Perf'!$C$6) -> 1225.6819
A5: =A4+0.5 -> 4.5 | C5: =(('Performance Calculator'!$B$37/(((2)*M5-'Systems Param+Perf'!$C$66+'Systems Param+Perf'!$C$76+'Systems Param+Perf'!$C$83+'Systems Param+Perf'!$C$86)))/60) -> 12.450043 | D5: =C5*60*A5/1000 -> 3.3615116 | F5: =0.5*('Aerodynamic Perf'!$B$24*A5^2*H5*'Aerodynamic Perf'!$B$14) -> 36.933725 | G5: =F5/9.81 -> 3.7649057 | H5: =('Aerodynamic Perf'!$B$21+'Aerodynamic Perf'!$B$29+'Aerodynamic Perf'!$B$2+'Aerodynamic Perf'!$B$28+'Aerodynamic Perf'!$B$5)+I5^2/(PI()*'Aerodynamic Perf'!$B$7*'Aerodynamic Perf'!$B$10) -> 3.5737921 | I5: =('Aircraft W+B'!$C$61)/(0.5*'Aerodynamic Perf'!$B$24*A5^2*'Aerodynamic Perf'!$B$14) -> 10.806823 | J5: =I5*0.5*'Aerodynamic Perf'!$B$24*A5^2*'Aerodynamic Perf'!$B$14 -> 111.68423 | K5: =I5/H5 -> 3.0239091 | L5: =M5/'Systems Param+Perf'!$C$58 -> 37.66567 | M5: =('Systems Param+Perf'!$C$4*((G5)^2)+'Systems Param+Perf'!$C$5*((G5))+'Systems Param+Perf'!$C$6) -> 836.17786
A6: =A5+0.5 -> 5 | C6: =(('Performance Calculator'!$B$37/(((2)*M6-'Systems Param+Perf'!$C$66+'Systems Param+Perf'!$C$76+'Systems Param+Perf'!$C$83+'Systems Param+Perf'!$C$86)))/60) -> 17.306955 | D6: =C6*60*A6/1000 -> 5.1920865 | F6: =0.5*('Aerodynamic Perf'!$B$24*A6^2*H6*'Aerodynamic Perf'!$B$14) -> 29.986521 | G6: =F6/9.81 -> 3.05673 | H6: =('Aerodynamic Perf'!$B$21+'Aerodynamic Perf'!$B$29+'Aerodynamic Perf'!$B$2+'Aerodynamic Perf'!$B$28+'Aerodynamic Perf'!$B$5)+I6^2/(PI()*'Aerodynamic Perf'!$B$7*'Aerodynamic Perf'!$B$10) -> 2.3502674 | I6: =('Aircraft W+B'!$C$61)/(0.5*'Aerodynamic Perf'!$B$24*A6^2*'Aerodynamic Perf'!$B$14) -> 8.7535263 | J6: =I6*0.5*'Aerodynamic Perf'!$B$24*A6^2*'Aerodynamic Perf'!$B$14 -> 111.68423 | K6: =I6/H6 -> 3.724481 | L6: =M6/'Systems Param+Perf'!$C$58 -> 27.07709 | M6: =('Systems Param+Perf'!$C$4*((G6)^2)+'Systems Param+Perf'!$C$5*((G6))+'Systems Param+Perf'!$C$6) -> 601.11139
A7: =A6+0.5 -> 5.5 | C7: =(('Performance Calculator'!$B$37/(((2)*M7-'Systems Param+Perf'!$C$66+'Systems Param+Perf'!$C$76+'Systems Param+Perf'!$C$83+'Systems Param+Perf'!$C$86)))/60) -> 23.068031 | D7: =C7*60*A7/1000 -> 7.6124501 | F7: =0.5*('Aerodynamic Perf'!$B$24*A7^2*H7*'Aerodynamic Perf'!$B$14) -> 24.860548 | G7: =F7/9.81 -> 2.5342047 | H7: =('Aerodynamic Perf'!$B$21+'Aerodynamic Perf'!$B$29+'Aerodynamic Perf'!$B$2+'Aerodynamic Perf'!$B$28+'Aerodynamic Perf'!$B$5)+I7^2/(PI()*'Aerodynamic Perf'!$B$7*'Aerodynamic Perf'!$B$10) -> 1.610336 | I7: =('Aircraft W+B'!$C$61)/(0.5*'Aerodynamic Perf'!$B$24*A7^2*'Aerodynamic Perf'!$B$14) -> 7.2343192 | J7: =I7*0.5*'Aerodynamic Perf'!$B$24*A7^2*'Aerodynamic Perf'!$B$14 -> 111.68423 | K7: =I7/H7 -> 4.4924283 | L7: =M7/'Systems Param+Perf'!$C$58 -> 20.298468 | M7: =('Systems Param+Perf'!$C$4*((G7)^2)+'Systems Param+Perf'!$C$5*((G7))+'Systems Param+Perf'!$C$6) -> 450.626
A8: =A7+0.5 -> 6 | C8: =(('Performance Calculator'!$B$37/(((2)*M8-'Systems Param+Perf'!$C$66+'Systems Param+Perf'!$C$76+'Systems Param+Perf'!$C$83+'Systems Param+Perf'!$C$86)))/60) -> 29.708784 | D8: =C8*60*A8/1000 -> 10.695162 | F8: =0.5*('Aerodynamic Perf'!$B$24*A8^2*H8*'Aerodynamic Perf'!$B$14) -> 20.976171 | G8: =F8/9.81 -> 2.1382437 | H8: =('Aerodynamic Perf'!$B$21+'Aerodynamic Perf'!$B$29+'Aerodynamic Perf'!$B$2+'Aerodynamic Perf'!$B$28+'Aerodynamic Perf'!$B$5)+I8^2/(PI()*'Aerodynamic Perf'!$B$7*'Aerodynamic Perf'!$B$10) -> 1.1417077 | I8: =('Aircraft W+B'!$C$61)/(0.5*'Aerodynamic Perf'!$B$24*A8^2*'Aerodynamic Perf'!$B$14) -> 6.0788377 | J8: =I8*0.5*'Aerodynamic Perf'!$B$24*A8^2*'Aerodynamic Perf'!$B$14 -> 111.68423 | K8: =I8/H8 -> 5.3243382 | L8: =M8/'Systems Param+Perf'!$C$58 -> 15.746587 | M8: =('Systems Param+Perf'!$C$4*((G8)^2)+'Systems Param+Perf'!$C$5*((G8))+'Systems Param+Perf'!$C$6) -> 349.57423
A9: =A8+0.5 -> 6.5 | C9: =(('Performance Calculator'!$B$37/(((2)*M9-'Systems Param+Perf'!$C$66+'Systems Param+Perf'!$C$76+'Systems Param+Perf'!$C$83+'Systems Param+Perf'!$C$86)))/60) -> 37.184642 | D9: =C9*60*A9/1000 -> 14.50201 | F9: =0.5*('Aerodynamic Perf'!$B$24*A9^2*H9*'Aerodynamic Perf'!$B$14) -> 17.967708 | G9: =F9/9.81 -> 1.8315706 | H9: =('Aerodynamic Perf'!$B$21+'Aerodynamic Perf'!$B$29+'Aerodynamic Perf'!$B$2+'Aerodynamic Perf'!$B$28+'Aerodynamic Perf'!$B$5)+I9^2/(PI()*'Aerodynamic Perf'!$B$7*'Aerodynamic Perf'!$B$10) -> 0.8332919 | I9: =('Aircraft W+B'!$C$61)/(0.5*'Aerodynamic Perf'!$B$24*A9^2*'Aerodynamic Perf'!$B$14) -> 5.1796014 | J9: =I9*0.5*'Aerodynamic Perf'!$B$24*A9^2*'Aerodynamic Perf'!$B$14 -> 111.68423 | K9: =I9/H9 -> 6.2158307 | L9: =M9/'Systems Param+Perf'!$C$58 -> 12.567652 | M9: =('Systems Param+Perf'!$C$4*((G9)^2)+'Systems Param+Perf'!$C$5*((G9))+'Systems Param+Perf'!$C$6) -> 279.00188
A10: =A9+0.5 -> 7 | C10: =(('Performance Calculator'!$B$37/(((2)*M10-'Systems Param+Perf'!$C$66+'Systems Param+Perf'!$C$76+'Systems Param+Perf'!$C$83+'Systems Param+Perf'!$C$86)))/60) -> 45.433418 | D10: =C10*60*A10/1000 -> 19.082036 | F10: =0.5*('Aerodynamic Perf'!$B$24*A10^2*H10*'Aerodynamic Perf'!$B$14) -> 15.595207 | G10: =F10/9.81 -> 1.5897255 | H10: =('Aerodynamic Perf'!$B$21+'Aerodynamic Perf'!$B$29+'Aerodynamic Perf'!$B$2+'Aerodynamic Perf'!$B$28+'Aerodynamic Perf'!$B$5)+I10^2/(PI()*'Aerodynamic Perf'!$B$7*'Aerodynamic Perf'!$B$10) -> 0.62362895 | I10: =('Aircraft W+B'!$C$61)/(0.5*'Aerodynamic Perf'!$B$24*A10^2*'Aerodynamic Perf'!$B$14) -> 4.4660848 | J10: =I10*0.5*'Aerodynamic Perf'!$B$24*A10^2*'Aerodynamic Perf'!$B$14 -> 111.68423 | K10: =I10/H10 -> 7.1614456 | L10: =M10/'Systems Param+Perf'!$C$58 -> 10.274043 | M10: =('Systems Param+Perf'!$C$4*((G10)^2)+'Systems Param+Perf'!$C$5*((G10))+'Systems Param+Perf'!$C$6) -> 228.08375
A11: =A10+0.5 -> 7.5 | C11: =(('Performance Calculator'!$B$37/(((2)*M11-'Systems Param+Perf'!$C$66+'Systems Param+Perf'!$C$76+'Systems Param+Perf'!$C$83+'Systems Param+Perf'!$C$86)))/60) -> 54.376986 | D11: =C11*60*A11/1000 -> 24.469644 | F11: =0.5*('Aerodynamic Perf'!$B$24*A11^2*H11*'Aerodynamic Perf'!$B$14) -> 13.69593 | G11: =F11/9.81 -> 1.3961192 | H11: =('Aerodynamic Perf'!$B$21+'Aerodynamic Perf'!$B$29+'Aerodynamic Perf'!$B$2+'Aerodynamic Perf'!$B$28+'Aerodynamic Perf'!$B$5)+I11^2/(PI()*'Aerodynamic Perf'!$B$7*'Aerodynamic Perf'!$B$10) -> 0.47708985 | I11: =('Aircraft W+B'!$C$61)/(0.5*'Aerodynamic Perf'!$B$24*A11^2*'Aerodynamic Perf'!$B$14) -> 3.8904561 | J11: =I11*0.5*'Aerodynamic Perf'!$B$24*A11^2*'Aerodynamic Perf'!$B$14 -> 111.68423 | K11: =I11/H11 -> 8.1545564 | L11: =M11/'Systems Param+Perf'!$C$58 -> 8.5734934 | M11: =('Systems Param+Perf'!$C$4*((G11)^2)+'Systems Param+Perf'!$C$5*((G11))+'Systems Param+Perf'!$C$6) -> 190.33155
A12: =A11+0.5 -> 8 | C12: =(('Performance Calculator'!$B$37/(((2)*M12-'Systems Param+Perf'!$C$66+'Systems Param+Perf'!$C$76+'Systems Param+Perf'!$C$83+'Systems Param+Perf'!$C$86)))/60) -> 63.922464 | D12: =C12*60*A12/1000 -> 30.682783 | F12: =0.5*('Aerodynamic Perf'!$B$24*A12^2*H12*'Aerodynamic Perf'!$B$14) -> 12.156342 | G12: =F12/9.81 -> 1.2391786 | H12: =('Aerodynamic Perf'!$B$21+'Aerodynamic Perf'!$B$29+'Aerodynamic Perf'!$B$2+'Aerodynamic Perf'!$B$28+'Aerodynamic Perf'!$B$5)+I12^2/(PI()*'Aerodynamic Perf'!$B$7*'Aerodynamic Perf'!$B$10) -> 0.37218094 | I12: =('Aircraft W+B'!$C$61)/(0.5*'Aerodynamic Perf'!$B$24*A12^2*'Aerodynamic Perf'!$B$14) -> 3.4193462 | J12: =I12*0.5*'Aerodynamic Perf'!$B$24*A12^2*'Aerodynamic Perf'!$B$14 -> 111.68423 | K12: =I12/H12 -> 9.1873223 | L12: =M12/'Systems Param+Perf'!$C$58 -> 7.2834687 | M12: =('Systems Param+Perf'!$C$4*((G12)^2)+'Systems Param+Perf'!$C$5*((G12))+'Systems Param+Perf'!$C$6) -> 161.693
A13: =A12+0.5 -> 8.5 | C13: =(('Performance Calculator'!$B$37/(((2)*M13-'Systems Param+Perf'!$C$66+'Systems Param+Perf'!$C$76+'Systems Param+Perf'!$C$83+'Systems Param+Perf'!$C$86)))/60) -> 73.963252 | D13: =C13*60*A13/1000 -> 37.721258 | F13: =0.5*('Aerodynamic Perf'!$B$24*A13^2*H13*'Aerodynamic Perf'!$B$14) -> 10.895288 | G13: =F13/9.81 -> 1.1106308 | H13: =('Aerodynamic Perf'!$B$21+'Aerodynamic Perf'!$B$29+'Aerodynamic Perf'!$B$2+'Aerodynamic Perf'!$B$28+'Aerodynamic Perf'!$B$5)+I13^2/(PI()*'Aerodynamic Perf'!$B$7*'Aerodynamic Perf'!$B$10) -> 0.29548269 | I13: =('Aircraft W+B'!$C$61)/(0.5*'Aerodynamic Perf'!$B$24*A13^2*'Aerodynamic Perf'!$B$14) -> 3.0289018 | J13: =I13*0.5*'Aerodynamic Perf'!$B$24*A13^2*'Aerodynamic Perf'!$B$14 -> 111.68423 | K13: =I13/H13 -> 10.250691 | L13: =M13/'Systems Param+Perf'!$C$58 -> 6.2858438 | M13: =('Systems Param+Perf'!$C$4*((G13)^2)+'Systems Param+Perf'!$C$5*((G13))+'Systems Param+Perf'!$C$6) -> 139.54573
A14: =A13+0.5 -> 9 | C14: =(('Performance Calculator'!$B$37/(((2)*M14-'Systems Param+Perf'!$C$66+'Systems Param+Perf'!$C$76+'Systems Param+Perf'!$C$83+'Systems Param+Perf'!$C$86)))/60) -> 84.380224 | D14: =C14*60*A14/1000 -> 45.565321 | F14: =0.5*('Aerodynamic Perf'!$B$24*A14^2*H14*'Aerodynamic Perf'!$B$14) -> 9.8535076 | G14: =F14/9.81 -> 1.004435 | H14: =('Aerodynamic Perf'!$B$21+'Aerodynamic Perf'!$B$29+'Aerodynamic Perf'!$B$2+'Aerodynamic Perf'!$B$28+'Aerodynamic Perf'!$B$5)+I14^2/(PI()*'Aerodynamic Perf'!$B$7*'Aerodynamic Perf'!$B$10) -> 0.23836201 | I14: =('Aircraft W+B'!$C$61)/(0.5*'Aerodynamic Perf'!$B$24*A14^2*'Aerodynamic Perf'!$B$14) -> 2.7017056 | J14: =I14*0.5*'Aerodynamic Perf'!$B$24*A14^2*'Aerodynamic Perf'!$B$14 -> 111.68423 | K14: =I14/H14 -> 11.334464 | L14: =M14/'Systems Param+Perf'!$C$58 -> 5.5017756 | M14: =('Systems Param+Perf'!$C$4*((G14)^2)+'Systems Param+Perf'!$C$5*((G14))+'Systems Param+Perf'!$C$6) -> 122.13942
A15: =A14+0.5 -> 9.5 | C15: =(('Performance Calculator'!$B$37/(((2)*M15-'Systems Param+Perf'!$C$66+'Systems Param+Perf'!$C$76+'Systems Param+Perf'!$C$83+'Systems Param+Perf'!$C$86)))/60) -> 95.043346 | D15: =C15*60*A15/1000 -> 54.174707 | F15: =0.5*('Aerodynamic Perf'!$B$24*A15^2*H15*'Aerodynamic Perf'!$B$14) -> 8.9869136 | G15: =F15/9.81 -> 0.91609721 | H15: =('Aerodynamic Perf'!$B$21+'Aerodynamic Perf'!$B$29+'Aerodynamic Perf'!$B$2+'Aerodynamic Perf'!$B$28+'Aerodynamic Perf'!$B$5)+I15^2/(PI()*'Aerodynamic Perf'!$B$7*'Aerodynamic Perf'!$B$10) -> 0.19511675 | I15: =('Aircraft W+B'!$C$61)/(0.5*'Aerodynamic Perf'!$B$24*A15^2*'Aerodynamic Perf'!$B$14) -> 2.4247995 | J15: =I15*0.5*'Aerodynamic Perf'!$B$24*A15^2*'Aerodynamic Perf'!$B$14 -> 111.68423 | K15: =I15/H15 -> 12.427429 | L15: =M15/'Systems Param+Perf'!$C$58 -> 4.8771915 | M15: =('Systems Param+Perf'!$C$4*((G15)^2)+'Systems Param+Perf'!$C$5*((G15))+'Systems Param+Perf'!$C$6) -> 108.27365
A16: =A15+0.5 -> 10 | C16: =(('Performance Calculator'!$B$37/(((2)*M16-'Systems Param+Perf'!$C$66+'Systems Param+Perf'!$C$76+'Systems Param+Perf'!$C$83+'Systems Param+Perf'!$C$86)))/60) -> 105.81387 | D16: =C16*60*A16/1000 -> 63.48832 | F16: =0.5*('Aerodynamic Perf'!$B$24*A16^2*H16*'Aerodynamic Perf'!$B$14) -> 8.2621566 | G16: =F16/9.81 -> 0.84221779 | H16: =('Aerodynamic Perf'!$B$21+'Aerodynamic Perf'!$B$29+'Aerodynamic Perf'!$B$2+'Aerodynamic Perf'!$B$28+'Aerodynamic Perf'!$B$5)+I16^2/(PI()*'Aerodynamic Perf'!$B$7*'Aerodynamic Perf'!$B$10) -> 0.16189171 | I16: =('Aircraft W+B'!$C$61)/(0.5*'Aerodynamic Perf'!$B$24*A16^2*'Aerodynamic Perf'!$B$14) -> 2.1883816 | J16: =I16*0.5*'Aerodynamic Perf'!$B$24*A16^2*'Aerodynamic Perf'!$B$14 -> 111.68423 | K16: =I16/H16 -> 13.517564 | L16: =M16/'Systems Param+Perf'!$C$58 -> 4.3741064 | M16: =('Systems Param+Perf'!$C$4*((G16)^2)+'Systems Param+Perf'!$C$5*((G16))+'Systems Param+Perf'!$C$6) -> 97.105163
... A80: =A79+0.5 -> 42 | C80: =(('Performance Calculator'!$B$37/(((2)*M80-'Systems Param+Perf'!$C$66+'Systems Param+Perf'!$C$76+'Systems Param+Perf'!$C$83+'Systems Param+Perf'!$C$86)))/60) -> 48.748135 | D80: =C80*60*A80/1000 -> 122.8453 | F80: =0.5*('Aerodynamic Perf'!$B$24*A80^2*H80*'Aerodynamic Perf'!$B$14) -> 14.826227 | G80: =F80/9.81 -> 1.5113381 | H80: =('Aerodynamic Perf'!$B$21+'Aerodynamic Perf'!$B$29+'Aerodynamic Perf'!$B$2+'Aerodynamic Perf'!$B$28+'Aerodynamic Perf'!$B$5)+I80^2/(PI()*'Aerodynamic Perf'!$B$7*'Aerodynamic Perf'!$B$10) -> 0.01646885 | I80: =('Aircraft W+B'!$C$61)/(0.5*'Aerodynamic Perf'!$B$24*A80^2*'Aerodynamic Perf'!$B$14) -> 0.12405791 | J80: =I80*0.5*'Aerodynamic Perf'!$B$24*A80^2*'Aerodynamic Perf'!$B$14 -> 111.68423 | K80: =I80/H80 -> 7.5328827 | L80: =M80/'Systems Param+Perf'!$C$58 -> 9.5709997 | M80: =('Systems Param+Perf'!$C$4*((G80)^2)+'Systems Param+Perf'!$C$5*((G80))+'Systems Param+Perf'!$C$6) -> 212.47619
A96: Airspeed (m/s) | C96: Power (W)
A97: ='[1]Irrelevant Example'!K8 -> #REF! | B97: Min Power Airspeed
A98: =A2 -> #REF! | B98: Cruise Airspeed
A99: =A4 -> 4 | C99: #REF!
A100: =A5 -> 4.5 | C100: #REF!
A101: =A6 -> 5 | C101: #REF!
A102: =A7 -> 5.5 | C102: #REF!
A103: =A8 -> 6 | C103: #REF!
A104: =A9 -> 6.5 | C104: #REF!
A105: =A10 -> 7 | C105: #REF!
A106: =A11 -> 7.5 | C106: #REF!
A107: =A12 -> 8 | C107: #REF!
A108: =A13 -> 8.5 | C108: #REF!
A109: =A14 -> 9 | C109: #REF!
A110: =A15 -> 9.5 | C110: #REF!
... A175: =A80 -> 42 | C175: #REF!
A177: Airspeed (m/s) | C177: Drag (N)
A178: ='[1]Irrelevant Example'!K7 -> #REF! | B178: Min Drag Airspeed
A179: =A98 -> #REF! | B179: Cruise AIrspeed
A180: =A99 -> 4 | C180: #REF!
A181: =A100 -> 4.5 | C181: #REF!
A182: =A101 -> 5 | C182: #REF!
A183: =A102 -> 5.5 | C183: #REF!
...

Sheet Purchasing Sheet
A1: Part Name | B1: Price | C1: Quantity | D1: Manufacturer | E1: Total Cost: | F1: Comment:
A2: MN505-S KV380 | B2: 109.9 | C2: 2 | D2: T-motor | E2: =B2*C2 -> 219.8 | F2: Aft Motors, Better for hovering only | G2: http://store-en.tmotor.com/goods.php?id=699
A3: AT3520 550KV | B3: 79.99 | C3: 2 | D3: T-motor | E3: =B3*C3 -> 159.98 | F3: Forward Motors, with higher rpms and pitch speed. | G3: http://store-en.tmotor.com/goods.php?id=794
A4: 60A ESC can handle up to 6S | B4: 85 | C4: 4 | E4: =B4*C4 -> 340 | F4: ESC's | G4: https://www.horizonhobby.com/60-amp-pro-switch-mode-bec-brushless-esc-%28v2%29-efla1060b
A5: P17x5.8 Carbon Props | B5: 71.9 | C5: 1 | D5: T-Motor | E5: =B5*C5 -> 71.9 | F5: Aft props | G5: http://store-en.tmotor.com/goods.php?id=383
A6: 14x8.5EP | B6: 5.99 | C6: 1 | D6: APC | E6: =B6*C6 -> 5.99 | F6: Forward Prop | G6: https://www.apcprop.com/product/14x8-5ep/
A7: 14x8.5E | B7: 5.99 | C7: 1 | D7: APC | E7: =B7*C7 -> 5.99 | F7: Forward Prop | G7: https://www.apcprop.com/product/14x8-5e/
D9: Power System Total: | E9: =SUM(E2:E8) -> 803.66

Sheet Motor Options
A1: Motor Option: | B1: Motor: | C1: Max Cont. Power: | D1: 3d airplane weight (lbs) | E1: Motor Weight (kg) | F1: Price | G1: ESC Weight | H1: Watts/kg motor mass | I1: Power per thrust (W/kg) | J1: Website
A2: 1 | B2: E-flight power 46 | C2: 925 | D2: 5 | E2: 0.29 | F2: 90 | H2: =C2/E2 -> 3189.6552 | J2: https://www.horizonhobby.com/power-46-brushless-outrunner-motor--670kv-eflm4046a
A3: 2 | B3: Rimfire .32 | C3: 925 | D3: 4 | E3: 0.198 | H3: =C3/E3 -> 4671.7172
A4: 3 | B4: Rimfire .46 | C4: 1110 | D4: 5 | E4: 0.268 | H4: =C4/E4 -> 4141.791 | J4: https://www.rcplanet.com/motors/airplane-motors/great-planes-rimfire-outrunner-brushless-motor-46-42-60-800-gpmg4725/
A5: 4 | B5: T-Motor U7-V2.0 280kv | C5: 800 | E5: 0.317 | H5: =C5/E5 -> 2523.6593
A6: 5 | B6: T-Motor U7-V2.0 420kv | C6: 1180 | E6: 0.296 | F6: 149.9 | H6: =C6/E6 -> 3986.4865
A7: 6 | B7: T-Motor U11 90KV | C7: 3000 | E7: 0.815 | F7: 349.9 | H7: =C7/E7 -> 3680.9816
A8: 7 | B8: T-Motor MN505-S 320kv | C8: 1300 | E8: 0.225 | F8: 110 | H8: =C8/E8 -> 5777.7778
B9: T-Motor MN505-S 380kv | C9: 1200 | E9: 0.225 | H9: =C9/E9 -> 5333.3333 | I9: 25.97x^2+87.83x+12.83
B10: T-Motor AT3520 | C10: 1100 | E10: 0.339 | F10: 79 | H10: =C10/E10 -> 3244.8378 | K10: 45 amps
H11: =C11/E11 -> #DIV/0!
H12: =C12/E12 -> #DIV/0!
H13: =C13/E13 -> #DIV/0!

Sheet Forward Motor Static Thrust Cur
A1: Thrust (kg) | B1: Thrust (g) | C1: Thrust (N) | D1: Power (W) | E1: Other Motor Power
A2: =B2/1000 -> 0.973 | B2: 973 | C2: =B2/101.97 -> 9.5420222 | D2: 115.79 | E2: =('Systems Param+Perf'!$C$4*((A2)^2)+'Systems Param+Perf'!$C$5*((A2))+'Systems Param+Perf'!$C6) -> 117.14143
A3: =B3/1000 -> 1.169 | B3: 1169 | C3: =B3/101.97 -> 11.464156 | D3: 150.66 | E3: =('Systems Param+Perf'!$C$4*((A3)^2)+'Systems Param+Perf'!$C$5*((A3))+'Systems Param+Perf'!$C7) -> 156.24183
A4: =B4/1000 -> 1.408 | B4: 1408 | C4: =B4/101.97 -> 13.807983 | D4: 190.74 | E4: =('Systems Param+Perf'!$C$4*((A4)^2)+'Systems Param+Perf'!$C$5*((A4))+'Systems Param+Perf'!$C8) -> 195.24116
A5: =B5/1000 -> 1.689 | B5: 1689 | C5: =B5/101.97 -> 16.563695 | D5: 250.13 | E5: =('Systems Param+Perf'!$C$4*((A5)^2)+'Systems Param+Perf'!$C$5*((A5))+'Systems Param+Perf'!$C9) -> 251.14974
A6: =B6/1000 -> 1.954 | B6: 1954 | C6: =B6/101.97 -> 19.162499 | D6: 305.98 | E6: =('Systems Param+Perf'!$C$4*((A6)^2)+'Systems Param+Perf'!$C$5*((A6))+'Systems Param+Perf'!$C10) -> 309.04034
A7: =B7/1000 -> 2.247 | B7: 2247 | C7: =B7/101.97 -> 22.035893 | D7: 376.74 | E7: =('Systems Param+Perf'!$C$4*((A7)^2)+'Systems Param+Perf'!$C$5*((A7))+'Systems Param+Perf'!$C11) -> 414.58442
A8: =B8/1000 -> 2.529 | B8: 2529 | C8: =B8/101.97 -> 24.801412 | D8: 450.36 | E8: =('Systems Param+Perf'!$C$4*((A8)^2)+'Systems Param+Perf'!$C$5*((A8))+'Systems Param+Perf'!$C12) -> 540.29512
A9: =B9/1000 -> 2.863 | B9: 2863 | C9: =B9/101.97 -> 28.076885 | D9: 544.3 | E9: =('Systems Param+Perf'!$C$4*((A9)^2)+'Systems Param+Perf'!$C$5*((A9))+'Systems Param+Perf'!$C13) -> 543.04385
A10: =B10/1000 -> 3.216 | B10: 3216 | C10: =B10/101.97 -> 31.538688 | D10: 644.83 | E10: =('Systems Param+Perf'!$C$4*((A10)^2)+'Systems Param+Perf'!$C$5*((A10))+'Systems Param+Perf'!$C14) -> 657.64322
A11: =B11/1000 -> 3.787 | B11: 3787 | C11: =B11/101.97 -> 37.138374 | D11: 843.54 | E11: =('Systems Param+Perf'!$C$4*((A11)^2)+'Systems Param+Perf'!$C$5*((A11))+'Systems Param+Perf'!$C15) -> 846.75767
A12: =B12/1000 -> 4.116 | B12: 4116 | C12: =B12/101.97 -> 40.364813 | D12: 966.63 | E12: =('Systems Param+Perf'!$C$4*((A12)^2)+'Systems Param+Perf'!$C$5*((A12))+'Systems Param+Perf'!$C16) -> 968.66438
